Workbook
Name _1___Excel_BuiltIn__FilterDatabase_1_1: #REF!
Name _1___Excel_BuiltIn__FilterDatabase_1_1: #REF!
Name _10__Excel_BuiltIn__FilterDatabase_5_1: #REF!
Name _11_Excel_BuiltIn__FilterDatabase_1_1: #REF!
Name _12_Excel_BuiltIn__FilterDatabase_2_1: #REF!
Name _13_Excel_BuiltIn__FilterDatabase_3_1: #REF!
Name _14_Excel_BuiltIn__FilterDatabase_4_1: #REF!
Name _15_Excel_BuiltIn__FilterDatabase_5_1: #REF!
Name _1Excel_BuiltIn__FilterDatabase_1_1: #REF!
Name _2___Excel_BuiltIn__FilterDatabase_2_1: #REF!
Name _2Excel_BuiltIn__FilterDatabase_2_1: #REF!
Name _3___Excel_BuiltIn__FilterDatabase_3_1: #REF!
Name _3Excel_BuiltIn__FilterDatabase_3_1: #REF!
Name _4___Excel_BuiltIn__FilterDatabase_4_1: #REF!
Name _4Excel_BuiltIn__FilterDatabase_4_1: #REF!
Name _5___Excel_BuiltIn__FilterDatabase_5_1: #REF!
Name _5Excel_BuiltIn__FilterDatabase_5_1: #REF!
Name _6__Excel_BuiltIn__FilterDatabase_1_1: #REF!
Name _7__Excel_BuiltIn__FilterDatabase_2_1: #REF!
Name _8__Excel_BuiltIn__FilterDatabase_3_1: #REF!
Name _9__Excel_BuiltIn__FilterDatabase_4_1: #REF!
Name a: #REF!
Name a: #REF!
Name aa: #REF!
Name AAAAAA: #REF!
Name AAAAAA: #REF!
Name aasqsadh: #REF!
Name AB: #REF!
Name ABRIL: #REF!
Name AFAM: #REF!
Name AFP: #REF!
Name AFP: #REF!
Name AGOSTO: #REF!
Name ASIG_FAM: #REF!
Name BAGO: #REF!
Name BANCO: #REF!
Name BASE: #REF!
Name BASE_AFECTA: #REF!
Name BASE_RETENCION: #REF!
Name BASEJULIO: #REF!
Name BASEJUNIO: #REF!
Name BASEMAYO: #REF!
Name BASESEP: #REF!
Name BASICO: #REF!
Name BOCTUBRE: #REF!
Name BONO: #REF!
Name cadddd: #REF!
Name cadddd: #REF!
Name Caja: #REF!
Name CODIGO: #REF!
Name CONSOLIDADO: #REF!
Name CTS: #REF!
Name CUENTA: #REF!
Name DATA: #REF!
Name DATA: #REF!
Name DATASEP: #REF!
Name DEPOSITO: #REF!
Name DNI: #REF!
Name ESSALUD: #REF!
Name Excel_BuiltIn__FilterDatabase_1: #REF!

Sheet UTILIDADES 2025
AA1: =+ROUND(V1/$AA$3,2) -> 0
C2: CITIKOLD
C3: PLANILLA DE UTILIDADES 2025 | M3: ok | N3: ok | Z3: TC | AA3: 3.435
C4: 1 | D4: 2 | E4: 3 | F4: 4 | I4: 5 | J4: 6 | M4: 7 | N4: 8 | O4: 9 | P4: 10 | Q4: 11 | R4: 12 | T4: 13 | V4: 14
C5: Nº+C5:M6 | D5: DNI | E5: APELLIDOS Y NOMBRES | F5: CARGO | G5: AREA | H5: CENTRO DE COSTO | I5: FECHA DE INGRESO | J5: FECHA DE CESE | K5: FECHA DE INGRESO | L5: FECHA DE CESE | M5: Nº dias Efectivos Laborados | N5: Total de Remuneraciones | O5: ESTADO | P5: EN FUNCION A DIAS | Q5: EN FUNCION A REMUNERACIONES | R5: TOTAL DE UTILIDADES | S5: IR 5ta CATEGORIA | T5: RETENCION JUDICIAL | U5: PRESTAMO / OTROS DESCUENTOS | V5: UTILIDADES NETAS | Y5: TRAMO ALCANZADO | AA5: DOLARES
C7: 1 | D7: 07262343 | E7: CIEZA AGUILAR CESAR AUGUSTO | F7: CHOFER | G7: ADMINISTRACION | H7: ADMINISTRACION | I7: =VLOOKUP(D7,'DÍAS EFECTIVOS LABORADOS 2025'!B:F,3,0) -> 43357 | M7: =VLOOKUP(D7,'DÍAS EFECTIVOS LABORADOS 2025'!B:O,14,0) -> 231 | N7: =+ROUND(VLOOKUP(D7,'INGRESOS 2025'!$B$7:$V$159,21,0),2) -> 57700.7 | O7: ACTIVO | P7: =$N$103*M7 -> 11372.668 | Q7: =$N$104*N7 -> 5731.2636 | R7: =+ROUND(P7+Q7,2) -> 17103.93 | S7: =ROUND(HLOOKUP(D7,'5ta'!$C$7:$CF$118,112,0),2) -> 1490.95 | U7: =5856.36+5000 -> 10856.36 | V7: =+ROUND(R7-T7-S7-U7,2) -> 4756.62 | X7: =HLOOKUP(D7,'5ta'!$C$7:$CG$139,133,0) -> FALSE | Y7: =HLOOKUP(D7,'5ta'!$C$7:$CF$145,134,0) -> 08% - 14% | Z7: =VLOOKUP(D7,'[1]0220262'!$E$12:$AD$94,26,0) -> 0 | AB7: =VLOOKUP(D7,'[2]Archivo Excel Haberes Input'!$K$11:$K$80,1,0) -> 07262343
C8: 2 | D8: 07537953 | E8: SALAZAR DE LA ROCHA JUAN CARLOS GERMAN | F8: GERENTE GENERAL | G8: GERENCIA GENERAL | H8: VARIOS | I8: =VLOOKUP(D8,'DÍAS EFECTIVOS LABORADOS 2025'!B:F,3,0) -> 43003 | M8: =VLOOKUP(D8,'DÍAS EFECTIVOS LABORADOS 2025'!B:O,14,0) -> 222 | N8: =+ROUND(VLOOKUP(D8,'INGRESOS 2025'!$B$7:$V$159,21,0),2) -> 574648.72 | O8: ACTIVO | P8: =$N$103*M8 -> 10929.577 | Q8: =$N$104*N8 -> 57078.394 | R8: =+ROUND(P8+Q8,2) -> 68007.97 | S8: =ROUND(HLOOKUP(D8,'5ta'!$C$7:$CF$118,112,0),2) -> 20402.39 | V8: =+ROUND(R8-T8-S8-U8,2) -> 47605.58 | W8: =+Y8*R8-S8 -> 0.001 | X8: =HLOOKUP(D8,'5ta'!$C$7:$CG$139,133,0) -> TRUE | Y8: =HLOOKUP(D8,'5ta'!$C$7:$CF$135,129,0) -> 0.3 | Z8: =VLOOKUP(D8,'[1]0220262'!$E$12:$AD$94,26,0) -> 0 | AB8: =VLOOKUP(D8,'[2]Archivo Excel Haberes Input'!$K$11:$K$80,1,0) -> 07537953
C9: 3 | D9: 08693248 | E9: IZARRA CARRASCO IRINA KAREM | F9: ANALISTA SENIOR DE DOCUMENTACIÓN | G9: DOCUMENTACION-VISTO BUENO | H9: OPERACIONES | I9: =VLOOKUP(D9,'DÍAS EFECTIVOS LABORADOS 2025'!B:F,3,0) -> 43160 | M9: =VLOOKUP(D9,'DÍAS EFECTIVOS LABORADOS 2025'!B:O,14,0) -> 235 | N9: =+ROUND(VLOOKUP(D9,'INGRESOS 2025'!$B$7:$V$159,21,0),2) -> 78353.36 | O9: ACTIVO | P9: =$N$103*M9 -> 11569.597 | Q9: =$N$104*N9 -> 7782.6398 | R9: =+ROUND(P9+Q9,2) -> 19352.24 | S9: =ROUND(HLOOKUP(D9,'5ta'!$C$7:$CF$118,112,0),2) -> 2709.31 | V9: =+ROUND(R9-T9-S9-U9,2) -> 16642.93 | W9: =+Y9*R9-S9 -> 0.0036 | X9: =HLOOKUP(D9,'5ta'!$C$7:$CG$139,133,0) -> TRUE | Y9: =HLOOKUP(D9,'5ta'!$C$7:$CF$135,129,0) -> 0.14 | Z9: =VLOOKUP(D9,'[1]0220262'!$E$12:$AD$94,26,0) -> 0 | AB9: =VLOOKUP(D9,'[2]Archivo Excel Haberes Input'!$K$11:$K$80,1,0) -> 08693248
C10: 4 | D10: 08887801 | E10: RUIZ SALCEDO MARIA DE LOURDES | F10: ASESOR COMERCIAL IMPO | G10: COMERCIAL- VENTAS | H10: VENTAS | I10: =VLOOKUP(D10,'DÍAS EFECTIVOS LABORADOS 2025'!B:F,3,0) -> 43003 | M10: =VLOOKUP(D10,'DÍAS EFECTIVOS LABORADOS 2025'!B:O,14,0) -> 222 | N10: =+ROUND(VLOOKUP(D10,'INGRESOS 2025'!$B$7:$V$159,21,0),2) -> 181223.64 | O10: ACTIVO | P10: =$N$103*M10 -> 10929.577 | Q10: =$N$104*N10 -> 18000.483 | R10: =+ROUND(P10+Q10,2) -> 28930.06 | S10: =ROUND(HLOOKUP(D10,'5ta'!$C$7:$CF$118,112,0),2) -> 4918.11 | V10: =+ROUND(R10-T10-S10-U10,2) -> 24011.95 | W10: =+Y10*R10-S10 -> 0.0002 | X10: =HLOOKUP(D10,'5ta'!$C$7:$CG$139,133,0) -> TRUE | Y10: =HLOOKUP(D10,'5ta'!$C$7:$CF$135,129,0) -> 0.17 | Z10: =VLOOKUP(D10,'[1]0220262'!$E$12:$AD$94,26,0) -> 0 | AB10: =VLOOKUP(D10,'[2]Archivo Excel Haberes Input'!$K$11:$K$80,1,0) -> 08887801
C11: 5 | D11: 09335023 | E11: AYOS JUNGBLUTH MARIANA | F11: ASESOR COMERCIAL EXPO | G11: COMERCIAL- VENTAS | H11: VENTAS | I11: =VLOOKUP(D11,'DÍAS EFECTIVOS LABORADOS 2025'!B:F,3,0) -> 43003 | M11: =VLOOKUP(D11,'DÍAS EFECTIVOS LABORADOS 2025'!B:O,14,0) -> 227 | N11: =+ROUND(VLOOKUP(D11,'INGRESOS 2025'!$B$7:$V$159,21,0),2) -> 179497.7 | O11: ACTIVO | P11: =$N$103*M11 -> 11175.738 | Q11: =$N$104*N11 -> 17829.05 | R11: =+ROUND(P11+Q11,2) -> 29004.79 | S11: =ROUND(HLOOKUP(D11,'5ta'!$C$7:$CF$118,112,0),2) -> 4930.81 | V11: =+ROUND(R11-T11-S11-U11,2) -> 24073.98 | W11: =+Y11*R11-S11 -> 0.0043 | X11: =HLOOKUP(D11,'5ta'!$C$7:$CG$139,133,0) -> TRUE | Y11: =HLOOKUP(D11,'5ta'!$C$7:$CF$135,129,0) -> 0.17 | Z11: =VLOOKUP(D11,'[1]0220262'!$E$12:$AD$94,26,0) -> 0 | AB11: =VLOOKUP(D11,'[2]Archivo Excel Haberes Input'!$K$11:$K$80,1,0) -> 09335023
C12: 6 | D12: 09410158 | E12: BONATTI CARRASCO JORGE LUIS | F12: ANALISTA SENIOR DE DOCUMENTACIÓN | G12: DOCUMENTACION-VISTO BUENO | H12: OPERACIONES | I12: =VLOOKUP(D12,'DÍAS EFECTIVOS LABORADOS 2025'!B:F,3,0) -> 42985 | M12: =VLOOKUP(D12,'DÍAS EFECTIVOS LABORADOS 2025'!B:O,14,0) -> 227 | N12: =+ROUND(VLOOKUP(D12,'INGRESOS 2025'!$B$7:$V$159,21,0),2) -> 71990.24 | O12: ACTIVO | P12: =$N$103*M12 -> 11175.738 | Q12: =$N$104*N12 -> 7150.6073 | R12: =+ROUND(P12+Q12,2) -> 18326.35 | S12: =ROUND(HLOOKUP(D12,'5ta'!$C$7:$CF$118,112,0),2) -> 2565.69 | V12: =+ROUND(R12-T12-S12-U12,2) -> 15760.66 | W12: =+Y12*R12-S12 -> -0.001 | X12: =HLOOKUP(D12,'5ta'!$C$7:$CG$139,133,0) -> TRUE | Y12: =HLOOKUP(D12,'5ta'!$C$7:$CF$135,129,0) -> 0.14 | Z12: =VLOOKUP(D12,'[1]0220262'!$E$12:$AD$94,26,0) -> 0 | AB12: =VLOOKUP(D12,'[2]Archivo Excel Haberes Input'!$K$11:$K$80,1,0) -> 09410158
C13: 7 | D13: 09542822 | E13: CAVERO RODRIGUEZ JANNYE VERONICA | F13: CUSTOMER SERVICE SENIOR EXPO | G13: COMERCIAL- VENTAS | H13: VENTAS | I13: =VLOOKUP(D13,'DÍAS EFECTIVOS LABORADOS 2025'!B:F,3,0) -> 42985 | M13: =VLOOKUP(D13,'DÍAS EFECTIVOS LABORADOS 2025'!B:O,14,0) -> 235 | N13: =+ROUND(VLOOKUP(D13,'INGRESOS 2025'!$B$7:$V$159,21,0),2) -> 132874.03 | O13: ACTIVO | P13: =$N$103*M13 -> 11569.597 | Q13: =$N$104*N13 -> 13198.039 | R13: =+ROUND(P13+Q13,2) -> 24767.64 | S13: =ROUND(HLOOKUP(D13,'5ta'!$C$7:$CF$118,112,0),2) -> 3467.47 | V13: =+ROUND(R13-T13-S13-U13,2) -> 21300.17 | W13: =+Y13*R13-S13 -> -0.0004 | X13: =HLOOKUP(D13,'5ta'!$C$7:$CG$139,133,0) -> TRUE | Y13: =HLOOKUP(D13,'5ta'!$C$7:$CF$135,129,0) -> 0.14 | Z13: =VLOOKUP(D13,'[1]0220262'!$E$12:$AD$94,26,0) -> 0 | AB13: =VLOOKUP(D13,'[2]Archivo Excel Haberes Input'!$K$11:$K$80,1,0) -> 09542822
C14: 8 | D14: 09867320 | E14: ROTALDE DEL RIO XIMENA MARIA | F14: JEFE DE CONTROL DE EQUIPOS | G14: CONTROL DE EQUIPOS | H14: OPERACIONES | I14: =VLOOKUP(D14,'DÍAS EFECTIVOS LABORADOS 2025'!B:F,3,0) -> 42985 | M14: =VLOOKUP(D14,'DÍAS EFECTIVOS LABORADOS 2025'!B:O,14,0) -> 229 | N14: =+ROUND(VLOOKUP(D14,'INGRESOS 2025'!$B$7:$V$159,21,0),2) -> 224410.03 | O14: ACTIVO | P14: =$N$103*M14 -> 11274.203 | Q14: =$N$104*N14 -> 22290.077 | R14: =+ROUND(P14+Q14,2) -> 33564.28 | S14: =ROUND(HLOOKUP(D14,'5ta'!$C$7:$CF$118,112,0),2) -> 6192.2 | V14: =+ROUND(R14-T14-S14-U14,2) -> 27372.08 | X14: =HLOOKUP(D14,'5ta'!$C$7:$CG$139,133,0) -> FALSE | Y14: =HLOOKUP(D14,'5ta'!$C$7:$CF$145,134,0) -> 17% - 20% | Z14: =VLOOKUP(D14,'[1]0220262'!$E$12:$AD$94,26,0) -> 0 | AB14: =VLOOKUP(D14,'[2]Archivo Excel Haberes Input'!$K$11:$K$80,1,0) -> 09867320
C15: 9 | D15: 10080476 | E15: CASTILLEJOS HINOSTROZA NAYLLI MARLENE | I15: =VLOOKUP(D15,'DÍAS EFECTIVOS LABORADOS 2025'!B:F,3,0) -> 44911 | J15: =VLOOKUP(D15,'DÍAS EFECTIVOS LABORADOS 2025'!B:F,5,0) -> 45961 | M15: =VLOOKUP(D15,'DÍAS EFECTIVOS LABORADOS 2025'!B:O,14,0) -> 179 | N15: =+ROUND(VLOOKUP(D15,'INGRESOS 2025'!$B$7:$V$159,21,0),2) -> 82758.7 | O15: CESADO | P15: =$N$103*M15 -> 8812.5866 | Q15: =$N$104*N15 -> 8220.211 | R15: =+ROUND(P15+Q15,2) -> 17032.8 | V15: =+ROUND(R15-T15-S15-U15,2) -> 17032.8 | Z15: =VLOOKUP(D15,'[1]0220262'!$E$12:$AD$94,26,0) -> #N/A
C16: 10 | D16: 10346719 | E16: ROMERO ORDOÑEZ EDUARDO ARTURO | F16: ANALISTA DE DOCUMENTACIÓN | G16: DOCUMENTACION-VISTO BUENO | H16: OPERACIONES | I16: =VLOOKUP(D16,'DÍAS EFECTIVOS LABORADOS 2025'!B:F,3,0) -> 43070 | M16: =VLOOKUP(D16,'DÍAS EFECTIVOS LABORADOS 2025'!B:O,14,0) -> 240 | N16: =+ROUND(VLOOKUP(D16,'INGRESOS 2025'!$B$7:$V$159,21,0),2) -> 62197.96 | O16: ACTIVO | P16: =$N$103*M16 -> 11815.759 | Q16: =$N$104*N16 -> 6177.965 | R16: =+ROUND(P16+Q16,2) -> 17993.72 | S16: =ROUND(HLOOKUP(D16,'5ta'!$C$7:$CF$118,112,0),2) -> 2161.89 | V16: =+ROUND(R16-T16-S16-U16,2) -> 15831.83 | X16: =HLOOKUP(D16,'5ta'!$C$7:$CG$139,133,0) -> FALSE | Y16: =HLOOKUP(D16,'5ta'!$C$7:$CF$145,134,0) -> 08% - 14% | Z16: =VLOOKUP(D16,'[1]0220262'!$E$12:$AD$94,26,0) -> 0 | AB16: =VLOOKUP(D16,'[2]Archivo Excel Haberes Input'!$K$11:$K$80,1,0) -> 10346719
C17: 11 | D17: 10725704 | E17: RONCEROS GONZALES LUISA MARILIN | F17: GERENTE DE ADMNISTRACIÓN | G17: ADMINISTRACION | H17: ADMINISTRACION | I17: =VLOOKUP(D17,'DÍAS EFECTIVOS LABORADOS 2025'!B:F,3,0) -> 43382 | M17: =VLOOKUP(D17,'DÍAS EFECTIVOS LABORADOS 2025'!B:O,14,0) -> 239 | N17: =+ROUND(VLOOKUP(D17,'INGRESOS 2025'!$B$7:$V$159,21,0),2) -> 116634.4 | O17: ACTIVO | P17: =$N$103*M17 -> 11766.526 | Q17: =$N$104*N17 -> 11584.998 | R17: =+ROUND(P17+Q17,2) -> 23351.52 | S17: =ROUND(HLOOKUP(D17,'5ta'!$C$7:$CF$118,112,0),2) -> 3269.21 | V17: =+ROUND(R17-T17-S17-U17,2) -> 20082.31 | W17: =+Y17*R17-S17 -> 0.0028 | X17: =HLOOKUP(D17,'5ta'!$C$7:$CG$139,133,0) -> TRUE | Y17: =HLOOKUP(D17,'5ta'!$C$7:$CF$135,129,0) -> 0.14 | Z17: =VLOOKUP(D17,'[1]0220262'!$E$12:$AD$94,26,0) -> 0 | AB17: =VLOOKUP(D17,'[2]Archivo Excel Haberes Input'!$K$11:$K$80,1,0) -> 10725704
C18: 12 | D18: 25710966 | E18: GIURIA CONSTANTINO HUMBERTO ANDRES | F18: JEFE DE DOCUMENTACIÓN Y VISTO BUENO | G18: DOCUMENTACION-VISTO BUENO | H18: OPERACIONES | I18: =VLOOKUP(D18,'DÍAS EFECTIVOS LABORADOS 2025'!B:F,3,0) -> 42985 | M18: =VLOOKUP(D18,'DÍAS EFECTIVOS LABORADOS 2025'!B:O,14,0) -> 238 | N18: =+ROUND(VLOOKUP(D18,'INGRESOS 2025'!$B$7:$V$159,21,0),2) -> 113138.07 | O18: ACTIVO | P18: =$N$103*M18 -> 11717.294 | Q18: =$N$104*N18 -> 11237.716 | R18: =+ROUND(P18+Q18,2) -> 22955.01 | S18: =ROUND(HLOOKUP(D18,'5ta'!$C$7:$CF$118,112,0),2) -> 3213.7 | V18: =+ROUND(R18-T18-S18-U18,2) -> 19741.31 | W18: =+Y18*R18-S18 -> 0.0014 | X18: =HLOOKUP(D18,'5ta'!$C$7:$CG$139,133,0) -> TRUE | Y18: =HLOOKUP(D18,'5ta'!$C$7:$CF$135,129,0) -> 0.14 | Z18: =VLOOKUP(D18,'[1]0220262'!$E$12:$AD$94,26,0) -> 0 | AB18: =VLOOKUP(D18,'[2]Archivo Excel Haberes Input'!$K$11:$K$80,1,0) -> 25710966
C19: 13 | D19: 25769631 | E19: RUIZ TORRES CESAR AUGUSTO | F19: CONDUCTOR/MENSAJERO | G19: ADMINISTRACION | H19: ADMINISTRACION | I19: =VLOOKUP(D19,'DÍAS EFECTIVOS LABORADOS 2025'!B:F,3,0) -> 44677 | M19: =VLOOKUP(D19,'DÍAS EFECTIVOS LABORADOS 2025'!B:O,14,0) -> 219 | N19: =+ROUND(VLOOKUP(D19,'INGRESOS 2025'!$B$7:$V$159,21,0),2) -> 30225.82 | O19: ACTIVO | P19: =$N$103*M19 -> 10781.88 | Q19: =$N$104*N19 -> 3002.2537 | R19: =+ROUND(P19+Q19,2) -> 13784.13 | S19: =ROUND(HLOOKUP(D19,'5ta'!$C$7:$CF$118,112,0),2) -> 203.01 | V19: =+ROUND(R19-T19-S19-U19,2) -> 13581.12 | X19: =HLOOKUP(D19,'5ta'!$C$7:$CG$139,133,0) -> FALSE | Y19: =HLOOKUP(D19,'5ta'!$C$7:$CF$145,134,0) -> 00% - 08% | Z19: =VLOOKUP(D19,'[1]0220262'!$E$12:$AD$94,26,0) -> 0 | AB19: =VLOOKUP(D19,'[2]Archivo Excel Haberes Input'!$K$11:$K$80,1,0) -> 25769631
C20: 14 | D20: 25828090 | E20: CHERO ORTIZ MARTIN ALEJANDRO | F20: ANALISTA DE CONTROL DE COSTO | G20: COST CONTROLER | H20: OPERACIONES | I20: =VLOOKUP(D20,'DÍAS EFECTIVOS LABORADOS 2025'!B:F,3,0) -> 44111 | M20: =VLOOKUP(D20,'DÍAS EFECTIVOS LABORADOS 2025'!B:O,14,0) -> 226 | N20: =+ROUND(VLOOKUP(D20,'INGRESOS 2025'!$B$7:$V$159,21,0),2) -> 54262.99 | O20: ACTIVO | P20: =$N$103*M20 -> 11126.506 | Q20: =$N$104*N20 -> 5389.8046 | R20: =+ROUND(P20+Q20,2) -> 16516.31 | S20: =ROUND(HLOOKUP(D20,'5ta'!$C$7:$CF$118,112,0),2) -> 1505.33 | V20: =+ROUND(R20-T20-S20-U20,2) -> 15010.98 | X20: =HLOOKUP(D20,'5ta'!$C$7:$CG$139,133,0) -> FALSE | Y20: =HLOOKUP(D20,'5ta'!$C$7:$CF$145,134,0) -> 08% - 14% | Z20: =VLOOKUP(D20,'[1]0220262'!$E$12:$AD$94,26,0) -> 0 | AB20: =VLOOKUP(D20,'[2]Archivo Excel Haberes Input'!$K$11:$K$80,1,0) -> 25828090
C21: 15 | D21: 40508445 | E21: MEJIA CAVERO PAOLA CECILIA | F21: ANALISTA SENIOR DE CONTROL DE EQUIPOS | G21: CONTROL DE EQUIPOS | H21: OPERACIONES | I21: =VLOOKUP(D21,'DÍAS EFECTIVOS LABORADOS 2025'!B:F,3,0) -> 42985 | M21: =VLOOKUP(D21,'DÍAS EFECTIVOS LABORADOS 2025'!B:O,14,0) -> 214 | N21: =+ROUND(VLOOKUP(D21,'INGRESOS 2025'!$B$7:$V$159,21,0),2) -> 76929.63 | O21: ACTIVO | P21: =$N$103*M21 -> 10535.718 | Q21: =$N$104*N21 -> 7641.2243 | R21: =+ROUND(P21+Q21,2) -> 18176.94 | S21: =ROUND(HLOOKUP(D21,'5ta'!$C$7:$CF$118,112,0),2) -> 2544.77 | V21: =+ROUND(R21-T21-S21-U21,2) -> 15632.17 | W21: =+Y21*R21-S21 -> 0.0016 | X21: =HLOOKUP(D21,'5ta'!$C$7:$CG$139,133,0) -> TRUE | Y21: =HLOOKUP(D21,'5ta'!$C$7:$CF$135,129,0) -> 0.14 | Z21: =VLOOKUP(D21,'[1]0220262'!$E$12:$AD$94,26,0) -> 0 | AB21: =VLOOKUP(D21,'[2]Archivo Excel Haberes Input'!$K$11:$K$80,1,0) -> 40508445
C22: 16 | D22: 40537272 | E22: GARRIDO LEON CARLA VERONICA | F22: ASESOR COMERCIAL EXPORTACIÓN | G22: COMERCIAL- VENTAS | H22: VENTAS | I22: =VLOOKUP(D22,'DÍAS EFECTIVOS LABORADOS 2025'!B:F,3,0) -> 42985 | M22: =VLOOKUP(D22,'DÍAS EFECTIVOS LABORADOS 2025'!B:O,14,0) -> 232 | N22: =+ROUND(VLOOKUP(D22,'INGRESOS 2025'!$B$7:$V$159,21,0),2) -> 154154.13 | O22: ACTIVO | P22: =$N$103*M22 -> 11421.9 | Q22: =$N$104*N22 -> 15311.737 | R22: =+ROUND(P22+Q22,2) -> 26733.64 | S22: =ROUND(HLOOKUP(D22,'5ta'!$C$7:$CF$118,112,0),2) -> 4378.81 | V22: =+ROUND(R22-T22-S22-U22,2) -> 22354.83 | X22: =HLOOKUP(D22,'5ta'!$C$7:$CG$139,133,0) -> FALSE | Y22: =HLOOKUP(D22,'5ta'!$C$7:$CF$145,134,0) -> 14% - 17% | Z22: =VLOOKUP(D22,'[1]0220262'!$E$12:$AD$94,26,0) -> 0 | AB22: =VLOOKUP(D22,'[2]Archivo Excel Haberes Input'!$K$11:$K$80,1,0) -> 40537272
C23: 17 | D23: 41047057 | E23: GALLEGOS BLAS LUIS MIGUEL | F23: CONTADOR | G23: CONTABILIDAD | H23: ADMINISTRACION | I23: =VLOOKUP(D23,'DÍAS EFECTIVOS LABORADOS 2025'!B:F,3,0) -> 45481 | M23: =VLOOKUP(D23,'DÍAS EFECTIVOS LABORADOS 2025'!B:O,14,0) -> 237 | N23: =+ROUND(VLOOKUP(D23,'INGRESOS 2025'!$B$7:$V$159,21,0),2) -> 87323.01 | O23: ACTIVO | P23: =$N$103*M23 -> 11668.062 | Q23: =$N$104*N23 -> 8673.5723 | R23: =+ROUND(P23+Q23,2) -> 20341.63 | S23: =ROUND(HLOOKUP(D23,'5ta'!$C$7:$CF$118,112,0),2) -> 2847.83 | V23: =+ROUND(R23-T23-S23-U23,2) -> 17493.8 | W23: =+Y23*R23-S23 -> -0.0018 | X23: =HLOOKUP(D23,'5ta'!$C$7:$CG$139,133,0) -> TRUE | Y23: =HLOOKUP(D23,'5ta'!$C$7:$CF$135,129,0) -> 0.14 | Z23: =VLOOKUP(D23,'[1]0220262'!$E$12:$AD$94,26,0) -> 0 | AB23: =VLOOKUP(D23,'[2]Archivo Excel Haberes Input'!$K$11:$K$80,1,0) -> 41047057
C24: 18 | D24: 41832234 | E24: HUERTA PALOMINO NELLY VANESSA | I24: =VLOOKUP(D24,'DÍAS EFECTIVOS LABORADOS 2025'!B:F,3,0) -> 44986 | J24: =VLOOKUP(D24,'DÍAS EFECTIVOS LABORADOS 2025'!B:F,5,0) -> 45748 | M24: =VLOOKUP(D24,'DÍAS EFECTIVOS LABORADOS 2025'!B:O,14,0) -> 49 | N24: =+ROUND(VLOOKUP(D24,'INGRESOS 2025'!$B$7:$V$159,21,0),2) -> 29573.67 | O24: CESADO | P24: =$N$103*M24 -> 2412.384 | Q24: =$N$104*N24 -> 2937.4773 | R24: =+ROUND(P24+Q24,2) -> 5349.86 | V24: =+ROUND(R24-T24-S24-U24,2) -> 5349.86 | Z24: =VLOOKUP(D24,'[1]0220262'!$E$12:$AD$94,26,0) -> #N/A
C25: 19 | D25: 42035890 | E25: CASTAÑEDA CARRION VIVIEN KARLA | F25: COORDINADOR TRIBUTARIO | G25: CONTABILIDAD | H25: ADMINISTRACION | I25: =VLOOKUP(D25,'DÍAS EFECTIVOS LABORADOS 2025'!B:F,3,0) -> 45181 | M25: =VLOOKUP(D25,'DÍAS EFECTIVOS LABORADOS 2025'!B:O,14,0) -> 227 | N25: =+ROUND(VLOOKUP(D25,'INGRESOS 2025'!$B$7:$V$159,21,0),2) -> 95349.71 | O25: ACTIVO | P25: =$N$103*M25 -> 11175.738 | Q25: =$N$104*N25 -> 9470.8439 | R25: =+ROUND(P25+Q25,2) -> 20646.58 | S25: =ROUND(HLOOKUP(D25,'5ta'!$C$7:$CF$118,112,0),2) -> 2890.52 | V25: =+ROUND(R25-T25-S25-U25,2) -> 17756.06 | W25: =+Y25*R25-S25 -> 0.0012 | X25: =HLOOKUP(D25,'5ta'!$C$7:$CG$139,133,0) -> TRUE | Y25: =HLOOKUP(D25,'5ta'!$C$7:$CF$135,129,0) -> 0.14 | Z25: =VLOOKUP(D25,'[1]0220262'!$E$12:$AD$94,26,0) -> 0 | AB25: =VLOOKUP(D25,'[2]Archivo Excel Haberes Input'!$K$11:$K$80,1,0) -> 42035890
C26: 20 | D26: 42168737 | E26: MARTINEZ MURAYARI INES ROXANA | F26: CUSTOMER SERVICE EXPORTACIÓN | G26: COMERCIAL- VENTAS | H26: VENTAS | I26: =VLOOKUP(D26,'DÍAS EFECTIVOS LABORADOS 2025'!B:F,3,0) -> 43252 | M26: =VLOOKUP(D26,'DÍAS EFECTIVOS LABORADOS 2025'!B:O,14,0) -> 238 | N26: =+ROUND(VLOOKUP(D26,'INGRESOS 2025'!$B$7:$V$159,21,0),2) -> 65356.07 | O26: ACTIVO | P26: =$N$103*M26 -> 11717.294 | Q26: =$N$104*N26 -> 6491.652 | R26: =+ROUND(P26+Q26,2) -> 18208.95 | S26: =ROUND(HLOOKUP(D26,'5ta'!$C$7:$CF$118,112,0),2) -> 2549.25 | V26: =+ROUND(R26-T26-S26-U26,2) -> 15659.7 | W26: =+Y26*R26-S26 -> 0.003 | X26: =HLOOKUP(D26,'5ta'!$C$7:$CG$139,133,0) -> TRUE | Y26: =HLOOKUP(D26,'5ta'!$C$7:$CF$135,129,0) -> 0.14 | Z26: =VLOOKUP(D26,'[1]0220262'!$E$12:$AD$94,26,0) -> 0 | AB26: =VLOOKUP(D26,'[2]Archivo Excel Haberes Input'!$K$11:$K$80,1,0) -> 42168737
C27: 21 | D27: 42326063 | E27: MARTI ROJAS DE ZÁRATE ANGELA TERESA | I27: =VLOOKUP(D27,'DÍAS EFECTIVOS LABORADOS 2025'!B:F,3,0) -> 43900 | J27: =VLOOKUP(D27,'DÍAS EFECTIVOS LABORADOS 2025'!B:F,5,0) -> 45747 | M27: =VLOOKUP(D27,'DÍAS EFECTIVOS LABORADOS 2025'!B:O,14,0) -> 63 | N27: =+ROUND(VLOOKUP(D27,'INGRESOS 2025'!$B$7:$V$159,21,0),2) -> 75354.76 | O27: CESADO | P27: =$N$103*M27 -> 3101.6366 | Q27: =$N$104*N27 -> 7484.7965 | R27: =+ROUND(P27+Q27,2) -> 10586.43 | V27: =+ROUND(R27-T27-S27-U27,2) -> 10586.43 | Z27: =VLOOKUP(D27,'[1]0220262'!$E$12:$AD$94,26,0) -> #N/A
C28: 22 | D28: 42560153 | E28: VALDEZ CRUZ JOSEPH JOSUE | F28: PROCURADOR MARITIMO PAITA | G28: OPERACIONES PORTUARIAS | H28: OPERACIONES | I28: =VLOOKUP(D28,'DÍAS EFECTIVOS LABORADOS 2025'!B:F,3,0) -> 43222 | M28: =VLOOKUP(D28,'DÍAS EFECTIVOS LABORADOS 2025'!B:O,14,0) -> 229 | N28: =+ROUND(VLOOKUP(D28,'INGRESOS 2025'!$B$7:$V$159,21,0),2) -> 46483.98 | O28: ACTIVO | P28: =$N$103*M28 -> 11274.203 | Q28: =$N$104*N28 -> 4617.1354 | R28: =+ROUND(P28+Q28,2) -> 15891.34 | S28: =ROUND(HLOOKUP(D28,'5ta'!$C$7:$CF$118,112,0),2) -> 1271.31 | V28: =+ROUND(R28-T28-S28-U28,2) -> 14620.03 | W28: =+Y28*R28-S28 -> -0.0028 | X28: =HLOOKUP(D28,'5ta'!$C$7:$CG$139,133,0) -> TRUE | Y28: =HLOOKUP(D28,'5ta'!$C$7:$CF$135,129,0) -> 0.08 | Z28: =VLOOKUP(D28,'[1]0220262'!$E$12:$AD$94,26,0) -> 0 | AB28: =VLOOKUP(D28,'[2]Archivo Excel Haberes Input'!$K$11:$K$80,1,0) -> 42560153
C29: 23 | D29: 42646402 | E29: BALDOCEDA COLQUI YESENIA FLORA | F29: AUXILIAR DE LIMPIEZA | G29: ADMINISTRACION | H29: ADMINISTRACION | I29: =VLOOKUP(D29,'DÍAS EFECTIVOS LABORADOS 2025'!B:F,3,0) -> 44935 | M29: =VLOOKUP(D29,'DÍAS EFECTIVOS LABORADOS 2025'!B:O,14,0) -> 235 | N29: =+ROUND(VLOOKUP(D29,'INGRESOS 2025'!$B$7:$V$159,21,0),2) -> 28101.11 | O29: ACTIVO | P29: =$N$103*M29 -> 11569.597 | Q29: =$N$104*N29 -> 2791.2117 | R29: =+ROUND(P29+Q29,2) -> 14360.81 | S29: =ROUND(HLOOKUP(D29,'5ta'!$C$7:$CF$118,112,0),2) -> 246.5 | V29: =+ROUND(R29-T29-S29-U29,2) -> 14114.31 | X29: =HLOOKUP(D29,'5ta'!$C$7:$CG$139,133,0) -> FALSE | Y29: =HLOOKUP(D29,'5ta'!$C$7:$CF$145,134,0) -> 00% - 08% | Z29: =VLOOKUP(D29,'[1]0220262'!$E$12:$AD$94,26,0) -> 0 | AB29: =VLOOKUP(D29,'[2]Archivo Excel Haberes Input'!$K$11:$K$80,1,0) -> 42646402
C30: 24 | D30: 43393889 | E30: ZAPATA QUEVEDO KARINA JANET | I30: =VLOOKUP(D30,'DÍAS EFECTIVOS LABORADOS 2025'!B:F,3,0) -> 45631 | J30: =VLOOKUP(D30,'DÍAS EFECTIVOS LABORADOS 2025'!B:F,5,0) -> 45882 | M30: =VLOOKUP(D30,'DÍAS EFECTIVOS LABORADOS 2025'!B:O,14,0) -> 152 | N30: =+ROUND(VLOOKUP(D30,'INGRESOS 2025'!$B$7:$V$159,21,0),2) -> 38843.4 | O30: CESADO | P30: =$N$103*M30 -> 7483.3138 | Q30: =$N$104*N30 -> 3858.216 | R30: =+ROUND(P30+Q30,2) -> 11341.53 | V30: =+ROUND(R30-T30-S30-U30,2) -> 11341.53 | Z30: =VLOOKUP(D30,'[1]0220262'!$E$12:$AD$94,26,0) -> #N/A
C31: 25 | D31: 43426313 | E31: LOPEZ MENDOZA GIULIANA JANNET | F31: ANALISTA SENIOR DE DOCUMENTACIÓ Y VISTO BUENO | G31: DOCUMENTACION-VISTO BUENO | H31: OPERACIONES | I31: =VLOOKUP(D31,'DÍAS EFECTIVOS LABORADOS 2025'!B:F,3,0) -> 43206 | M31: =VLOOKUP(D31,'DÍAS EFECTIVOS LABORADOS 2025'!B:O,14,0) -> 219 | N31: =+ROUND(VLOOKUP(D31,'INGRESOS 2025'!$B$7:$V$159,21,0),2) -> 71138.4 | O31: ACTIVO | P31: =$N$103*M31 -> 10781.88 | Q31: =$N$104*N31 -> 7065.9962 | R31: =+ROUND(P31+Q31,2) -> 17847.88 | S31: =ROUND(HLOOKUP(D31,'5ta'!$C$7:$CF$118,112,0),2) -> 2498.7 | V31: =+ROUND(R31-T31-S31-U31,2) -> 15349.18 | W31: =+Y31*R31-S31 -> 0.0032 | X31: =HLOOKUP(D31,'5ta'!$C$7:$CG$139,133,0) -> TRUE | Y31: =HLOOKUP(D31,'5ta'!$C$7:$CF$135,129,0) -> 0.14 | Z31: =VLOOKUP(D31,'[1]0220262'!$E$12:$AD$94,26,0) -> 0 | AB31: =VLOOKUP(D31,'[2]Archivo Excel Haberes Input'!$K$11:$K$80,1,0) -> 43426313
C32: 26 | D32: 43643490 | E32: ESPINOZA RUA KARINNA ESPERANZA | I32: =VLOOKUP(D32,'DÍAS EFECTIVOS LABORADOS 2025'!B:F,3,0) -> 44348 | J32: =VLOOKUP(D32,'DÍAS EFECTIVOS LABORADOS 2025'!B:F,5,0) -> 45844 | M32: =VLOOKUP(D32,'DÍAS EFECTIVOS LABORADOS 2025'!B:O,14,0) -> 115 | N32: =+ROUND(VLOOKUP(D32,'INGRESOS 2025'!$B$7:$V$159,21,0),2) -> 62939.35 | O32: CESADO | P32: =$N$103*M32 -> 5661.7177 | Q32: =$N$104*N32 -> 6251.6054 | R32: =+ROUND(P32+Q32,2) -> 11913.32 | U32: 21.74 | V32: =+ROUND(R32-T32-S32-U32,2) -> 11891.58 | Z32: =VLOOKUP(D32,'[1]0220262'!$E$12:$AD$94,26,0) -> #N/A
C33: 27 | D33: 45282900 | E33: BELUPU GUTIERREZ CARLO DANIEL | F33: ANALISTA DE COMPRAS | G33: COMPRAS | H33: OPERACIONES | I33: =VLOOKUP(D33,'DÍAS EFECTIVOS LABORADOS 2025'!B:F,3,0) -> 45541 | M33: =VLOOKUP(D33,'DÍAS EFECTIVOS LABORADOS 2025'!B:O,14,0) -> 240 | N33: =+ROUND(VLOOKUP(D33,'INGRESOS 2025'!$B$7:$V$159,21,0),2) -> 41728.5 | O33: ACTIVO | P33: =$N$103*M33 -> 11815.759 | Q33: =$N$104*N33 -> 4144.7857 | R33: =+ROUND(P33+Q33,2) -> 15960.54 | S33: =ROUND(HLOOKUP(D33,'5ta'!$C$7:$CF$118,112,0),2) -> 1276.84 | V33: =+ROUND(R33-T33-S33-U33,2) -> 14683.7 | W33: =+Y33*R33-S33 -> 0.0032 | X33: =HLOOKUP(D33,'5ta'!$C$7:$CG$139,133,0) -> TRUE | Y33: =HLOOKUP(D33,'5ta'!$C$7:$CF$135,129,0) -> 0.08 | Z33: =VLOOKUP(D33,'[1]0220262'!$E$12:$AD$94,26,0) -> 0 | AB33: =VLOOKUP(D33,'[2]Archivo Excel Haberes Input'!$K$11:$K$80,1,0) -> 45282900
C34: 28 | D34: 45813056 | E34: ALFARO VILLACORTA VICTOR HUGO GARY | F34: JEFE DE OPERACIONES | G34: OPERACIONES PORTUARIAS | H34: OPERACIONES | I34: =VLOOKUP(D34,'DÍAS EFECTIVOS LABORADOS 2025'!B:F,3,0) -> 42948 | M34: =VLOOKUP(D34,'DÍAS EFECTIVOS LABORADOS 2025'!B:O,14,0) -> 221 | N34: =+ROUND(VLOOKUP(D34,'INGRESOS 2025'!$B$7:$V$159,21,0),2) -> 156914.37 | O34: ACTIVO | P34: =$N$103*M34 -> 10880.344 | Q34: =$N$104*N34 -> 15585.905 | R34: =+ROUND(P34+Q34,2) -> 26466.25 | S34: =ROUND(HLOOKUP(D34,'5ta'!$C$7:$CF$118,112,0),2) -> 4250.84 | V34: =+ROUND(R34-T34-S34-U34,2) -> 22215.41 | X34: =HLOOKUP(D34,'5ta'!$C$7:$CG$139,133,0) -> FALSE | Y34: =HLOOKUP(D34,'5ta'!$C$7:$CF$145,134,0) -> 14% - 17% | Z34: =VLOOKUP(D34,'[1]0220262'!$E$12:$AD$94,26,0) -> 0 | AB34: =VLOOKUP(D34,'[2]Archivo Excel Haberes Input'!$K$11:$K$80,1,0) -> 45813056
C35: 29 | D35: 45858948 | E35: CHAVEZ QUILCATE JULIA DEL PILAR | F35: ASISTENTE DE OPERACIONES PORTUARIAS | G35: OPERACIONES PORTUARIAS | H35: OPERACIONES | I35: =VLOOKUP(D35,'DÍAS EFECTIVOS LABORADOS 2025'!B:F,3,0) -> 44600 | M35: =VLOOKUP(D35,'DÍAS EFECTIVOS LABORADOS 2025'!B:O,14,0) -> 223 | N35: =+ROUND(VLOOKUP(D35,'INGRESOS 2025'!$B$7:$V$159,21,0),2) -> 41789.27 | O35: ACTIVO | P35: =$N$103*M35 -> 10978.809 | Q35: =$N$104*N35 -> 4150.8218 | R35: =+ROUND(P35+Q35,2) -> 15129.63 | S35: =ROUND(HLOOKUP(D35,'5ta'!$C$7:$CF$118,112,0),2) -> 1149.86 | V35: =+ROUND(R35-T35-S35-U35,2) -> 13979.77 | X35: =HLOOKUP(D35,'5ta'!$C$7:$CG$139,133,0) -> FALSE | Y35: =HLOOKUP(D35,'5ta'!$C$7:$CF$145,134,0) -> 00% - 08% | Z35: =VLOOKUP(D35,'[1]0220262'!$E$12:$AD$94,26,0) -> 0 | AB35: =VLOOKUP(D35,'[2]Archivo Excel Haberes Input'!$K$11:$K$80,1,0) -> 45858948
C36: 30 | D36: 46833118 | E36: MOSCAYZA NAZARIO STEPHANIE JULIANA | F36: ASISTENTE DE CONTABILIDAD | G36: CONTABILIDAD | H36: ADMINISTRACION | I36: =VLOOKUP(D36,'DÍAS EFECTIVOS LABORADOS 2025'!B:F,3,0) -> 45292 | M36: =VLOOKUP(D36,'DÍAS EFECTIVOS LABORADOS 2025'!B:O,14,0) -> 233 | N36: =+ROUND(VLOOKUP(D36,'INGRESOS 2025'!$B$7:$V$159,21,0),2) -> 38324.14 | O36: ACTIVO | P36: =$N$103*M36 -> 11471.132 | Q36: =$N$104*N36 -> 3806.6393 | R36: =+ROUND(P36+Q36,2) -> 15277.77 | S36: =ROUND(HLOOKUP(D36,'5ta'!$C$7:$CF$118,112,0),2) -> 1222.22 | V36: =+ROUND(R36-T36-S36-U36,2) -> 14055.55 | W36: =+Y36*R36-S36 -> 0.0016 | X36: =HLOOKUP(D36,'5ta'!$C$7:$CG$139,133,0) -> TRUE | Y36: =HLOOKUP(D36,'5ta'!$C$7:$CF$135,129,0) -> 0.08 | Z36: =VLOOKUP(D36,'[1]0220262'!$E$12:$AD$94,26,0) -> 0 | AB36: =VLOOKUP(D36,'[2]Archivo Excel Haberes Input'!$K$11:$K$80,1,0) -> 46833118
C37: 31 | D37: 47470495 | E37: VILLANTOY GUTIERREZ ANDRES DANIEL | F37: COORDINADOR DE OPERACIONES | G37: OPERACIONES PORTUARIAS | H37: OPERACIONES | I37: =VLOOKUP(D37,'DÍAS EFECTIVOS LABORADOS 2025'!B:F,3,0) -> 43206 | M37: =VLOOKUP(D37,'DÍAS EFECTIVOS LABORADOS 2025'!B:O,14,0) -> 224 | N37: =+ROUND(VLOOKUP(D37,'INGRESOS 2025'!$B$7:$V$159,21,0),2) -> 63233.48 | O37: ACTIVO | P37: =$N$103*M37 -> 11028.041 | Q37: =$N$104*N37 -> 6280.8206 | R37: =+ROUND(P37+Q37,2) -> 17308.86 | S37: =ROUND(HLOOKUP(D37,'5ta'!$C$7:$CF$118,112,0),2) -> 2423.24 | V37: =+ROUND(R37-T37-S37-U37,2) -> 14885.62 | W37: =+Y37*R37-S37 -> 0.0004 | X37: =HLOOKUP(D37,'5ta'!$C$7:$CG$139,133,0) -> TRUE | Y37: =HLOOKUP(D37,'5ta'!$C$7:$CF$135,129,0) -> 0.14 | Z37: =VLOOKUP(D37,'[1]0220262'!$E$12:$AD$94,26,0) -> 0 | AB37: =VLOOKUP(D37,'[2]Archivo Excel Haberes Input'!$K$11:$K$80,1,0) -> 47470495
C38: 32 | D38: 47472407 | E38: BARRANZUELA SANTOS MELISSA ANTONED | F38: ANALISTA DE COBRANZAS Y FACTURACION | G38: COBRANZAS | H38: ADMINISTRACION | I38: =VLOOKUP(D38,'DÍAS EFECTIVOS LABORADOS 2025'!B:F,3,0) -> 43374 | M38: =VLOOKUP(D38,'DÍAS EFECTIVOS LABORADOS 2025'!B:O,14,0) -> 224 | N38: =+ROUND(VLOOKUP(D38,'INGRESOS 2025'!$B$7:$V$159,21,0),2) -> 47055.4 | O38: ACTIVO | P38: =$N$103*M38 -> 11028.041 | Q38: =$N$104*N38 -> 4673.8931 | R38: =+ROUND(P38+Q38,2) -> 15701.93 | S38: =ROUND(HLOOKUP(D38,'5ta'!$C$7:$CF$118,112,0),2) -> 1256.15 | V38: =+ROUND(R38-T38-S38-U38,2) -> 14445.78 | W38: =+Y38*R38-S38 -> 0.0044 | X38: =HLOOKUP(D38,'5ta'!$C$7:$CG$139,133,0) -> TRUE | Y38: =HLOOKUP(D38,'5ta'!$C$7:$CF$135,129,0) -> 0.08 | Z38: =VLOOKUP(D38,'[1]0220262'!$E$12:$AD$94,26,0) -> 0 | AB38: =VLOOKUP(D38,'[2]Archivo Excel Haberes Input'!$K$11:$K$80,1,0) -> 47472407
C39: 33 | D39: 47668422 | E39: ROMAN PINTADO JULLISA IVETTE | F39: ASISTENTE SENIOR DE DOCUMENTACIÓN | G39: DOCUMENTACION-VISTO BUENO | H39: OPERACIONES | I39: =VLOOKUP(D39,'DÍAS EFECTIVOS LABORADOS 2025'!B:F,3,0) -> 43160 | M39: =VLOOKUP(D39,'DÍAS EFECTIVOS LABORADOS 2025'!B:O,14,0) -> 235 | N39: =+ROUND(VLOOKUP(D39,'INGRESOS 2025'!$B$7:$V$159,21,0),2) -> 48632.41 | O39: ACTIVO | P39: =$N$103*M39 -> 11569.597 | Q39: =$N$104*N39 -> 4830.5335 | R39: =+ROUND(P39+Q39,2) -> 16400.13 | S39: =ROUND(HLOOKUP(D39,'5ta'!$C$7:$CF$118,112,0),2) -> 1312.01 | V39: =+ROUND(R39-T39-S39-U39,2) -> 15088.12 | W39: =+Y39*R39-S39 -> 0.0004 | X39: =HLOOKUP(D39,'5ta'!$C$7:$CG$139,133,0) -> TRUE | Y39: =HLOOKUP(D39,'5ta'!$C$7:$CF$135,129,0) -> 0.08 | Z39: =VLOOKUP(D39,'[1]0220262'!$E$12:$AD$94,26,0) -> 0 | AB39: =VLOOKUP(D39,'[2]Archivo Excel Haberes Input'!$K$11:$K$80,1,0) -> 47668422
C40: 34 | D40: 47706283 | E40: ALIAGA DEL ROSARIO JOSEPH CHRISTHOPHER | F40: ASISTENTE DE VISTO BUENO | G40: DOCUMENTACION-VISTO BUENO | H40: OPERACIONES | I40: =VLOOKUP(D40,'DÍAS EFECTIVOS LABORADOS 2025'!B:F,3,0) -> 44539 | M40: =VLOOKUP(D40,'DÍAS EFECTIVOS LABORADOS 2025'!B:O,14,0) -> 234 | N40: =+ROUND(VLOOKUP(D40,'INGRESOS 2025'!$B$7:$V$159,21,0),2) -> 33537.66 | O40: ACTIVO | P40: =$N$103*M40 -> 11520.365 | Q40: =$N$104*N40 -> 3331.2104 | R40: =+ROUND(P40+Q40,2) -> 14851.58 | S40: =ROUND(HLOOKUP(D40,'5ta'!$C$7:$CF$118,112,0),2) -> 713.36 | V40: =+ROUND(R40-T40-S40-U40,2) -> 14138.22 | X40: =HLOOKUP(D40,'5ta'!$C$7:$CG$139,133,0) -> FALSE | Y40: =HLOOKUP(D40,'5ta'!$C$7:$CF$145,134,0) -> 00% - 08% | Z40: =VLOOKUP(D40,'[1]0220262'!$E$12:$AD$94,26,0) -> 0 | AB40: =VLOOKUP(D40,'[2]Archivo Excel Haberes Input'!$K$11:$K$80,1,0) -> 47706283
C41: 35 | D41: 47806538 | E41: RAMIREZ ALBINAGORTA ENRIQUE ALEJANDRO | F41: ANALISTA CUSTOMER SERVICES EXPORTACION | G41: COMERCIAL- VENTAS | H41: VENTAS | I41: =VLOOKUP(D41,'DÍAS EFECTIVOS LABORADOS 2025'!B:F,3,0) -> 43402 | M41: =VLOOKUP(D41,'DÍAS EFECTIVOS LABORADOS 2025'!B:O,14,0) -> 246 | N41: =+ROUND(VLOOKUP(D41,'INGRESOS 2025'!$B$7:$V$159,21,0),2) -> 43663.7 | O41: ACTIVO | P41: =$N$103*M41 -> 12111.153 | Q41: =$N$104*N41 -> 4337.0042 | R41: =+ROUND(P41+Q41,2) -> 16448.16 | S41: =ROUND(HLOOKUP(D41,'5ta'!$C$7:$CF$118,112,0),2) -> 1388.32 | V41: =+ROUND(R41-T41-S41-U41,2) -> 15059.84 | X41: =HLOOKUP(D41,'5ta'!$C$7:$CG$139,133,0) -> FALSE | Y41: =HLOOKUP(D41,'5ta'!$C$7:$CF$145,134,0) -> 08% - 14% | Z41: =VLOOKUP(D41,'[1]0220262'!$E$12:$AD$94,26,0) -> 0 | AB41: =VLOOKUP(D41,'[2]Archivo Excel Haberes Input'!$K$11:$K$80,1,0) -> 47806538
...

Sheet BOLETA
L1: 4
B5: PARTICIPACION EN LAS UTILIDADES POR EL EJERCICIO GRAVABLE 2025
B6: ( D.Leg. Nº 892 y el D.S. Nº 009-98-TR )
B11: CITIKOLD DEL PERU S.A.C., con RUC Nº 20601767423 domiciliado fiscal en AV. JAVIER PRADO OESTE NRO. 757 INT. 1303 URB. SAN FELIPE (EDIFICIO SKYTOWER), DISTRITO DE MAGDALENA DEL MAR, PROVINCIA Y DEPARTAMENTO DE LIMA, debidamente representada por el Sr. SALAZAR DE LA ROCHA JUAN CARLOS GERMAN con DNI 07537953 , en su calidad de empleador y en cumplimiento de lo dispuesto por el D.Leg. Nº 892 y el D.S. Nº 009-98-TR., deja constancia de la determinación, distribución y pago de la participación en las utilidades al :
B17: Sr.(a) | C17: =VLOOKUP($L$1,'UTILIDADES 2025'!C6:V97,3,0) -> RUIZ SALCEDO MARIA DE LOURDES | G17: identificado(a) con DNI / C.E. | J17: =VLOOKUP($L$1,'UTILIDADES 2025'!C6:V97,2,0) -> 08887801 | K17: ,
B18: correspondiente al ejercicio gravable 2025, calculado en base al siguiente detalle:
B21: 1. UTILIDAD POR DISTRIBUIR
B23: - Renta anual de la empresa antes de impuestos : | J23: =+'UTILIDADES 2025'!N99 -> 33151080
B25: - Porcentaje a distribuir : | J25: 0.05
B27: - Monto a distribuir : | J27: =+J23*J25 -> 1657554
B29: 2. CALCULO DE LA PARTICIPACION
B31: 2.1. SEGÚN LOS DÍAS LABORADOS
B33: - Número total de días laborados durante el ejercicio 2025 por todos los trabajadores
B34: de la empresa con derecho a percibir utilidades : | J34: =+'UTILIDADES 2025'!M97 -> 16834
B36: - Número de días laborados durante el ejercicio 2025 por el trabajador : | J36: =VLOOKUP($L$1,'UTILIDADES 2025'!C7:V96,11,0) -> 222
B38: - Participación del trabajador según los días laborados : | J38: =VLOOKUP($L$1,'UTILIDADES 2025'!C7:V96,14,0) -> 10929.577
B40: 2.2. SEGÚN LAS REMUNERACION PERCIBIDAS
B42: - Remuneración computable total pagada durante el ejercicio 2025 a todos los
B43: trabajadores de la empresa : | J43: =+'UTILIDADES 2025'!N97 -> 8343886.5
B45: - Remuneración computable percibida durante el ejercicio 2025 por el trabajador : | J45: =VLOOKUP($L$1,'UTILIDADES 2025'!C7:V96,12,0) -> 181223.64
B47: - Participación del trabajador según las remuneraciones percibidas : | J47: =VLOOKUP($L$1,'UTILIDADES 2025'!C7:V96,15,0) -> 18000.483
B49: 3. MONTO DE LA PARTICIPACIÓN A PERCIBIR POR EL TRABAJADOR
B51: - Participación según los días laborados : | J51: =+J38 -> 10929.577
B53: - Participación según las remuneraciones percibidas : | J53: =+J47 -> 18000.483
B55: - Total de la participación del trabajador en las utilidades : | J55: =ROUND(SUM(J51:J53),2) -> 28930.06
B57: - Descuento de Renta de Quinta Categoria : | J57: =VLOOKUP($L$1,'UTILIDADES 2025'!C7:V96,17,0) -> 4918.11
B59: - Otros descuentos | J59: =VLOOKUP($L$1,'UTILIDADES 2025'!C7:V96,19,0) -> 0
B61: TOTAL DE LA PARTICIPACION NETA DEL TRABAJADOR EN LAS UTILIDADES | J61: =+J55-J57-J59 -> 24011.95 | M61: =VLOOKUP($L$1,'UTILIDADES 2025'!C7:ZV96,20,0) -> 24011.95 | N61: =+J61-M61 -> 0
B64: Lima, 25 de Marzo del 2026
A74: =+C17 -> RUIZ SALCEDO MARIA DE LOURDES | H74: CITIKOLD DEL PERU S.A.C
B75: DNI / C.E. : | C75: =+J17 -> 08887801 | H75: RUC : 20601767423

Sheet 5ta
B1: PROYECTADO DE RENTA QUINTA CATEGORÍA
B3: PERIODO 2026 | CC3: =MONTH(CC6) -> 1
B4: Nro.
B5: OBS | V5: RIA | AB5: RIA | AR5: RIA | AS5: RIA | AT5: RIA
B6: FECHA DE INICIO | C6: 42948 | D6: 43003 | E6: 43374 | F6: 42985 | G6: 43243 | H6: 42985 | I6: 43357 | J6: 42985 | K6: 42985 | L6: 43160 | M6: 43206 | N6: 43252 | O6: 42985 | P6: 43402 | Q6: 43160 | R6: 43070 | S6: 43382 | T6: 42985 | U6: 43003 | V6: 43003 | W6: 43222 | X6: 43206 | Y6: 43497 | Z6: 43530 | AA6: 43525 | AB6: 43678 | AC6: 43724 | AD6: 43973 | AE6: 44111 | AF6: 44432 | AG6: 44453 | AH6: 44483 | AI6: 44483 | AJ6: 44539 | AK6: 44600 | AL6: 44636 | AM6: 44677 | AN6: 44799 | AO6: 44911 | AP6: 44935 | AQ6: 45125 | AR6: 45170 | AS6: 45170 | AT6: 45170 | AU6: 45181 | AV6: 45181 | AW6: 45261 | AX6: 45261 | AY6: 45292 | AZ6: 45313 | BA6: 45481 | BB6: 45481 | BC6: 45541 | BD6: 45574 | BE6: 45600 | BF6: 45627 | BG6: 45628 | BH6: 45658 | BI6: 45689 | BJ6: 45717 | BK6: 45784 | BL6: 45839 | BM6: 45852 | BN6: 45870 | BO6: 45887 | BP6: 45908 | BQ6: 45894 | BR6: 45887 | BS6: 45931 | BT6: 45931 | BU6: 45943 | BV6: 45943 | BW6: 45964 | BX6: 45964 | BY6: 45962 | BZ6: 45992 | CA6: 45992 | CB6: 46002 | CC6: 46024 | CD6: 46027 | CE6: 46023 | CF6: 46041
B7: DNI/C.E | C7: 45813056 | D7: 09335023 | E7: 47472407 | F7: 09410158 | G7: 48588627 | H7: 09542822 | I7: 07262343 | J7: 40537272 | K7: 25710966 | L7: 08693248 | M7: 43426313 | N7: 42168737 | O7: 40508445 | P7: 47806538 | Q7: 47668422 | R7: 10346719 | S7: 10725704 | T7: 09867320 | U7: 08887801 | V7: 07537953 | W7: 42560153 | X7: 47470495 | Y7: 74080395 | Z7: 73958636 | AA7: 71467210 | AB7: 002120932 | AC7: 72152204 | AD7: 71569497 | AE7: 25828090 | AF7: 72016504 | AG7: 72686896 | AH7: 74069271 | AI7: 72001771 | AJ7: 47706283 | AK7: 45858948 | AL7: 76723256 | AM7: 25769631 | AN7: 70857319 | AO7: 47867088 | AP7: 42646402 | AQ7: 76084478 | AR7: 005608621 | AS7: 006123587 | AT7: 005698394 | AU7: 76163280 | AV7: 42035890 | AW7: 002420607 | AX7: 77473806 | AY7: 46833118 | AZ7: 72152557 | BA7: 41047057 | BB7: 73115211 | BC7: 45282900 | BD7: 72857524 | BE7: 71726981 | BF7: 48035238 | BG7: 75743277 | BH7: 76055775 | BI7: 74723670 | BJ7: 008938904 | BK7: 78377581 | BL7: 42151178 | BM7: 73218422 | BN7: 48332716 | BO7: 48109666 | BP7: 74611823 | BQ7: 76644670 | BR7: 45533404 | BS7: 72531605 | BT7: 75267086 | BU7: 46137609 | BV7: 10659025 | BW7: 47500764 | BX7: 46854908 | BY7: 72902664 | BZ7: 72859721 | CA7: 40865746 | CB7: 74376927 | CC7: 48280194 | CD7: 73881843 | CE7: 70447361 | CF7: 70000534
B8: EPS | C8: SI | D8: SI | E8: SI | F8: SI | G8: SI | H8: SI | I8: SI | J8: SI | K8: SI | L8: NO | M8: NO | N8: SI | O8: NO | P8: SI | Q8: SI | R8: NO | S8: SI | T8: SI | U8: SI | V8: SI | W8: SI | X8: NO | Y8: SI | Z8: SI | AA8: SI | AB8: SI | AC8: SI | AD8: SI | AE8: NO | AF8: SI | AG8: SI | AH8: SI | AI8: SI | AJ8: SI | AK8: NO | AL8: SI | AM8: NO | AN8: SI | AO8: NO | AP8: NO | AQ8: NO | AR8: NO | AS8: NO | AT8: NO | AU8: SI | AV8: SI | AW8: NO | AX8: SI | AY8: SI | AZ8: SI | BA8: SI | BB8: SI | BC8: SI | BD8: SI | BE8: SI | BF8: SI | BG8: SI | BH8: NO | BI8: NO | BJ8: NO | BK8: SI | BL8: SI | BM8: SI | BN8: SI | BO8: SI | BP8: SI | BQ8: NO | BR8: NO | BS8: SI | BT8: SI | BU8: NO | BV8: NO | BW8: NO | BX8: NO | BY8: SI | BZ8: NO | CA8: NO | CB8: NO | CC8: NO | CD8: NO | CE8: SI | CF8: NO
B9: REGIMEN | C9: GENERAL | D9: GENERAL | E9: GENERAL | F9: GENERAL | G9: GENERAL | H9: GENERAL | I9: GENERAL | J9: GENERAL | K9: GENERAL | L9: GENERAL | M9: GENERAL | N9: GENERAL | O9: GENERAL | P9: GENERAL | Q9: GENERAL | R9: GENERAL | S9: GENERAL | T9: GENERAL | U9: GENERAL | V9: GENERAL | W9: GENERAL | X9: GENERAL | Y9: GENERAL | Z9: GENERAL | AA9: GENERAL | AB9: GENERAL | AC9: GENERAL | AD9: GENERAL | AE9: GENERAL | AF9: GENERAL | AG9: GENERAL | AH9: GENERAL | AI9: GENERAL | AJ9: GENERAL | AK9: GENERAL | AL9: GENERAL | AM9: GENERAL | AN9: GENERAL | AO9: GENERAL | AP9: GENERAL | AQ9: GENERAL | AR9: GENERAL | AS9: GENERAL | AT9: GENERAL | AU9: GENERAL | AV9: GENERAL | AW9: GENERAL | AX9: GENERAL | AY9: GENERAL | AZ9: GENERAL | BA9: GENERAL | BB9: GENERAL | BC9: GENERAL | BD9: GENERAL | BE9: GENERAL | BF9: GENERAL | BG9: GENERAL | BH9: GENERAL | BI9: GENERAL | BJ9: GENERAL | BK9: GENERAL | BL9: GENERAL | BM9: GENERAL | BN9: GENERAL | BO9: GENERAL | BP9: GENERAL | BQ9: GENERAL | BR9: GENERAL | BS9: GENERAL | BT9: GENERAL | BU9: GENERAL | BV9: GENERAL | BW9: GENERAL | BX9: GENERAL | BY9: GENERAL | BZ9: GENERAL | CA9: GENERAL | CB9: GENERAL | CC9: GENERAL | CD9: GENERAL | CE9: GENERAL | CF9: GENERAL
B10: PERIODO | C10: ALFARO VILLACORTA VICTOR HUGO GARY | D10: AYOS JUNGBLUTH MARIANA | E10: BARRANZUELA SANTOS MELISSA ANTONED | F10: BONATTI CARRASCO JORGE LUIS | G10: CARRERA RAMIREZ KATTYA HELEN | H10: CAVERO RODRIGUEZ JANNYE VERONICA | I10: CIEZA AGUILAR CESAR AUGUSTO | J10: GARRIDO LEON CARLA VERONICA | K10: GIURIA CONSTANTINO HUMBERTO ANDRES | L10: IZARRA CARRASCO IRINA KAREM | M10: LOPEZ MENDOZA GIULIANA JANNET | N10: MARTINEZ MURAYARI DE PEREZ INES ROXANA | O10: MEJIA CAVERO PAOLA CECILIA | P10: RAMIREZ ALBINAGORTA ENRIQUE ALEJANDRO | Q10: ROMAN PINTADO JULLISA IVETTE | R10: ROMERO ORDOÑEZ EDUARDO ARTURO | S10: RONCEROS GONZALES LUISA MARILIN | T10: ROTALDE DEL RIO XIMENA MARIA | U10: RUIZ SALCEDO MARIA DE LOURDES | V10: SALAZAR DE LA ROCHA JUAN CARLOS | W10: VALDEZ CRUZ JOSEPH JOSUE | X10: VILLANTOY GUTIERREZ ANDRES DANIEL | Y10: AVALOS MORANTE KATHERINE ALEXANDRA | Z10: ALEJOS EGUSQUIZA AYXA JELUZETH | AA10: ANTAYHUA GRABIEL ISAAC ISMAEL | AB10: GAME LOAIZA MANUEL XAVIER | AC10: HUAMAN COLLANTES WALTER JUNIOR | AD10: CAMPOS PALOMINO DIANA MARGARITA | AE10: CHERO ORTIZ MARTIN ALEJANDRO | AF10: GUTIERREZ DE LA CRUZ MIGUEL ANGEL | AG10: REBATTA ROJAS GONZALO | AH10: HUAMANI ALTAMIRANO GABRIELA SABRINA | AI10: GUEVARA SALINAS BRYAN GUSTAVO | AJ10: ALIAGA DEL ROSARIO JOSEPH CHRISTHOPHER | AK10: CHAVEZ QUILCATE JULIA DEL PILAR | AL10: REYNA CORTEZ PATRICK ADAMS | AM10: RUIZ TORRES CESAR AUGUSTO | AN10: SAKAY MORISAKI LUIS CARLOS | AO10: ROSALES ATOCHE ROXANA IVETTE | AP10: BALDOCEDA COLQUI YESENIA FLORA | AQ10: SANCHEZ AUCCAPURE JILLS KRAINEEM | AR10: GAME TRIVIÑO MARIA JOSE | AS10: GAME TRIVIÑO MANUEL XAVIER | AT10: GAME TRIVIÑO JUAN ANDRES | AU10: BENITES OTERO YRINNA | AV10: CASTAÑEDA CARRION VIVIEN | AW10: ESCALANTE ZUÑIGA DAVID | AX10: SANDOVAL GONZALES YASIRA JASMIN | AY10: MOSCAYZA NAZARIO STEPHANIE JULIANA | AZ10: ENCALADA PRADA GLORIA STEFANY | BA10: GALLEGOS BLAS LUIS MIGUEL | BB10: TORRES TORRES ANA PAULA | BC10: BELUPU GUTIERREZ CARLO DANIEL | BD10: SANCHEZ VALDEZ MACARENA | BE10: CRUZ QUISPE GEYDI ANTONELA | BF10: YUCRA MANCILLA AHRON | BG10: MALPARTIDA CASTILLO CLAUDIA | BH10: ALAMA BERECHE ROYAL ANTHONY | BI10: QUINTO CAMAHUALI LISETH CHARO | BJ10: CABEZAS RUBIO JORGE ARTURO | BK10: ROMAN RENTERIA ZAIDA YASMIN | BL10: BORDA LEON ROSARIO LIZBETH | BM10: VERA HUAMANCHUMO ANA PAULA | BN10: GUILLEN QUEZADA EMELY HARUMI | BO10: CCAPA SIGUEÑAS SILENE DORA | BP10: CARDENAS CARDENAS LESLIE ELIZABETH | BQ10: MARTINEZ HUAMAN GABRIELA NICOLE | BR10: CASTILLO SANDOVAL MARIA ISABEL | BS10: ROBINSON TORIBIO SARA JANET | BT10: ZETA CORONADO SHAHIRA CELIA | BU10: FERNANDEZ MALASQUEZ KATHERINE | BV10: LEON FUENTES ROCIO MATILDE | BW10: VILLANUEVA TORRES GERALDINE CYNTHIA | BX10: MURGA ESPINOZA YAJAIRA LISBEL | BY10: DEXTRE ZUBIETA ELA SIBELY | BZ10: ESPINOZA REYES LIZ KERALDIL | CA10: OLAYA RAMOS GLADYS MARLENY | CB10: AMODEO GORDILLO ANGIE ESTEFANI | CC10: BAZAN ANAMPA JOE RAUL | CD10: GARCIA SARMIENTO HANZ ENRIQUE | CE10: SAAVEDRA PAREDES MIGUEL ANGEL | CF10: CORREA CORREA STEFANY DEL SOCORRO
B11: SUELDO + ASIG. FAM. + VACACIONES+DME+ LIC CON GOCE
B12: CERTIFICADO DE 5TA
B13: ENERO | C13: 9920 | D13: 11933.5 | E13: 3200 | F13: 4600.87 | G13: 2597.32 | H13: 8591.75 | I13: 3386.03 | J13: 10113 | K13: 7208.7233 | L13: 5434.21 | M13: 4913 | N13: 4377.17 | O13: 5153 | P13: 3575.55 | Q13: 3242.6 | R13: 4113 | S13: 8113 | T13: 15131.83 | U13: 12090.87 | V13: 38870.55 | W13: 3000 | X13: 5022.7767 | Y13: 9999.9967 | Z13: 113 | AA13: 3489.06 | AB13: 150204.29 | AC13: 3669.46 | AD13: 2313 | AE13: 3672.97 | AF13: 2231.87 | AG13: 2977.12 | AH13: 2422.08 | AI13: 2958.75 | AJ13: 2264.87 | AK13: 2588.21 | AL13: 2551.03 | AM13: 2021.31 | AN13: 2195.42 | AO13: 2297.14 | AP13: 1913 | AQ13: 2000 | AR13: 19841.631 | AS13: 23852.223 | AT13: 19841.631 | AU13: 4700 | AV13: 6499.9967 | AW13: 21855.5 | AX13: 2313 | AY13: 2577.9 | AZ13: 2588.21 | BA13: 6113 | BB13: 2244.98 | BC13: 3102.7967 | BD13: 2995 | BE13: 1998.58 | BF13: 3185.6 | BG13: 3500 | BH13: 3194.67 | BI13: 1939.2 | BJ13: 4014 | BK13: 2800 | BL13: 11113 | BM13: 2500 | BN13: 3500 | BO13: 4599.9967 | BP13: 3100 | BQ13: 2177.27 | BR13: 2000 | BS13: 4100 | BT13: 1797 | BU13: 3778.31 | BV13: 1913 | BW13: 2281.65 | BX13: 5000 | BY13: 5113 | BZ13: 1350 | CA13: 6500 | CB13: 1500 | CC13: 4946.3333 | CD13: 2059.3 | CE13: 3700 | CF13: 1480
B14: FEBRERO | C14: 9920 | D14: 12000 | E14: 3200 | F14: 4593.97 | G14: 2569.35 | H14: 8635.6 | I14: 3620.54 | J14: 10135.6 | K14: 7154.4333 | L14: 5113 | M14: 5073.79 | N14: 4276.86 | O14: 5196.58 | P14: 3498 | Q14: 3332.3133 | R14: 4107.67 | S14: 8180.8 | T14: 15116.77 | U14: 12113 | V14: 39103.07 | W14: 2997.25 | X14: 5050.3733 | Y14: 10000 | Z14: 2393.7033 | AA14: 3500 | AB14: 153110.97 | AC14: 3309.74 | AD14: 2343.1333 | AE14: 3653.47 | AF14: 2236.55 | AG14: 2989.42 | AH14: 2425.31 | AI14: 2937.5 | AJ14: 2232.29 | AK14: 2600.9267 | AL14: 2528.5 | AM14: 1913 | AN14: 2185.42 | AO14: 2321.27 | AP14: 1913 | AQ14: 2000 | AR14: 19956.211 | AS14: 24005.073 | AT14: 19956.211 | AU14: 4700 | AV14: 6500.0033 | AW14: 21972.5 | AX14: 2361.9667 | AY14: 2582.8233 | AZ14: 2684.4567 | BA14: 6124.3 | BB14: 2358.3133 | BC14: 3100 | BD14: 2964.87 | BE14: 2006.59 | BF14: 0 | BG14: 3500.0033 | BH14: 3200 | BI14: 1913 | BJ14: 4035.6 | BK14: 2798.02 | BL14: 11113 | BM14: 2493.44 | BN14: 0 | BO14: 4600 | BP14: 3081.79 | BQ14: 2185.7 | BR14: 2000 | BS14: 4100 | BT14: 1797.15 | BU14: 3792.9667 | BV14: 1913 | BW14: 2268.91 | BX14: 5000 | BY14: 5113 | BZ14: 1350 | CA14: 6500 | CB14: 1500 | CC14: 5022.79 | CD14: 2356.3 | CE14: 3700 | CF14: 3700
B15: MARZO | C15: 9920 | D15: 12000 | E15: 3200 | F15: 4713 | G15: 2613 | H15: 8613 | I15: 3113 | J15: 10113 | K15: 7113 | L15: 5113 | M15: 4913 | N15: 4413 | O15: 5153 | P15: 3600 | Q15: 3313 | R15: 4113 | S15: 8113 | T15: 15113 | U15: 12113 | V15: 39076.7 | W15: 3000 | X15: 5000 | Y15: 10000 | Z15: 3613 | AA15: 3500 | AB15: 153110.97 | AC15: 3413 | AD15: 2313 | AE15: 3713 | AF15: 2313 | AG15: 3000 | AH15: 2500 | AI15: 3000 | AJ15: 2313 | AK15: 2613 | AL15: 2600 | AM15: 1913 | AN15: 2200 | AO15: 2313 | AP15: 1913 | AQ15: 2000 | AR15: 19956.211 | AS15: 24005.073 | AT15: 19956.211 | AU15: 4700 | AV15: 6500 | AW15: 21972.5 | AX15: 2313 | AY15: 2613 | AZ15: 2613 | BA15: 6113 | BB15: 2313 | BC15: 3100 | BD15: 3000 | BE15: 2000 | BF15: 0 | BG15: 3500 | BH15: 3200 | BI15: 1913 | BJ15: 4035.6 | BK15: 2800 | BL15: 11113 | BM15: 2500 | BN15: 0 | BO15: 4600 | BP15: 3100 | BQ15: 2200 | BR15: 2000 | BS15: 4100 | BT15: 1800 | BU15: 3813 | BV15: 1913 | BW15: 2313 | BX15: 5000 | BY15: 5113 | BZ15: 1350 | CA15: 6500 | CB15: 1500 | CC15: 5113 | CD15: 2400 | CE15: 3700 | CF15: 3700
B16: ABRIL | C16: 9920 | D16: 12000 | E16: 3200 | F16: 4713 | G16: 2613 | H16: 8613 | I16: 3113 | J16: 10113 | K16: 7113 | L16: 5113 | M16: 4913 | N16: 4413 | O16: 5153 | P16: 3600 | Q16: 3313 | R16: 4113 | S16: 8113 | T16: 15113 | U16: 12113 | V16: 39076.7 | W16: 3000 | X16: 5000 | Y16: 10000 | Z16: 3613 | AA16: 3500 | AB16: 153110.97 | AC16: 3413 | AD16: 2313 | AE16: 3713 | AF16: 2313 | AG16: 3000 | AH16: 2500 | AI16: 3000 | AJ16: 2313 | AK16: 2613 | AL16: 2600 | AM16: 1913 | AN16: 2200 | AO16: 2313 | AP16: 1913 | AQ16: 2000 | AR16: 19956.211 | AS16: 24005.073 | AT16: 19956.211 | AU16: 4700 | AV16: 6500 | AW16: 21972.5 | AX16: 2313 | AY16: 2613 | AZ16: 2613 | BA16: 6113 | BB16: 2313 | BC16: 3100 | BD16: 3000 | BE16: 2000 | BF16: 0 | BG16: 3500 | BH16: 3200 | BI16: 1913 | BJ16: 4035.6 | BK16: 2800 | BL16: 11113 | BM16: 2500 | BN16: 0 | BO16: 4600 | BP16: 3100 | BQ16: 2200 | BR16: 2000 | BS16: 4100 | BT16: 1800 | BU16: 3813 | BV16: 1913 | BW16: 2313 | BX16: 5000 | BY16: 5113 | BZ16: 1350 | CA16: 6500 | CB16: 1500 | CC16: 5113 | CD16: 2400 | CE16: 3700 | CF16: 3700
B17: MAYO | C17: 9920 | D17: 12000 | E17: 3200 | F17: 4713 | G17: 2613 | H17: 8613 | I17: 3113 | J17: 10113 | K17: 7113 | L17: 5113 | M17: 4913 | N17: 4413 | O17: 5153 | P17: 3600 | Q17: 3313 | R17: 4113 | S17: 8113 | T17: 15113 | U17: 12113 | V17: 39076.7 | W17: 3000 | X17: 5000 | Y17: 10000 | Z17: 3613 | AA17: 3500 | AB17: 153110.97 | AC17: 3413 | AD17: 2313 | AE17: 3713 | AF17: 2313 | AG17: 3000 | AH17: 2500 | AI17: 3000 | AJ17: 2313 | AK17: 2613 | AL17: 2600 | AM17: 1913 | AN17: 2200 | AO17: 2313 | AP17: 1913 | AQ17: 2000 | AR17: 19956.211 | AS17: 24005.073 | AT17: 19956.211 | AU17: 4700 | AV17: 6500 | AW17: 21972.5 | AX17: 2313 | AY17: 2613 | AZ17: 2613 | BA17: 6113 | BB17: 2313 | BC17: 3100 | BD17: 3000 | BE17: 2000 | BF17: 0 | BG17: 3500 | BH17: 3200 | BI17: 1913 | BJ17: 4035.6 | BK17: 2800 | BL17: 11113 | BM17: 2500 | BN17: 0 | BO17: 4600 | BP17: 3100 | BQ17: 2200 | BR17: 2000 | BS17: 4100 | BT17: 1800 | BU17: 3813 | BV17: 1913 | BW17: 2313 | BX17: 5000 | BY17: 5113 | BZ17: 1350 | CA17: 6500 | CB17: 1500 | CC17: 5113 | CD17: 2400 | CE17: 3700 | CF17: 3700
B18: JUNIO | C18: 9920 | D18: 12000 | E18: 3200 | F18: 4713 | G18: 2613 | H18: 8613 | I18: 3113 | J18: 10113 | K18: 7113 | L18: 5113 | M18: 4913 | N18: 4413 | O18: 5153 | P18: 3600 | Q18: 3313 | R18: 4113 | S18: 8113 | T18: 15113 | U18: 12113 | V18: 39076.7 | W18: 3000 | X18: 5000 | Y18: 10000 | Z18: 3613 | AA18: 3500 | AB18: 153110.97 | AC18: 3413 | AD18: 2313 | AE18: 3713 | AF18: 2313 | AG18: 3000 | AH18: 2500 | AI18: 3000 | AJ18: 2313 | AK18: 2613 | AL18: 2600 | AM18: 1913 | AN18: 2200 | AO18: 2313 | AP18: 1913 | AQ18: 2000 | AR18: 19956.211 | AS18: 24005.073 | AT18: 19956.211 | AU18: 4700 | AV18: 6500 | AW18: 21972.5 | AX18: 2313 | AY18: 2613 | AZ18: 2613 | BA18: 6113 | BB18: 2313 | BC18: 3100 | BD18: 3000 | BE18: 2000 | BF18: 0 | BG18: 3500 | BH18: 3200 | BI18: 1913 | BJ18: 4035.6 | BK18: 2800 | BL18: 11113 | BM18: 2500 | BN18: 0 | BO18: 4600 | BP18: 3100 | BQ18: 2200 | BR18: 2000 | BS18: 4100 | BT18: 1800 | BU18: 3813 | BV18: 1913 | BW18: 2313 | BX18: 5000 | BY18: 5113 | BZ18: 1350 | CA18: 6500 | CB18: 1500 | CC18: 5113 | CD18: 2400 | CE18: 3700 | CF18: 3700
B19: JULIO | C19: 9920 | D19: 12000 | E19: 3200 | F19: 4713 | G19: 2613 | H19: 8613 | I19: 3113 | J19: 10113 | K19: 7113 | L19: 5113 | M19: 4913 | N19: 4413 | O19: 5153 | P19: 3600 | Q19: 3313 | R19: 4113 | S19: 8113 | T19: 15113 | U19: 12113 | V19: 39076.7 | W19: 3000 | X19: 5000 | Y19: 10000 | Z19: 3613 | AA19: 3500 | AB19: 153110.97 | AC19: 3413 | AD19: 2313 | AE19: 3713 | AF19: 2313 | AG19: 3000 | AH19: 2500 | AI19: 3000 | AJ19: 2313 | AK19: 2613 | AL19: 2600 | AM19: 1913 | AN19: 2200 | AO19: 2313 | AP19: 1913 | AQ19: 2000 | AR19: 19956.211 | AS19: 24005.073 | AT19: 19956.211 | AU19: 4700 | AV19: 6500 | AW19: 21972.5 | AX19: 2313 | AY19: 2613 | AZ19: 2613 | BA19: 6113 | BB19: 2313 | BC19: 3100 | BD19: 3000 | BE19: 2000 | BF19: 0 | BG19: 3500 | BH19: 3200 | BI19: 1913 | BJ19: 4035.6 | BK19: 2800 | BL19: 11113 | BM19: 2500 | BN19: 0 | BO19: 4600 | BP19: 3100 | BQ19: 2200 | BR19: 2000 | BS19: 4100 | BT19: 1800 | BU19: 3813 | BV19: 1913 | BW19: 2313 | BX19: 5000 | BY19: 5113 | BZ19: 1350 | CA19: 6500 | CB19: 1500 | CC19: 5113 | CD19: 2400 | CE19: 3700 | CF19: 3700
B20: AGOSTO | C20: 9920 | D20: 12000 | E20: 3200 | F20: 4713 | G20: 2613 | H20: 8613 | I20: 3113 | J20: 10113 | K20: 7113 | L20: 5113 | M20: 4913 | N20: 4413 | O20: 5153 | P20: 3600 | Q20: 3313 | R20: 4113 | S20: 8113 | T20: 15113 | U20: 12113 | V20: 39076.7 | W20: 3000 | X20: 5000 | Y20: 10000 | Z20: 3613 | AA20: 3500 | AB20: 153110.97 | AC20: 3413 | AD20: 2313 | AE20: 3713 | AF20: 2313 | AG20: 3000 | AH20: 2500 | AI20: 3000 | AJ20: 2313 | AK20: 2613 | AL20: 2600 | AM20: 1913 | AN20: 2200 | AO20: 2313 | AP20: 1913 | AQ20: 2000 | AR20: 19956.211 | AS20: 24005.073 | AT20: 19956.211 | AU20: 4700 | AV20: 6500 | AW20: 21972.5 | AX20: 2313 | AY20: 2613 | AZ20: 2613 | BA20: 6113 | BB20: 2313 | BC20: 3100 | BD20: 3000 | BE20: 2000 | BF20: 0 | BG20: 3500 | BH20: 3200 | BI20: 1913 | BJ20: 4035.6 | BK20: 2800 | BL20: 11113 | BM20: 2500 | BN20: 0 | BO20: 4600 | BP20: 3100 | BQ20: 2200 | BR20: 2000 | BS20: 4100 | BT20: 1800 | BU20: 3813 | BV20: 1913 | BW20: 2313 | BX20: 5000 | BY20: 5113 | BZ20: 1350 | CA20: 6500 | CB20: 1500 | CC20: 5113 | CD20: 2400 | CE20: 3700 | CF20: 3700
B21: SEPTIEMBRE | C21: 9920 | D21: 12000 | E21: 3200 | F21: 4713 | G21: 2613 | H21: 8613 | I21: 3113 | J21: 10113 | K21: 7113 | L21: 5113 | M21: 4913 | N21: 4413 | O21: 5153 | P21: 3600 | Q21: 3313 | R21: 4113 | S21: 8113 | T21: 15113 | U21: 12113 | V21: 39076.7 | W21: 3000 | X21: 5000 | Y21: 10000 | Z21: 3613 | AA21: 3500 | AB21: 153110.97 | AC21: 3413 | AD21: 2313 | AE21: 3713 | AF21: 2313 | AG21: 3000 | AH21: 2500 | AI21: 3000 | AJ21: 2313 | AK21: 2613 | AL21: 2600 | AM21: 1913 | AN21: 2200 | AO21: 2313 | AP21: 1913 | AQ21: 2000 | AR21: 19956.211 | AS21: 24005.073 | AT21: 19956.211 | AU21: 4700 | AV21: 6500 | AW21: 21972.5 | AX21: 2313 | AY21: 2613 | AZ21: 2613 | BA21: 6113 | BB21: 2313 | BC21: 3100 | BD21: 3000 | BE21: 2000 | BF21: 0 | BG21: 3500 | BH21: 3200 | BI21: 1913 | BJ21: 4035.6 | BK21: 2800 | BL21: 11113 | BM21: 2500 | BN21: 0 | BO21: 4600 | BP21: 3100 | BQ21: 2200 | BR21: 2000 | BS21: 4100 | BT21: 1800 | BU21: 3813 | BV21: 1913 | BW21: 2313 | BX21: 5000 | BY21: 5113 | BZ21: 1350 | CA21: 6500 | CB21: 1500 | CC21: 5113 | CD21: 2400 | CE21: 3700 | CF21: 3700
B22: OCTUBRE | C22: 9920 | D22: 12000 | E22: 3200 | F22: 4713 | G22: 2613 | H22: 8613 | I22: 3113 | J22: 10113 | K22: 7113 | L22: 5113 | M22: 4913 | N22: 4413 | O22: 5153 | P22: 3600 | Q22: 3313 | R22: 4113 | S22: 8113 | T22: 15113 | U22: 12113 | V22: 39076.7 | W22: 3000 | X22: 5000 | Y22: 10000 | Z22: 3613 | AA22: 3500 | AB22: 153110.97 | AC22: 3413 | AD22: 2313 | AE22: 3713 | AF22: 2313 | AG22: 3000 | AH22: 2500 | AI22: 3000 | AJ22: 2313 | AK22: 2613 | AL22: 2600 | AM22: 1913 | AN22: 2200 | AO22: 2313 | AP22: 1913 | AQ22: 2000 | AR22: 19956.211 | AS22: 24005.073 | AT22: 19956.211 | AU22: 4700 | AV22: 6500 | AW22: 21972.5 | AX22: 2313 | AY22: 2613 | AZ22: 2613 | BA22: 6113 | BB22: 2313 | BC22: 3100 | BD22: 3000 | BE22: 2000 | BF22: 0 | BG22: 3500 | BH22: 3200 | BI22: 1913 | BJ22: 4035.6 | BK22: 2800 | BL22: 11113 | BM22: 2500 | BN22: 0 | BO22: 4600 | BP22: 3100 | BQ22: 2200 | BR22: 2000 | BS22: 4100 | BT22: 1800 | BU22: 3813 | BV22: 1913 | BW22: 2313 | BX22: 5000 | BY22: 5113 | BZ22: 1350 | CA22: 6500 | CB22: 1500 | CC22: 5113 | CD22: 2400 | CE22: 3700 | CF22: 3700
B23: NOVIEMBRE | C23: 9920 | D23: 12000 | E23: 3200 | F23: 4713 | G23: 2613 | H23: 8613 | I23: 3113 | J23: 10113 | K23: 7113 | L23: 5113 | M23: 4913 | N23: 4413 | O23: 5153 | P23: 3600 | Q23: 3313 | R23: 4113 | S23: 8113 | T23: 15113 | U23: 12113 | V23: 39076.7 | W23: 3000 | X23: 5000 | Y23: 10000 | Z23: 3613 | AA23: 3500 | AB23: 153110.97 | AC23: 3413 | AD23: 2313 | AE23: 3713 | AF23: 2313 | AG23: 3000 | AH23: 2500 | AI23: 3000 | AJ23: 2313 | AK23: 2613 | AL23: 2600 | AM23: 1913 | AN23: 2200 | AO23: 2313 | AP23: 1913 | AQ23: 2000 | AR23: 19956.211 | AS23: 24005.073 | AT23: 19956.211 | AU23: 4700 | AV23: 6500 | AW23: 21972.5 | AX23: 2313 | AY23: 2613 | AZ23: 2613 | BA23: 6113 | BB23: 2313 | BC23: 3100 | BD23: 3000 | BE23: 2000 | BF23: 0 | BG23: 3500 | BH23: 3200 | BI23: 1913 | BJ23: 4035.6 | BK23: 2800 | BL23: 11113 | BM23: 2500 | BN23: 0 | BO23: 4600 | BP23: 3100 | BQ23: 2200 | BR23: 2000 | BS23: 4100 | BT23: 1800 | BU23: 3813 | BV23: 1913 | BW23: 2313 | BX23: 5000 | BY23: 5113 | BZ23: 1350 | CA23: 6500 | CB23: 1500 | CC23: 5113 | CD23: 2400 | CE23: 3700 | CF23: 3700
B24: DICIEMBRE | C24: 9920 | D24: 12000 | E24: 3200 | F24: 4713 | G24: 2613 | H24: 8613 | I24: 3113 | J24: 10113 | K24: 7113 | L24: 5113 | M24: 4913 | N24: 4413 | O24: 5153 | P24: 3600 | Q24: 3313 | R24: 4113 | S24: 8113 | T24: 15113 | U24: 12113 | V24: 39076.7 | W24: 3000 | X24: 5000 | Y24: 10000 | Z24: 3613 | AA24: 3500 | AB24: 153110.97 | AC24: 3413 | AD24: 2313 | AE24: 3713 | AF24: 2313 | AG24: 3000 | AH24: 2500 | AI24: 3000 | AJ24: 2313 | AK24: 2613 | AL24: 2600 | AM24: 1913 | AN24: 2200 | AO24: 2313 | AP24: 1913 | AQ24: 2000 | AR24: 19956.211 | AS24: 24005.073 | AT24: 19956.211 | AU24: 4700 | AV24: 6500 | AW24: 21972.5 | AX24: 2313 | AY24: 2613 | AZ24: 2613 | BA24: 6113 | BB24: 2313 | BC24: 3100 | BD24: 3000 | BE24: 2000 | BF24: 0 | BG24: 3500 | BH24: 3200 | BI24: 1913 | BJ24: 4035.6 | BK24: 2800 | BL24: 11113 | BM24: 2500 | BN24: 0 | BO24: 4600 | BP24: 3100 | BQ24: 2200 | BR24: 2000 | BS24: 4100 | BT24: 1800 | BU24: 3813 | BV24: 1913 | BW24: 2313 | BX24: 5000 | BY24: 5113 | BZ24: 1350 | CA24: 6500 | CB24: 1500 | CC24: 5113 | CD24: 2400 | CE24: 3700 | CF24: 3700
... B28: BONIFICACION 9% | C28: 669.6 | D28: 810 | E28: 216 | F28: 323.6949 | G28: 176.3775 | H28: 581.3775 | I28: 310.63849 | J28: 682.6275 | K28: 480.1275 | L28: 460.17 | M28: 501.31481 | N28: 297.8775 | O28: 471.20985 | P28: 243 | Q28: 243.19508 | R28: 407.40139 | S28: 547.6275 | T28: 1020.1275 | U28: 817.6275 | V28: 0 | W28: 213.46875 | X28: 464.99985 | Y28: 675 | Z28: 243.8775 | AA28: 236.25 | AB28: 0 | AC28: 230.3775 | AD28: 156.1275 | AE28: 334.17 | AF28: 156.1275 | AG28: 202.5 | AH28: 168.75 | AI28: 202.5 | AJ28: 156.1275 | AK28: 250.848 | AL28: 175.5 | AM28: 172.575 | AN28: 148.5 | AO28: 210.98025 | AP28: 174.195 | AQ28: 193.5 | AR28: 0 | AS28: 0 | AT28: 0 | AU28: 317.25 | AV28: 438.75 | AW28: 1977.525 | AX28: 167.38178 | AY28: 176.3775 | AZ28: 185.19638 | BA28: 412.6275 | BB28: 156.1275 | BC28: 212.2875 | BD28: 205.03125 | BE28: 137.81239 | BF28: 0 | BG28: 236.25 | BH28: 288 | BI28: 172.17 | BJ28: 363.204 | BK28: 189 | BL28: 750.43125 | BM28: 168.75 | BN28: 0 | BO28: 310.5 | BP28: 209.25 | BQ28: 198.405 | BR28: 192.00015 | BS28: 276.75 | BT28: 121.5 | BU28: 343.17 | BV28: 172.17 | BW28: 208.17 | BX28: 452.835 | BY28: 346.3425 | BZ28: 130.815 | CA28: 585 | CB28: 135 | CC28: 460.17 | CD28: 216 | CE28: 250.05375 | CF28: 333
B29: COMISIONES Y BONOS REGULARES
B30: ENERO | C30: 0 | D30: 0 | E30: 0 | F30: 0 | G30: 0 | H30: 0 | I30: 0 | J30: 0 | K30: 0 | L30: 0 | M30: 0 | N30: 0 | O30: 0 | P30: 0 | Q30: 0 | R30: 0 | S30: 0 | T30: 0 | U30: 0 | V30: 0 | W30: 0 | X30: 0 | Y30: 0 | Z30: 0 | AA30: 0 | AB30: 0 | AC30: 0 | AD30: 0 | AE30: 0 | AF30: 0 | AG30: 0 | AH30: 0 | AI30: 0 | AJ30: 0 | AK30: 0 | AL30: 0 | AM30: 0 | AN30: 0 | AO30: 0 | AP30: 45 | AQ30: 0 | AR30: 0 | AS30: 0 | AT30: 0 | AU30: 0 | AV30: 0 | AW30: 0 | AX30: 0 | AY30: 0 | AZ30: 0 | BA30: 0 | BB30: 0 | BC30: 36 | BD30: 0 | BE30: 0 | BF30: 0 | BG30: 0 | BH30: 0 | BI30: 0 | BJ30: 0 | BK30: 0 | BL30: 0 | BM30: 0 | BN30: 0 | BO30: 0 | BP30: 0 | BQ30: 0 | BR30: 0 | BS30: 0 | BT30: 0 | BU30: 0 | BV30: 0 | BW30: 0 | BX30: 9 | BY30: 27 | BZ30: 36 | CA30: 0 | CB30: 0 | CC30: 0 | CD30: 0 | CE30: 9 | CF30: 0
B31: FEBRERO | C31: 0 | D31: 0 | E31: 0 | F31: 0 | G31: 0 | H31: 0 | I31: 0 | J31: 0 | K31: 0 | L31: 0 | M31: 0 | N31: 0 | O31: 0 | P31: 0 | Q31: 0 | R31: 0 | S31: 0 | T31: 0 | U31: 0 | V31: 0 | W31: 0 | X31: 0 | Y31: 0 | Z31: 0 | AA31: 0 | AB31: 0 | AC31: 0 | AD31: 0 | AE31: 0 | AF31: 0 | AG31: 0 | AH31: 0 | AI31: 0 | AJ31: 0 | AK31: 0 | AL31: 0 | AM31: 9 | AN31: 0 | AO31: 0 | AP31: 0 | AQ31: 0 | AR31: 0 | AS31: 0 | AT31: 0 | AU31: 0 | AV31: 0 | AW31: 0 | AX31: 0 | AY31: 0 | AZ31: 0 | BA31: 0 | BB31: 0 | BC31: 54 | BD31: 0 | BE31: 0 | BF31: 0 | BG31: 0 | BH31: 0 | BI31: 0 | BJ31: 0 | BK31: 0 | BL31: 9 | BM31: 0 | BN31: 0 | BO31: 0 | BP31: 0 | BQ31: 9 | BR31: 0 | BS31: 0 | BT31: 0 | BU31: 0 | BV31: 0 | BW31: 0 | BX31: 54 | BY31: 9 | BZ31: 171 | CA31: 0 | CB31: 0 | CC31: 0 | CD31: 0 | CE31: 0 | CF31: 0
B32: MARZO
B33: ABRIL
B34: MAYO
B35: JUNIO
B36: JULIO
B37: AGOSTO
B38: SEPTIEMBRE
B39: OCTUBRE
B40: NOVIEMBRE
B41: DICIEMBRE
B42: HORAS EXTRAS
B43: ENERO | C43: 0 | D43: 0 | E43: 0 | F43: 164.96 | G43: 0 | H43: 0 | I43: 1428.7373 | J43: 0 | K43: 0 | L43: 0 | M43: 1314.329 | N43: 0 | O43: 165.33 | P43: 0 | Q43: 579.78 | R43: 0 | S43: 0 | T43: 0 | U43: 0 | V43: 0 | W43: 325 | X43: 333.33 | Y43: 0 | Z43: 0 | AA43: 0 | AB43: 0 | AC43: 0 | AD43: 0 | AE43: 0 | AF43: 0 | AG43: 0 | AH43: 0 | AI43: 0 | AJ43: 0 | AK43: 348.4 | AL43: 0 | AM43: 0 | AN43: 0 | AO43: 62.45 | AP43: 0 | AQ43: 300 | AR43: 0 | AS43: 0 | AT43: 0 | AU43: 0 | AV43: 0 | AW43: 0 | AX43: 333.46 | AY43: 0 | AZ43: 261.3 | BA43: 0 | BB43: 0 | BC43: 0 | BD43: 75 | BE43: 83.33 | BF43: 0 | BG43: 0 | BH43: 0 | BI43: 0 | BJ43: 0 | BK43: 0 | BL43: 0 | BM43: 0 | BN43: 0 | BO43: 0 | BP43: 0 | BQ43: 0 | BR43: 266.67 | BS43: 0 | BT43: 0 | BU43: 0 | BV43: 0 | BW43: 0 | BX43: 0 | BY43: 0 | BZ43: 0 | CA43: 0 | CB43: 0 | CC43: 0 | CD43: 0 | CE43: 0 | CF43: 0
B44: FEBRERO | C44: 0 | D44: 0 | E44: 0 | F44: 0 | G44: 0 | H44: 0 | I44: 1549.366 | J44: 0 | K44: 0 | L44: 0 | M44: 0 | N44: 0 | O44: 0 | P44: 0 | Q44: 0 | R44: 827.36423 | S44: 0 | T44: 0 | U44: 0 | V44: 0 | W44: 0 | X44: 0 | Y44: 0 | Z44: 0 | AA44: 0 | AB44: 0 | AC44: 0 | AD44: 0 | AE44: 0 | AF44: 0 | AG44: 0 | AH44: 0 | AI44: 0 | AJ44: 0 | AK44: 0 | AL44: 0 | AM44: 0 | AN44: 0 | AO44: 0 | AP44: 0 | AQ44: 0 | AR44: 0 | AS44: 0 | AT44: 0 | AU44: 0 | AV44: 0 | AW44: 0 | AX44: 0 | AY44: 0 | AZ44: 0 | BA44: 0 | BB44: 0 | BC44: 0 | BD44: 0 | BE44: 0 | BF44: 0 | BG44: 0 | BH44: 0 | BI44: 0 | BJ44: 0 | BK44: 0 | BL44: 0 | BM44: 0 | BN44: 0 | BO44: 0 | BP44: 0 | BQ44: 0 | BR44: 0 | BS44: 0 | BT44: 0 | BU44: 0 | BV44: 0 | BW44: 0 | BX44: 0 | BY44: 0 | BZ44: 0 | CA44: 0 | CB44: 0 | CC44: 0 | CD44: 0 | CE44: 0 | CF44: 0
...

Sheet DÍAS EFECTIVOS LABORADOS 2025
A2: DÍAS EFECTIVOS TRABAJADORES 2025
D3: ok | F3: ok | G3: ok | H3: ok | I3: ok | J3: ok | O3: ok
A5: Datos del Trabajador
