Workbook
Name _1___Excel_BuiltIn__FilterDatabase_1_1: #REF!
Name _1___Excel_BuiltIn__FilterDatabase_1_1: #REF!
Name _10__Excel_BuiltIn__FilterDatabase_5_1: #REF!
Name _10__Excel_BuiltIn__FilterDatabase_5_1: #REF!
Name _11_Excel_BuiltIn__FilterDatabase_1_1: #REF!
Name _11_Excel_BuiltIn__FilterDatabase_1_1: #REF!
Name _12_Excel_BuiltIn__FilterDatabase_2_1: #REF!
Name _13_Excel_BuiltIn__FilterDatabase_3_1: #REF!
Name _14_Excel_BuiltIn__FilterDatabase_4_1: #REF!
Name _15_Excel_BuiltIn__FilterDatabase_5_1: #REF!
Name _1Excel_BuiltIn__FilterDatabase_1_1: #REF!
Name _2___Excel_BuiltIn__FilterDatabase_2_1: #REF!
Name _2Excel_BuiltIn__FilterDatabase_2_1: #REF!
Name _3___Excel_BuiltIn__FilterDatabase_3_1: #REF!
Name _3Excel_BuiltIn__FilterDatabase_3_1: #REF!
Name _4___Excel_BuiltIn__FilterDatabase_4_1: #REF!
Name _4Excel_BuiltIn__FilterDatabase_4_1: #REF!
Name _5___Excel_BuiltIn__FilterDatabase_5_1: #REF!
Name _5Excel_BuiltIn__FilterDatabase_5_1: #REF!
Name _6__Excel_BuiltIn__FilterDatabase_1_1: #REF!
Name _7__Excel_BuiltIn__FilterDatabase_2_1: #REF!
Name _8__Excel_BuiltIn__FilterDatabase_3_1: #REF!
Name _9__Excel_BuiltIn__FilterDatabase_4_1: #REF!
Name a: #REF!
Name a: #REF!
Name aa: #REF!
Name AAAAAA: #REF!
Name AAAAAA: #REF!
Name aasqsadh: #REF!
Name aasqsadh: #REF!
Name ABRIL: #REF!
Name AFAM: '[2]GRATI JULIO'!#REF!
Name AFAM: '[3]GRATI JULIO'!#REF!
Name AFP: [4]AFP!$A$5:$E$9
Name AFP: #REF!
Name AGOSTO: #REF!
Name ASIG_FAM: #REF!
Name ASIG_FAM: #REF!
Name BANCO: '[2]GRATI JULIO'!#REF!
Name BANCO: '[3]GRATI JULIO'!#REF!
Name BASE: '[2]GRATI JULIO'!#REF!
Name BASE: '[3]GRATI JULIO'!#REF!
Name BASE_AFECTA: #REF!
Name BASE_RETENCION: #REF!
Name BASICO: #REF!
Name BASICO: #REF!
Name cadddd: #REF!
Name cadddd: #REF!
Name CODIGO: #REF!
Name CTS: #REF!
Name CUENTA: '[2]GRATI JULIO'!#REF!
Name CUENTA: '[3]GRATI JULIO'!#REF!
Name DATA: [4]DATA!$A$10:$U$25
Name DATA: #REF!
Name DDDDDDD: #REF!
Name DEPOSITO: #REF!
Name DNI: #REF!
Name Excel_BuiltIn__FilterDatabase_1: #REF!
Name Excel_BuiltIn__FilterDatabase_1: #REF!
Name Excel_BuiltIn__FilterDatabase_2: #REF!

Sheet dias mes
J2: TOTAL DE DIAS LABORALBLES 2025 | X2: TOTAL DE DIAS NO LABORADOS 2025 | AL2: TOTAL DE DIAS EFECTIVOS 2025 PARA UTILIDADES
H3: F. INICIO | J3: 45658 | K3: 45689 | L3: 45717 | M3: 45748 | N3: 45778 | O3: 45809 | P3: 45839 | Q3: 45870 | R3: 45901 | S3: 45931 | T3: 45962 | U3: 45992
H4: F. FIN | J4: 45688 | K4: 45716 | L4: 45747 | M4: 45777 | N4: 45808 | O4: 45838 | P4: 45869 | Q4: 45900 | R4: 45930 | S4: 45961 | T4: 45991 | U4: 46022
B5: DNI | C5: APELLIDOS Y NOMBRES | J5: ENERO | K5: FEBRERO | L5: MARZO | M5: ABRIL | N5: MAYO | O5: JUNIO | P5: JULIO | Q5: AGOSTO | R5: SETIEMBRE | S5: OCTUBRE | T5: NOVIEMBRE | U5: DICIEMBRE | V5: total | X5: ENERO | Y5: FEBRERO | Z5: MARZO | AA5: ABRIL | AB5: MAYO | AC5: JUNIO | AD5: JULIO | AE5: AGOSTO | AF5: SETIEMBRE | AG5: OCTUBRE | AH5: NOVIEMBRE | AI5: DICIEMBRE | AJ5: total | AL5: ENERO | AM5: FEBRERO | AN5: MARZO | AO5: ABRIL | AP5: MAYO | AQ5: JUNIO | AR5: JULIO | AS5: AGOSTO | AT5: SETIEMBRE | AU5: OCTUBRE | AV5: NOVIEMBRE | AW5: DICIEMBRE | AX5: total
A6: 01 | B6: 09859427 | C6: KUANG | D6: LINARES | E6: MARIA ROSARIO | F6: 45658 | G6: 46022 | J6: =NETWORKDAYS.INTL($J$3,$J$4,1,DIAS!$F$51:$J$54) -> 22 | K6: =NETWORKDAYS.INTL($K$3,$K$4,1,DIAS!$F$51:$J$54) -> 20 | L6: =NETWORKDAYS.INTL($L$3,$L$4,1,DIAS!$F$51:$J$54) -> 21 | M6: =NETWORKDAYS.INTL($M$3,$M$4,1,DIAS!$F$51:$J$54) -> 20 | N6: =NETWORKDAYS.INTL($N$3,$N$4,1, DIAS!$F$51:$J$54) -> 21 | O6: =NETWORKDAYS.INTL($O$3,$O$4,1,DIAS!$F$51:$J$54) -> 21 | P6: =NETWORKDAYS.INTL($P$3,$P$4,1, DIAS!$F$51:$J$54) -> 20 | Q6: =NETWORKDAYS.INTL($Q$3,$Q$4,1,DIAS!$F$51:$J$54) -> 20 | R6: =NETWORKDAYS.INTL($R$3,$R$4,1,DIAS!$F$51:$J$54) -> 22 | S6: =NETWORKDAYS.INTL($S$3,$S$4,1,DIAS!$F$51:$J$54) -> 22 | T6: =NETWORKDAYS.INTL($T$3,$T$4,1,DIAS!$F$51:$J$54) -> 20 | U6: =NETWORKDAYS.INTL($U$3,$U$4,1,DIAS!$F$51:$J$54) -> 20 | V6: =SUM(J6:U6) -> 249 | X6: =SUMIFS(DIAS!$L$11:$L$47,DIAS!$A$11:$A$47,X$5,DIAS!$B$11:$B$47,$B6) -> 20 | Y6: =SUMIFS(DIAS!$L$11:$L$47,DIAS!$A$11:$A$47,Y$5,DIAS!$B$11:$B$47,$B6) -> 0 | Z6: =SUMIFS(DIAS!$L$11:$L$47,DIAS!$A$11:$A$47,Z$5,DIAS!$B$11:$B$47,$B6) -> 0 | AA6: =SUMIFS(DIAS!$L$11:$L$47,DIAS!$A$11:$A$47,AA$5,DIAS!$B$11:$B$47,$B6) -> 0 | AB6: =SUMIFS(DIAS!$L$11:$L$47,DIAS!$A$11:$A$47,AB$5,DIAS!$B$11:$B$47,$B6) -> 0 | AC6: =SUMIFS(DIAS!$L$11:$L$47,DIAS!$A$11:$A$47,AC$5,DIAS!$B$11:$B$47,$B6) -> 0 | AD6: =SUMIFS(DIAS!$L$11:$L$47,DIAS!$A$11:$A$47,AD$5,DIAS!$B$11:$B$47,$B6) -> 0 | AE6: =SUMIFS(DIAS!$L$11:$L$47,DIAS!$A$11:$A$47,AE$5,DIAS!$B$11:$B$47,$B6) -> 0 | ... AI6: =SUMIFS(DIAS!$L$11:$L$47,DIAS!$A$11:$A$47,AI$5,DIAS!$B$11:$B$47,$B6) -> 0 | AJ6: =SUM(X6:AI6) -> 20 | AL6: =+J6-X6 -> 2 | AM6: =+K6-Y6 -> 20 | AN6: =+L6-Z6 -> 21 | AO6: =+M6-AA6 -> 20 | AP6: =+N6-AB6 -> 21 | AQ6: =+O6-AC6 -> 21 | AR6: =+P6-AD6 -> 20 | AS6: =+Q6-AE6 -> 20 | ... AW6: =+U6-AI6 -> 20 | AX6: =+SUM(AL6:AW6) -> 229
A7: 01 | B7: 10798282 | C7: KUANG | D7: CHUSING | E7: NANCY AIDA | F7: 45658 | G7: 46022 | J7: =NETWORKDAYS.INTL($J$3,$J$4,1,DIAS!$F$51:$J$54) -> 22 | K7: =NETWORKDAYS.INTL($K$3,$K$4,1,DIAS!$F$51:$J$54) -> 20 | L7: =NETWORKDAYS.INTL($L$3,$L$4,1,DIAS!$F$51:$J$54) -> 21 | M7: =NETWORKDAYS.INTL($M$3,$M$4,1,DIAS!$F$51:$J$54) -> 20 | N7: =NETWORKDAYS.INTL($N$3,$N$4,1, DIAS!$F$51:$J$54) -> 21 | O7: =NETWORKDAYS.INTL($O$3,$O$4,1,DIAS!$F$51:$J$54) -> 21 | P7: =NETWORKDAYS.INTL($P$3,$P$4,1, DIAS!$F$51:$J$54) -> 20 | Q7: =NETWORKDAYS.INTL($Q$3,$Q$4,1,DIAS!$F$51:$J$54) -> 20 | R7: =NETWORKDAYS.INTL($R$3,$R$4,1,DIAS!$F$51:$J$54) -> 22 | S7: =NETWORKDAYS.INTL($S$3,$S$4,1,DIAS!$F$51:$J$54) -> 22 | T7: =NETWORKDAYS.INTL($T$3,$T$4,1,DIAS!$F$51:$J$54) -> 20 | U7: =NETWORKDAYS.INTL($U$3,$U$4,1,DIAS!$F$51:$J$54) -> 20 | V7: =SUM(J7:U7) -> 249 | X7: =SUMIFS(DIAS!$L$11:$L$47,DIAS!$A$11:$A$47,X$5,DIAS!$B$11:$B$47,$B7) -> 0 | Y7: =SUMIFS(DIAS!$L$11:$L$47,DIAS!$A$11:$A$47,Y$5,DIAS!$B$11:$B$47,$B7) -> 20 | Z7: =SUMIFS(DIAS!$L$11:$L$47,DIAS!$A$11:$A$47,Z$5,DIAS!$B$11:$B$47,$B7) -> 0 | AA7: =SUMIFS(DIAS!$L$11:$L$47,DIAS!$A$11:$A$47,AA$5,DIAS!$B$11:$B$47,$B7) -> 0 | AB7: =SUMIFS(DIAS!$L$11:$L$47,DIAS!$A$11:$A$47,AB$5,DIAS!$B$11:$B$47,$B7) -> 0 | AC7: =SUMIFS(DIAS!$L$11:$L$47,DIAS!$A$11:$A$47,AC$5,DIAS!$B$11:$B$47,$B7) -> 0 | AD7: =SUMIFS(DIAS!$L$11:$L$47,DIAS!$A$11:$A$47,AD$5,DIAS!$B$11:$B$47,$B7) -> 0 | AE7: =SUMIFS(DIAS!$L$11:$L$47,DIAS!$A$11:$A$47,AE$5,DIAS!$B$11:$B$47,$B7) -> 0 | ... AI7: =SUMIFS(DIAS!$L$11:$L$47,DIAS!$A$11:$A$47,AI$5,DIAS!$B$11:$B$47,$B7) -> 0 | AJ7: =SUM(X7:AI7) -> 20 | AL7: =+J7-X7 -> 22 | AM7: =+K7-Y7 -> 0 | AN7: =+L7-Z7 -> 21 | AO7: =+M7-AA7 -> 20 | AP7: =+N7-AB7 -> 21 | AQ7: =+O7-AC7 -> 21 | AR7: =+P7-AD7 -> 20 | AS7: =+Q7-AE7 -> 20 | ... AW7: =+U7-AI7 -> 20 | AX7: =+SUM(AL7:AW7) -> 229
A8: 01 | B8: 40243954 | C8: KUANG | D8: CHUSING | E8: HECTOR ENRIQUE | F8: 45658 | G8: 46022 | J8: =NETWORKDAYS.INTL($J$3,$J$4,1,DIAS!$F$51:$J$54) -> 22 | K8: =NETWORKDAYS.INTL($K$3,$K$4,1,DIAS!$F$51:$J$54) -> 20 | L8: =NETWORKDAYS.INTL($L$3,$L$4,1,DIAS!$F$51:$J$54) -> 21 | M8: =NETWORKDAYS.INTL($M$3,$M$4,1,DIAS!$F$51:$J$54) -> 20 | N8: =NETWORKDAYS.INTL($N$3,$N$4,1, DIAS!$F$51:$J$54) -> 21 | O8: =NETWORKDAYS.INTL($O$3,$O$4,1,DIAS!$F$51:$J$54) -> 21 | P8: =NETWORKDAYS.INTL($P$3,$P$4,1, DIAS!$F$51:$J$54) -> 20 | Q8: =NETWORKDAYS.INTL($Q$3,$Q$4,1,DIAS!$F$51:$J$54) -> 20 | R8: =NETWORKDAYS.INTL($R$3,$R$4,1,DIAS!$F$51:$J$54) -> 22 | S8: =NETWORKDAYS.INTL($S$3,$S$4,1,DIAS!$F$51:$J$54) -> 22 | T8: =NETWORKDAYS.INTL($T$3,$T$4,1,DIAS!$F$51:$J$54) -> 20 | U8: =NETWORKDAYS.INTL($U$3,$U$4,1,DIAS!$F$51:$J$54) -> 20 | V8: =SUM(J8:U8) -> 249 | X8: =SUMIFS(DIAS!$L$11:$L$47,DIAS!$A$11:$A$47,X$5,DIAS!$B$11:$B$47,$B8) -> 20 | Y8: =SUMIFS(DIAS!$L$11:$L$47,DIAS!$A$11:$A$47,Y$5,DIAS!$B$11:$B$47,$B8) -> 0 | Z8: =SUMIFS(DIAS!$L$11:$L$47,DIAS!$A$11:$A$47,Z$5,DIAS!$B$11:$B$47,$B8) -> 0 | AA8: =SUMIFS(DIAS!$L$11:$L$47,DIAS!$A$11:$A$47,AA$5,DIAS!$B$11:$B$47,$B8) -> 0 | AB8: =SUMIFS(DIAS!$L$11:$L$47,DIAS!$A$11:$A$47,AB$5,DIAS!$B$11:$B$47,$B8) -> 0 | AC8: =SUMIFS(DIAS!$L$11:$L$47,DIAS!$A$11:$A$47,AC$5,DIAS!$B$11:$B$47,$B8) -> 0 | AD8: =SUMIFS(DIAS!$L$11:$L$47,DIAS!$A$11:$A$47,AD$5,DIAS!$B$11:$B$47,$B8) -> 0 | AE8: =SUMIFS(DIAS!$L$11:$L$47,DIAS!$A$11:$A$47,AE$5,DIAS!$B$11:$B$47,$B8) -> 0 | ... AI8: =SUMIFS(DIAS!$L$11:$L$47,DIAS!$A$11:$A$47,AI$5,DIAS!$B$11:$B$47,$B8) -> 0 | AJ8: =SUM(X8:AI8) -> 20 | AL8: =+J8-X8 -> 2 | AM8: =+K8-Y8 -> 20 | AN8: =+L8-Z8 -> 21 | AO8: =+M8-AA8 -> 20 | AP8: =+N8-AB8 -> 21 | AQ8: =+O8-AC8 -> 21 | AR8: =+P8-AD8 -> 20 | AS8: =+Q8-AE8 -> 20 | ... AW8: =+U8-AI8 -> 20 | AX8: =+SUM(AL8:AW8) -> 229
A9: 01 | B9: 40640169 | C9: OLIVARES | D9: HERRERA | E9: LILY | F9: 45658 | G9: 46022 | J9: =NETWORKDAYS.INTL($J$3,$J$4,1,DIAS!$F$51:$J$54) -> 22 | K9: =NETWORKDAYS.INTL($K$3,$K$4,1,DIAS!$F$51:$J$54) -> 20 | L9: =NETWORKDAYS.INTL($L$3,$L$4,1,DIAS!$F$51:$J$54) -> 21 | M9: =NETWORKDAYS.INTL($M$3,$M$4,1,DIAS!$F$51:$J$54) -> 20 | N9: =NETWORKDAYS.INTL($N$3,$N$4,1, DIAS!$F$51:$J$54) -> 21 | O9: =NETWORKDAYS.INTL($O$3,$O$4,1,DIAS!$F$51:$J$54) -> 21 | P9: =NETWORKDAYS.INTL($P$3,$P$4,1, DIAS!$F$51:$J$54) -> 20 | Q9: =NETWORKDAYS.INTL($Q$3,$Q$4,1,DIAS!$F$51:$J$54) -> 20 | R9: =NETWORKDAYS.INTL($R$3,$R$4,1,DIAS!$F$51:$J$54) -> 22 | S9: =NETWORKDAYS.INTL($S$3,$S$4,1,DIAS!$F$51:$J$54) -> 22 | T9: =NETWORKDAYS.INTL($T$3,$T$4,1,DIAS!$F$51:$J$54) -> 20 | U9: =NETWORKDAYS.INTL($U$3,$U$4,1,DIAS!$F$51:$J$54) -> 20 | V9: =SUM(J9:U9) -> 249 | X9: =SUMIFS(DIAS!$L$11:$L$47,DIAS!$A$11:$A$47,X$5,DIAS!$B$11:$B$47,$B9) -> 0 | Y9: =SUMIFS(DIAS!$L$11:$L$47,DIAS!$A$11:$A$47,Y$5,DIAS!$B$11:$B$47,$B9) -> 0 | Z9: =SUMIFS(DIAS!$L$11:$L$47,DIAS!$A$11:$A$47,Z$5,DIAS!$B$11:$B$47,$B9) -> 0 | AA9: =SUMIFS(DIAS!$L$11:$L$47,DIAS!$A$11:$A$47,AA$5,DIAS!$B$11:$B$47,$B9) -> 18 | AB9: =SUMIFS(DIAS!$L$11:$L$47,DIAS!$A$11:$A$47,AB$5,DIAS!$B$11:$B$47,$B9) -> 0 | AC9: =SUMIFS(DIAS!$L$11:$L$47,DIAS!$A$11:$A$47,AC$5,DIAS!$B$11:$B$47,$B9) -> 0 | AD9: =SUMIFS(DIAS!$L$11:$L$47,DIAS!$A$11:$A$47,AD$5,DIAS!$B$11:$B$47,$B9) -> 0 | AE9: =SUMIFS(DIAS!$L$11:$L$47,DIAS!$A$11:$A$47,AE$5,DIAS!$B$11:$B$47,$B9) -> 0 | ... AI9: =SUMIFS(DIAS!$L$11:$L$47,DIAS!$A$11:$A$47,AI$5,DIAS!$B$11:$B$47,$B9) -> 0 | AJ9: =SUM(X9:AI9) -> 18 | AL9: =+J9-X9 -> 22 | AM9: =+K9-Y9 -> 20 | AN9: =+L9-Z9 -> 21 | AO9: =+M9-AA9 -> 2 | AP9: =+N9-AB9 -> 21 | AQ9: =+O9-AC9 -> 21 | AR9: =+P9-AD9 -> 20 | AS9: =+Q9-AE9 -> 20 | ... AW9: =+U9-AI9 -> 20 | AX9: =+SUM(AL9:AW9) -> 231
A10: 01 | B10: 41194847 | C10: DURAND | D10: GARCIA | E10: ERICKA RAQUEL | F10: 45658 | G10: 46022 | J10: =NETWORKDAYS.INTL($J$3,$J$4,1,DIAS!$F$51:$J$54) -> 22 | K10: =NETWORKDAYS.INTL($K$3,$K$4,1,DIAS!$F$51:$J$54) -> 20 | L10: =NETWORKDAYS.INTL($L$3,$L$4,1,DIAS!$F$51:$J$54) -> 21 | M10: =NETWORKDAYS.INTL($M$3,$M$4,1,DIAS!$F$51:$J$54) -> 20 | N10: =NETWORKDAYS.INTL($N$3,$N$4,1, DIAS!$F$51:$J$54) -> 21 | O10: =NETWORKDAYS.INTL($O$3,$O$4,1,DIAS!$F$51:$J$54) -> 21 | P10: =NETWORKDAYS.INTL($P$3,$P$4,1, DIAS!$F$51:$J$54) -> 20 | Q10: =NETWORKDAYS.INTL($Q$3,$Q$4,1,DIAS!$F$51:$J$54) -> 20 | R10: =NETWORKDAYS.INTL($R$3,$R$4,1,DIAS!$F$51:$J$54) -> 22 | S10: =NETWORKDAYS.INTL($S$3,$S$4,1,DIAS!$F$51:$J$54) -> 22 | T10: =NETWORKDAYS.INTL($T$3,$T$4,1,DIAS!$F$51:$J$54) -> 20 | U10: =NETWORKDAYS.INTL($U$3,$U$4,1,DIAS!$F$51:$J$54) -> 20 | V10: =SUM(J10:U10) -> 249 | X10: =SUMIFS(DIAS!$L$11:$L$47,DIAS!$A$11:$A$47,X$5,DIAS!$B$11:$B$47,$B10) -> 0 | Y10: =SUMIFS(DIAS!$L$11:$L$47,DIAS!$A$11:$A$47,Y$5,DIAS!$B$11:$B$47,$B10) -> 0 | Z10: =SUMIFS(DIAS!$L$11:$L$47,DIAS!$A$11:$A$47,Z$5,DIAS!$B$11:$B$47,$B10) -> 20 | AA10: =SUMIFS(DIAS!$L$11:$L$47,DIAS!$A$11:$A$47,AA$5,DIAS!$B$11:$B$47,$B10) -> 0 | AB10: =SUMIFS(DIAS!$L$11:$L$47,DIAS!$A$11:$A$47,AB$5,DIAS!$B$11:$B$47,$B10) -> 0 | AC10: =SUMIFS(DIAS!$L$11:$L$47,DIAS!$A$11:$A$47,AC$5,DIAS!$B$11:$B$47,$B10) -> 0 | AD10: =SUMIFS(DIAS!$L$11:$L$47,DIAS!$A$11:$A$47,AD$5,DIAS!$B$11:$B$47,$B10) -> 0 | AE10: =SUMIFS(DIAS!$L$11:$L$47,DIAS!$A$11:$A$47,AE$5,DIAS!$B$11:$B$47,$B10) -> 0 | ... AI10: =SUMIFS(DIAS!$L$11:$L$47,DIAS!$A$11:$A$47,AI$5,DIAS!$B$11:$B$47,$B10) -> 0 | AJ10: =SUM(X10:AI10) -> 20 | AL10: =+J10-X10 -> 22 | AM10: =+K10-Y10 -> 20 | AN10: =+L10-Z10 -> 1 | AO10: =+M10-AA10 -> 20 | AP10: =+N10-AB10 -> 21 | AQ10: =+O10-AC10 -> 21 | AR10: =+P10-AD10 -> 20 | AS10: =+Q10-AE10 -> 20 | ... AW10: =+U10-AI10 -> 20 | AX10: =+SUM(AL10:AW10) -> 229
A11: 01 | B11: 41202202 | C11: GARCIA | D11: ZAVALETA | E11: GIOVANNA HERMELINDA | F11: 45658 | G11: 46022 | J11: =NETWORKDAYS.INTL($J$3,$J$4,1,DIAS!$F$51:$J$54) -> 22 | K11: =NETWORKDAYS.INTL($K$3,$K$4,1,DIAS!$F$51:$J$54) -> 20 | L11: =NETWORKDAYS.INTL($L$3,$L$4,1,DIAS!$F$51:$J$54) -> 21 | M11: =NETWORKDAYS.INTL($M$3,$M$4,1,DIAS!$F$51:$J$54) -> 20 | N11: =NETWORKDAYS.INTL($N$3,$N$4,1, DIAS!$F$51:$J$54) -> 21 | O11: =NETWORKDAYS.INTL($O$3,$O$4,1,DIAS!$F$51:$J$54) -> 21 | P11: =NETWORKDAYS.INTL($P$3,$P$4,1, DIAS!$F$51:$J$54) -> 20 | Q11: =NETWORKDAYS.INTL($Q$3,$Q$4,1,DIAS!$F$51:$J$54) -> 20 | R11: =NETWORKDAYS.INTL($R$3,$R$4,1,DIAS!$F$51:$J$54) -> 22 | S11: =NETWORKDAYS.INTL($S$3,$S$4,1,DIAS!$F$51:$J$54) -> 22 | T11: =NETWORKDAYS.INTL($T$3,$T$4,1,DIAS!$F$51:$J$54) -> 20 | U11: =NETWORKDAYS.INTL($U$3,$U$4,1,DIAS!$F$51:$J$54) -> 20 | V11: =SUM(J11:U11) -> 249 | X11: =SUMIFS(DIAS!$L$11:$L$47,DIAS!$A$11:$A$47,X$5,DIAS!$B$11:$B$47,$B11) -> 0 | Y11: =SUMIFS(DIAS!$L$11:$L$47,DIAS!$A$11:$A$47,Y$5,DIAS!$B$11:$B$47,$B11) -> 0 | Z11: =SUMIFS(DIAS!$L$11:$L$47,DIAS!$A$11:$A$47,Z$5,DIAS!$B$11:$B$47,$B11) -> 0 | AA11: =SUMIFS(DIAS!$L$11:$L$47,DIAS!$A$11:$A$47,AA$5,DIAS!$B$11:$B$47,$B11) -> 2 | AB11: =SUMIFS(DIAS!$L$11:$L$47,DIAS!$A$11:$A$47,AB$5,DIAS!$B$11:$B$47,$B11) -> 0 | AC11: =SUMIFS(DIAS!$L$11:$L$47,DIAS!$A$11:$A$47,AC$5,DIAS!$B$11:$B$47,$B11) -> 0 | AD11: =SUMIFS(DIAS!$L$11:$L$47,DIAS!$A$11:$A$47,AD$5,DIAS!$B$11:$B$47,$B11) -> 1 | AE11: =SUMIFS(DIAS!$L$11:$L$47,DIAS!$A$11:$A$47,AE$5,DIAS!$B$11:$B$47,$B11) -> 2 | ... AI11: =SUMIFS(DIAS!$L$11:$L$47,DIAS!$A$11:$A$47,AI$5,DIAS!$B$11:$B$47,$B11) -> 0 | AJ11: =SUM(X11:AI11) -> 15 | AL11: =+J11-X11 -> 22 | AM11: =+K11-Y11 -> 20 | AN11: =+L11-Z11 -> 21 | AO11: =+M11-AA11 -> 18 | AP11: =+N11-AB11 -> 21 | AQ11: =+O11-AC11 -> 21 | AR11: =+P11-AD11 -> 19 | AS11: =+Q11-AE11 -> 18 | ... AW11: =+U11-AI11 -> 20 | AX11: =+SUM(AL11:AW11) -> 234
A12: 01 | B12: 41320534 | C12: LEZAMA | D12: ULLOA | E12: CESAR ENRIQUE | F12: 45658 | G12: 46022 | J12: =NETWORKDAYS.INTL($J$3,$J$4,1,DIAS!$F$51:$J$54) -> 22 | K12: =NETWORKDAYS.INTL($K$3,$K$4,1,DIAS!$F$51:$J$54) -> 20 | L12: =NETWORKDAYS.INTL($L$3,$L$4,1,DIAS!$F$51:$J$54) -> 21 | M12: =NETWORKDAYS.INTL($M$3,$M$4,1,DIAS!$F$51:$J$54) -> 20 | N12: =NETWORKDAYS.INTL($N$3,$N$4,1, DIAS!$F$51:$J$54) -> 21 | O12: =NETWORKDAYS.INTL($O$3,$O$4,1,DIAS!$F$51:$J$54) -> 21 | P12: =NETWORKDAYS.INTL($P$3,$P$4,1, DIAS!$F$51:$J$54) -> 20 | Q12: =NETWORKDAYS.INTL($Q$3,$Q$4,1,DIAS!$F$51:$J$54) -> 20 | R12: =NETWORKDAYS.INTL($R$3,$R$4,1,DIAS!$F$51:$J$54) -> 22 | S12: =NETWORKDAYS.INTL($S$3,$S$4,1,DIAS!$F$51:$J$54) -> 22 | T12: =NETWORKDAYS.INTL($T$3,$T$4,1,DIAS!$F$51:$J$54) -> 20 | U12: =NETWORKDAYS.INTL($U$3,$U$4,1,DIAS!$F$51:$J$54) -> 20 | V12: =SUM(J12:U12) -> 249 | X12: =SUMIFS(DIAS!$L$11:$L$47,DIAS!$A$11:$A$47,X$5,DIAS!$B$11:$B$47,$B12) -> 0 | Y12: =SUMIFS(DIAS!$L$11:$L$47,DIAS!$A$11:$A$47,Y$5,DIAS!$B$11:$B$47,$B12) -> 1 | Z12: =SUMIFS(DIAS!$L$11:$L$47,DIAS!$A$11:$A$47,Z$5,DIAS!$B$11:$B$47,$B12) -> 0 | AA12: =SUMIFS(DIAS!$L$11:$L$47,DIAS!$A$11:$A$47,AA$5,DIAS!$B$11:$B$47,$B12) -> 0 | AB12: =SUMIFS(DIAS!$L$11:$L$47,DIAS!$A$11:$A$47,AB$5,DIAS!$B$11:$B$47,$B12) -> 0 | AC12: =SUMIFS(DIAS!$L$11:$L$47,DIAS!$A$11:$A$47,AC$5,DIAS!$B$11:$B$47,$B12) -> 0 | AD12: =SUMIFS(DIAS!$L$11:$L$47,DIAS!$A$11:$A$47,AD$5,DIAS!$B$11:$B$47,$B12) -> 18 | AE12: =SUMIFS(DIAS!$L$11:$L$47,DIAS!$A$11:$A$47,AE$5,DIAS!$B$11:$B$47,$B12) -> 0 | ... AI12: =SUMIFS(DIAS!$L$11:$L$47,DIAS!$A$11:$A$47,AI$5,DIAS!$B$11:$B$47,$B12) -> 5 | AJ12: =SUM(X12:AI12) -> 24 | AL12: =+J12-X12 -> 22 | AM12: =+K12-Y12 -> 19 | AN12: =+L12-Z12 -> 21 | AO12: =+M12-AA12 -> 20 | AP12: =+N12-AB12 -> 21 | AQ12: =+O12-AC12 -> 21 | AR12: =+P12-AD12 -> 2 | AS12: =+Q12-AE12 -> 20 | ... AW12: =+U12-AI12 -> 15 | AX12: =+SUM(AL12:AW12) -> 225
A13: 01 | B13: 42263949 | C13: HERRERA | D13: ANDAMAYO | E13: NAHALA DOROTHY | F13: 45658 | G13: 46022 | J13: =NETWORKDAYS.INTL($J$3,$J$4,1,DIAS!$F$51:$J$54) -> 22 | K13: =NETWORKDAYS.INTL($K$3,$K$4,1,DIAS!$F$51:$J$54) -> 20 | L13: =NETWORKDAYS.INTL($L$3,$L$4,1,DIAS!$F$51:$J$54) -> 21 | M13: =NETWORKDAYS.INTL($M$3,$M$4,1,DIAS!$F$51:$J$54) -> 20 | N13: =NETWORKDAYS.INTL($N$3,$N$4,1, DIAS!$F$51:$J$54) -> 21 | O13: =NETWORKDAYS.INTL($O$3,$O$4,1,DIAS!$F$51:$J$54) -> 21 | P13: =NETWORKDAYS.INTL($P$3,$P$4,1, DIAS!$F$51:$J$54) -> 20 | Q13: =NETWORKDAYS.INTL($Q$3,$Q$4,1,DIAS!$F$51:$J$54) -> 20 | R13: =NETWORKDAYS.INTL($R$3,$R$4,1,DIAS!$F$51:$J$54) -> 22 | S13: =NETWORKDAYS.INTL($S$3,$S$4,1,DIAS!$F$51:$J$54) -> 22 | T13: =NETWORKDAYS.INTL($T$3,$T$4,1,DIAS!$F$51:$J$54) -> 20 | U13: =NETWORKDAYS.INTL($U$3,$U$4,1,DIAS!$F$51:$J$54) -> 20 | V13: =SUM(J13:U13) -> 249 | X13: =SUMIFS(DIAS!$L$11:$L$47,DIAS!$A$11:$A$47,X$5,DIAS!$B$11:$B$47,$B13) -> 2 | Y13: =SUMIFS(DIAS!$L$11:$L$47,DIAS!$A$11:$A$47,Y$5,DIAS!$B$11:$B$47,$B13) -> 0 | Z13: =SUMIFS(DIAS!$L$11:$L$47,DIAS!$A$11:$A$47,Z$5,DIAS!$B$11:$B$47,$B13) -> 0 | AA13: =SUMIFS(DIAS!$L$11:$L$47,DIAS!$A$11:$A$47,AA$5,DIAS!$B$11:$B$47,$B13) -> 0 | AB13: =SUMIFS(DIAS!$L$11:$L$47,DIAS!$A$11:$A$47,AB$5,DIAS!$B$11:$B$47,$B13) -> 1 | AC13: =SUMIFS(DIAS!$L$11:$L$47,DIAS!$A$11:$A$47,AC$5,DIAS!$B$11:$B$47,$B13) -> 20 | AD13: =SUMIFS(DIAS!$L$11:$L$47,DIAS!$A$11:$A$47,AD$5,DIAS!$B$11:$B$47,$B13) -> 2 | AE13: =SUMIFS(DIAS!$L$11:$L$47,DIAS!$A$11:$A$47,AE$5,DIAS!$B$11:$B$47,$B13) -> 0 | ... AI13: =SUMIFS(DIAS!$L$11:$L$47,DIAS!$A$11:$A$47,AI$5,DIAS!$B$11:$B$47,$B13) -> 1 | AJ13: =SUM(X13:AI13) -> 26 | AL13: =+J13-X13 -> 20 | AM13: =+K13-Y13 -> 20 | AN13: =+L13-Z13 -> 21 | AO13: =+M13-AA13 -> 20 | AP13: =+N13-AB13 -> 20 | AQ13: =+O13-AC13 -> 1 | AR13: =+P13-AD13 -> 18 | AS13: =+Q13-AE13 -> 20 | ... AW13: =+U13-AI13 -> 19 | AX13: =+SUM(AL13:AW13) -> 223
A14: 01 | B14: 43658082 | C14: TENORIO | D14: FERNANDEZ | E14: JOSE VICTOR | F14: 45658 | G14: 46022 | J14: =NETWORKDAYS.INTL($J$3,$J$4,1,DIAS!$F$51:$J$54) -> 22 | K14: =NETWORKDAYS.INTL($K$3,$K$4,1,DIAS!$F$51:$J$54) -> 20 | L14: =NETWORKDAYS.INTL($L$3,$L$4,1,DIAS!$F$51:$J$54) -> 21 | M14: =NETWORKDAYS.INTL($M$3,$M$4,1,DIAS!$F$51:$J$54) -> 20 | N14: =NETWORKDAYS.INTL($N$3,$N$4,1, DIAS!$F$51:$J$54) -> 21 | O14: =NETWORKDAYS.INTL($O$3,$O$4,1,DIAS!$F$51:$J$54) -> 21 | P14: =NETWORKDAYS.INTL($P$3,$P$4,1, DIAS!$F$51:$J$54) -> 20 | Q14: =NETWORKDAYS.INTL($Q$3,$Q$4,1,DIAS!$F$51:$J$54) -> 20 | R14: =NETWORKDAYS.INTL($R$3,$R$4,1,DIAS!$F$51:$J$54) -> 22 | S14: =NETWORKDAYS.INTL($S$3,$S$4,1,DIAS!$F$51:$J$54) -> 22 | T14: =NETWORKDAYS.INTL($T$3,$T$4,1,DIAS!$F$51:$J$54) -> 20 | U14: =NETWORKDAYS.INTL($U$3,$U$4,1,DIAS!$F$51:$J$54) -> 20 | V14: =SUM(J14:U14) -> 249 | X14: =SUMIFS(DIAS!$L$11:$L$47,DIAS!$A$11:$A$47,X$5,DIAS!$B$11:$B$47,$B14) -> 0 | Y14: =SUMIFS(DIAS!$L$11:$L$47,DIAS!$A$11:$A$47,Y$5,DIAS!$B$11:$B$47,$B14) -> 5 | Z14: =SUMIFS(DIAS!$L$11:$L$47,DIAS!$A$11:$A$47,Z$5,DIAS!$B$11:$B$47,$B14) -> 0 | AA14: =SUMIFS(DIAS!$L$11:$L$47,DIAS!$A$11:$A$47,AA$5,DIAS!$B$11:$B$47,$B14) -> 0 | AB14: =SUMIFS(DIAS!$L$11:$L$47,DIAS!$A$11:$A$47,AB$5,DIAS!$B$11:$B$47,$B14) -> 10 | AC14: =SUMIFS(DIAS!$L$11:$L$47,DIAS!$A$11:$A$47,AC$5,DIAS!$B$11:$B$47,$B14) -> 5 | AD14: =SUMIFS(DIAS!$L$11:$L$47,DIAS!$A$11:$A$47,AD$5,DIAS!$B$11:$B$47,$B14) -> 14 | AE14: =SUMIFS(DIAS!$L$11:$L$47,DIAS!$A$11:$A$47,AE$5,DIAS!$B$11:$B$47,$B14) -> 0 | ... AI14: =SUMIFS(DIAS!$L$11:$L$47,DIAS!$A$11:$A$47,AI$5,DIAS!$B$11:$B$47,$B14) -> 0 | AJ14: =SUM(X14:AI14) -> 34 | AL14: =+J14-X14 -> 22 | AM14: =+K14-Y14 -> 15 | AN14: =+L14-Z14 -> 21 | AO14: =+M14-AA14 -> 20 | AP14: =+N14-AB14 -> 11 | AQ14: =+O14-AC14 -> 16 | AR14: =+P14-AD14 -> 6 | AS14: =+Q14-AE14 -> 20 | ... AW14: =+U14-AI14 -> 20 | AX14: =+SUM(AL14:AW14) -> 215
A15: 01 | B15: 44262618 | C15: NIQUEN | D15: PUMA | E15: MARIELLA ISABEL | F15: 45658 | G15: 46022 | J15: =NETWORKDAYS.INTL($J$3,$J$4,1,DIAS!$F$51:$J$54) -> 22 | K15: =NETWORKDAYS.INTL($K$3,$K$4,1,DIAS!$F$51:$J$54) -> 20 | L15: =NETWORKDAYS.INTL($L$3,$L$4,1,DIAS!$F$51:$J$54) -> 21 | M15: =NETWORKDAYS.INTL($M$3,$M$4,1,DIAS!$F$51:$J$54) -> 20 | N15: =NETWORKDAYS.INTL($N$3,$N$4,1, DIAS!$F$51:$J$54) -> 21 | O15: =NETWORKDAYS.INTL($O$3,$O$4,1,DIAS!$F$51:$J$54) -> 21 | P15: =NETWORKDAYS.INTL($P$3,$P$4,1, DIAS!$F$51:$J$54) -> 20 | Q15: =NETWORKDAYS.INTL($Q$3,$Q$4,1,DIAS!$F$51:$J$54) -> 20 | R15: =NETWORKDAYS.INTL($R$3,$R$4,1,DIAS!$F$51:$J$54) -> 22 | S15: =NETWORKDAYS.INTL($S$3,$S$4,1,DIAS!$F$51:$J$54) -> 22 | T15: =NETWORKDAYS.INTL($T$3,$T$4,1,DIAS!$F$51:$J$54) -> 20 | U15: =NETWORKDAYS.INTL($U$3,$U$4,1,DIAS!$F$51:$J$54) -> 20 | V15: =SUM(J15:U15) -> 249 | X15: =SUMIFS(DIAS!$L$11:$L$47,DIAS!$A$11:$A$47,X$5,DIAS!$B$11:$B$47,$B15) -> 0 | Y15: =SUMIFS(DIAS!$L$11:$L$47,DIAS!$A$11:$A$47,Y$5,DIAS!$B$11:$B$47,$B15) -> 20 | Z15: =SUMIFS(DIAS!$L$11:$L$47,DIAS!$A$11:$A$47,Z$5,DIAS!$B$11:$B$47,$B15) -> 0 | AA15: =SUMIFS(DIAS!$L$11:$L$47,DIAS!$A$11:$A$47,AA$5,DIAS!$B$11:$B$47,$B15) -> 2 | AB15: =SUMIFS(DIAS!$L$11:$L$47,DIAS!$A$11:$A$47,AB$5,DIAS!$B$11:$B$47,$B15) -> 0 | AC15: =SUMIFS(DIAS!$L$11:$L$47,DIAS!$A$11:$A$47,AC$5,DIAS!$B$11:$B$47,$B15) -> 0 | AD15: =SUMIFS(DIAS!$L$11:$L$47,DIAS!$A$11:$A$47,AD$5,DIAS!$B$11:$B$47,$B15) -> 0 | AE15: =SUMIFS(DIAS!$L$11:$L$47,DIAS!$A$11:$A$47,AE$5,DIAS!$B$11:$B$47,$B15) -> 0 | ... AI15: =SUMIFS(DIAS!$L$11:$L$47,DIAS!$A$11:$A$47,AI$5,DIAS!$B$11:$B$47,$B15) -> 0 | AJ15: =SUM(X15:AI15) -> 22 | AL15: =+J15-X15 -> 22 | AM15: =+K15-Y15 -> 0 | AN15: =+L15-Z15 -> 21 | AO15: =+M15-AA15 -> 18 | AP15: =+N15-AB15 -> 21 | AQ15: =+O15-AC15 -> 21 | AR15: =+P15-AD15 -> 20 | AS15: =+Q15-AE15 -> 20 | ... AW15: =+U15-AI15 -> 20 | AX15: =+SUM(AL15:AW15) -> 227
A16: 01 | B16: 46098021 | C16: HERRERA | D16: GERONIMO | E16: MARYELIZA SANTA | F16: 45658 | G16: 46022 | J16: =NETWORKDAYS.INTL($J$3,$J$4,1,DIAS!$F$51:$J$54) -> 22 | K16: =NETWORKDAYS.INTL($K$3,$K$4,1,DIAS!$F$51:$J$54) -> 20 | L16: =NETWORKDAYS.INTL($L$3,$L$4,1,DIAS!$F$51:$J$54) -> 21 | M16: =NETWORKDAYS.INTL($M$3,$M$4,1,DIAS!$F$51:$J$54) -> 20 | N16: =NETWORKDAYS.INTL($N$3,$N$4,1, DIAS!$F$51:$J$54) -> 21 | O16: =NETWORKDAYS.INTL($O$3,$O$4,1,DIAS!$F$51:$J$54) -> 21 | P16: =NETWORKDAYS.INTL($P$3,$P$4,1, DIAS!$F$51:$J$54) -> 20 | Q16: =NETWORKDAYS.INTL($Q$3,$Q$4,1,DIAS!$F$51:$J$54) -> 20 | R16: =NETWORKDAYS.INTL($R$3,$R$4,1,DIAS!$F$51:$J$54) -> 22 | S16: =NETWORKDAYS.INTL($S$3,$S$4,1,DIAS!$F$51:$J$54) -> 22 | T16: =NETWORKDAYS.INTL($T$3,$T$4,1,DIAS!$F$51:$J$54) -> 20 | U16: =NETWORKDAYS.INTL($U$3,$U$4,1,DIAS!$F$51:$J$54) -> 20 | V16: =SUM(J16:U16) -> 249 | X16: =SUMIFS(DIAS!$L$11:$L$47,DIAS!$A$11:$A$47,X$5,DIAS!$B$11:$B$47,$B16) -> 0 | Y16: =SUMIFS(DIAS!$L$11:$L$47,DIAS!$A$11:$A$47,Y$5,DIAS!$B$11:$B$47,$B16) -> 0 | Z16: =SUMIFS(DIAS!$L$11:$L$47,DIAS!$A$11:$A$47,Z$5,DIAS!$B$11:$B$47,$B16) -> 0 | AA16: =SUMIFS(DIAS!$L$11:$L$47,DIAS!$A$11:$A$47,AA$5,DIAS!$B$11:$B$47,$B16) -> 0 | AB16: =SUMIFS(DIAS!$L$11:$L$47,DIAS!$A$11:$A$47,AB$5,DIAS!$B$11:$B$47,$B16) -> 0 | AC16: =SUMIFS(DIAS!$L$11:$L$47,DIAS!$A$11:$A$47,AC$5,DIAS!$B$11:$B$47,$B16) -> 0 | AD16: =SUMIFS(DIAS!$L$11:$L$47,DIAS!$A$11:$A$47,AD$5,DIAS!$B$11:$B$47,$B16) -> 0 | AE16: =SUMIFS(DIAS!$L$11:$L$47,DIAS!$A$11:$A$47,AE$5,DIAS!$B$11:$B$47,$B16) -> 0 | ... AI16: =SUMIFS(DIAS!$L$11:$L$47,DIAS!$A$11:$A$47,AI$5,DIAS!$B$11:$B$47,$B16) -> 0 | AJ16: =SUM(X16:AI16) -> 18 | AL16: =+J16-X16 -> 22 | AM16: =+K16-Y16 -> 20 | AN16: =+L16-Z16 -> 21 | AO16: =+M16-AA16 -> 20 | AP16: =+N16-AB16 -> 21 | AQ16: =+O16-AC16 -> 21 | AR16: =+P16-AD16 -> 20 | AS16: =+Q16-AE16 -> 20 | ... AW16: =+U16-AI16 -> 20 | AX16: =+SUM(AL16:AW16) -> 231
A17: 01 | B17: 46345862 | C17: CATAÑO | D17: OYANGUREN | E17: GIANCARLO | F17: 45658 | G17: 46022 | J17: =NETWORKDAYS.INTL($J$3,$J$4,1,DIAS!$F$51:$J$54) -> 22 | K17: =NETWORKDAYS.INTL($K$3,$K$4,1,DIAS!$F$51:$J$54) -> 20 | L17: =NETWORKDAYS.INTL($L$3,$L$4,1,DIAS!$F$51:$J$54) -> 21 | M17: =NETWORKDAYS.INTL($M$3,$M$4,1,DIAS!$F$51:$J$54) -> 20 | N17: =NETWORKDAYS.INTL($N$3,$N$4,1, DIAS!$F$51:$J$54) -> 21 | O17: =NETWORKDAYS.INTL($O$3,$O$4,1,DIAS!$F$51:$J$54) -> 21 | P17: =NETWORKDAYS.INTL($P$3,$P$4,1, DIAS!$F$51:$J$54) -> 20 | Q17: =NETWORKDAYS.INTL($Q$3,$Q$4,1,DIAS!$F$51:$J$54) -> 20 | R17: =NETWORKDAYS.INTL($R$3,$R$4,1,DIAS!$F$51:$J$54) -> 22 | S17: =NETWORKDAYS.INTL($S$3,$S$4,1,DIAS!$F$51:$J$54) -> 22 | T17: =NETWORKDAYS.INTL($T$3,$T$4,1,DIAS!$F$51:$J$54) -> 20 | U17: =NETWORKDAYS.INTL($U$3,$U$4,1,DIAS!$F$51:$J$54) -> 20 | V17: =SUM(J17:U17) -> 249 | X17: =SUMIFS(DIAS!$L$11:$L$47,DIAS!$A$11:$A$47,X$5,DIAS!$B$11:$B$47,$B17) -> 0 | Y17: =SUMIFS(DIAS!$L$11:$L$47,DIAS!$A$11:$A$47,Y$5,DIAS!$B$11:$B$47,$B17) -> 0 | Z17: =SUMIFS(DIAS!$L$11:$L$47,DIAS!$A$11:$A$47,Z$5,DIAS!$B$11:$B$47,$B17) -> 5 | AA17: =SUMIFS(DIAS!$L$11:$L$47,DIAS!$A$11:$A$47,AA$5,DIAS!$B$11:$B$47,$B17) -> 0 | AB17: =SUMIFS(DIAS!$L$11:$L$47,DIAS!$A$11:$A$47,AB$5,DIAS!$B$11:$B$47,$B17) -> 0 | AC17: =SUMIFS(DIAS!$L$11:$L$47,DIAS!$A$11:$A$47,AC$5,DIAS!$B$11:$B$47,$B17) -> 0 | AD17: =SUMIFS(DIAS!$L$11:$L$47,DIAS!$A$11:$A$47,AD$5,DIAS!$B$11:$B$47,$B17) -> 0 | AE17: =SUMIFS(DIAS!$L$11:$L$47,DIAS!$A$11:$A$47,AE$5,DIAS!$B$11:$B$47,$B17) -> 0 | ... AI17: =SUMIFS(DIAS!$L$11:$L$47,DIAS!$A$11:$A$47,AI$5,DIAS!$B$11:$B$47,$B17) -> 0 | AJ17: =SUM(X17:AI17) -> 12 | AL17: =+J17-X17 -> 22 | AM17: =+K17-Y17 -> 20 | AN17: =+L17-Z17 -> 16 | AO17: =+M17-AA17 -> 20 | AP17: =+N17-AB17 -> 21 | AQ17: =+O17-AC17 -> 21 | AR17: =+P17-AD17 -> 20 | AS17: =+Q17-AE17 -> 20 | ... AW17: =+U17-AI17 -> 20 | AX17: =+SUM(AL17:AW17) -> 237
... A19: 01 | B19: 72196931 | C19: CONDORI | D19: LOPEZ | E19: ANDREA DEL PILAR | F19: 45658 | G19: 46022 | J19: =NETWORKDAYS.INTL($J$3,$J$4,1,DIAS!$F$51:$J$54) -> 22 | K19: =NETWORKDAYS.INTL($K$3,$K$4,1,DIAS!$F$51:$J$54) -> 20 | L19: =NETWORKDAYS.INTL($L$3,$L$4,1,DIAS!$F$51:$J$54) -> 21 | M19: =NETWORKDAYS.INTL($M$3,$M$4,1,DIAS!$F$51:$J$54) -> 20 | N19: =NETWORKDAYS.INTL($N$3,$N$4,1, DIAS!$F$51:$J$54) -> 21 | O19: =NETWORKDAYS.INTL($O$3,$O$4,1,DIAS!$F$51:$J$54) -> 21 | P19: =NETWORKDAYS.INTL($P$3,$P$4,1, DIAS!$F$51:$J$54) -> 20 | Q19: =NETWORKDAYS.INTL($Q$3,$Q$4,1,DIAS!$F$51:$J$54) -> 20 | R19: =NETWORKDAYS.INTL($R$3,$R$4,1,DIAS!$F$51:$J$54) -> 22 | S19: =NETWORKDAYS.INTL($S$3,$S$4,1,DIAS!$F$51:$J$54) -> 22 | T19: =NETWORKDAYS.INTL($T$3,$T$4,1,DIAS!$F$51:$J$54) -> 20 | U19: =NETWORKDAYS.INTL($U$3,$U$4,1,DIAS!$F$51:$J$54) -> 20 | V19: =SUM(J19:U19) -> 249 | X19: =SUMIFS(DIAS!$L$11:$L$47,DIAS!$A$11:$A$47,X$5,DIAS!$B$11:$B$47,$B19) -> 0 | Y19: =SUMIFS(DIAS!$L$11:$L$47,DIAS!$A$11:$A$47,Y$5,DIAS!$B$11:$B$47,$B19) -> 0 | Z19: =SUMIFS(DIAS!$L$11:$L$47,DIAS!$A$11:$A$47,Z$5,DIAS!$B$11:$B$47,$B19) -> 0 | AA19: =SUMIFS(DIAS!$L$11:$L$47,DIAS!$A$11:$A$47,AA$5,DIAS!$B$11:$B$47,$B19) -> 2 | AB19: =SUMIFS(DIAS!$L$11:$L$47,DIAS!$A$11:$A$47,AB$5,DIAS!$B$11:$B$47,$B19) -> 7 | AC19: =SUMIFS(DIAS!$L$11:$L$47,DIAS!$A$11:$A$47,AC$5,DIAS!$B$11:$B$47,$B19) -> 0 | AD19: =SUMIFS(DIAS!$L$11:$L$47,DIAS!$A$11:$A$47,AD$5,DIAS!$B$11:$B$47,$B19) -> 5 | AE19: =SUMIFS(DIAS!$L$11:$L$47,DIAS!$A$11:$A$47,AE$5,DIAS!$B$11:$B$47,$B19) -> 0 | ... AI19: =SUMIFS(DIAS!$L$11:$L$47,DIAS!$A$11:$A$47,AI$5,DIAS!$B$11:$B$47,$B19) -> 0 | AJ19: =SUM(X19:AI19) -> 19 | AL19: =+J19-X19 -> 22 | AM19: =+K19-Y19 -> 20 | AN19: =+L19-Z19 -> 21 | AO19: =+M19-AA19 -> 18 | AP19: =+N19-AB19 -> 14 | AQ19: =+O19-AC19 -> 21 | AR19: =+P19-AD19 -> 15 | AS19: =+Q19-AE19 -> 20 | ... AW19: =+U19-AI19 -> 20 | AX19: =+SUM(AL19:AW19) -> 230
A20: 01 | B20: 73093059 | C20: VEGA | D20: FARRO | E20: JOSE RICARDO | F20: 45658 | G20: =+DIAS!F71 -> 45996 | J20: =NETWORKDAYS.INTL($J$3,$J$4,1,DIAS!$F$51:$J$54) -> 22 | K20: =NETWORKDAYS.INTL($K$3,$K$4,1,DIAS!$F$51:$J$54) -> 20 | L20: =NETWORKDAYS.INTL($L$3,$L$4,1,DIAS!$F$51:$J$54) -> 21 | M20: =NETWORKDAYS.INTL($M$3,$M$4,1,DIAS!$F$51:$J$54) -> 20 | N20: =NETWORKDAYS.INTL($N$3,$N$4,1, DIAS!$F$51:$J$54) -> 21 | O20: =NETWORKDAYS.INTL($O$3,$O$4,1,DIAS!$F$51:$J$54) -> 21 | P20: =NETWORKDAYS.INTL($P$3,$P$4,1, DIAS!$F$51:$J$54) -> 20 | Q20: =NETWORKDAYS.INTL($Q$3,$Q$4,1,DIAS!$F$51:$J$54) -> 20 | R20: =NETWORKDAYS.INTL($R$3,$R$4,1,DIAS!$F$51:$J$54) -> 22 | S20: =NETWORKDAYS.INTL($S$3,$S$4,1,DIAS!$F$51:$J$54) -> 22 | T20: =NETWORKDAYS.INTL($T$3,$T$4,1,DIAS!$F$51:$J$54) -> 20 | U20: =NETWORKDAYS.INTL($U$3,$G$20,1,DIAS!$F$51:$J$54) -> 5 | V20: =SUM(J20:U20) -> 234 | X20: =SUMIFS(DIAS!$L$11:$L$47,DIAS!$A$11:$A$47,X$5,DIAS!$B$11:$B$47,$B20) -> 0 | Y20: =SUMIFS(DIAS!$L$11:$L$47,DIAS!$A$11:$A$47,Y$5,DIAS!$B$11:$B$47,$B20) -> 0 | Z20: =SUMIFS(DIAS!$L$11:$L$47,DIAS!$A$11:$A$47,Z$5,DIAS!$B$11:$B$47,$B20) -> 0 | AA20: =SUMIFS(DIAS!$L$11:$L$47,DIAS!$A$11:$A$47,AA$5,DIAS!$B$11:$B$47,$B20) -> 0 | AB20: =SUMIFS(DIAS!$L$11:$L$47,DIAS!$A$11:$A$47,AB$5,DIAS!$B$11:$B$47,$B20) -> 0 | AC20: =SUMIFS(DIAS!$L$11:$L$47,DIAS!$A$11:$A$47,AC$5,DIAS!$B$11:$B$47,$B20) -> 0 | AD20: =SUMIFS(DIAS!$L$11:$L$47,DIAS!$A$11:$A$47,AD$5,DIAS!$B$11:$B$47,$B20) -> 0 | AE20: =SUMIFS(DIAS!$L$11:$L$47,DIAS!$A$11:$A$47,AE$5,DIAS!$B$11:$B$47,$B20) -> 17 | ... AI20: =SUMIFS(DIAS!$L$11:$L$47,DIAS!$A$11:$A$47,AI$5,DIAS!$B$11:$B$47,$B20) -> 0 | AJ20: =SUM(X20:AI20) -> 17 | AL20: =+J20-X20 -> 22 | AM20: =+K20-Y20 -> 20 | AN20: =+L20-Z20 -> 21 | AO20: =+M20-AA20 -> 20 | AP20: =+N20-AB20 -> 21 | AQ20: =+O20-AC20 -> 21 | AR20: =+P20-AD20 -> 20 | AS20: =+Q20-AE20 -> 3 | ... AW20: =+U20-AI20 -> 5 | AX20: =+SUM(AL20:AW20) -> 217
J21: =SUM(J6:J20) -> 330 | K21: =SUM(K6:K20) -> 300 | L21: =SUM(L6:L20) -> 315 | M21: =SUM(M6:M20) -> 300 | N21: =SUM(N6:N20) -> 315 | O21: =SUM(O6:O20) -> 315 | P21: =SUM(P6:P20) -> 300 | Q21: =SUM(Q6:Q20) -> 300 | ... U21: =SUM(U6:U20) -> 285 | V21: =SUM(J21:U21) -> 3720 | X21: =SUM(X6:X20) -> 42 | Y21: =SUM(Y6:Y20) -> 46 | Z21: =SUM(Z6:Z20) -> 25 | AA21: =SUM(AA6:AA20) -> 24 | AB21: =SUM(AB6:AB20) -> 18 | AC21: =SUM(AC6:AC20) -> 25 | AD21: =SUM(AD6:AD20) -> 42 | AE21: =SUM(AE6:AE20) -> 19 | ... AI21: =SUM(AI6:AI20) -> 8 | AJ21: =SUM(X21:AI21) -> 309 | AL21: =SUM(AL6:AL20) -> 288 | AM21: =SUM(AM6:AM20) -> 254 | AN21: =SUM(AN6:AN20) -> 290 | AO21: =SUM(AO6:AO20) -> 276 | AP21: =SUM(AP6:AP20) -> 297 | AQ21: =SUM(AQ6:AQ20) -> 290 | AR21: =SUM(AR6:AR20) -> 258 | AS21: =SUM(AS6:AS20) -> 281 | ... AX21: =SUM(AX6:AX20) -> 3411

Sheet UTILIDADES
B3: UTILIDADES GERENCIA DE RIESGOS 2025
B5: DNI | C5: Nombre del Trabajador | D5: CARGO | E5: FECHA DE INGRESO | F5: FECHA DE CESE | G5: Nº dias Efectivos Laborados | H5: Total de Remuneraciones | J5: EN FUNCION A DIAS | K5: EN FUNCION A REMUNERACIONES | L5: TOTAL DE UTILIDADES | M5: IR 5ta CATEGORIA | N5: RETENCION JUDICIAL | O5: ADELANTO | P5: UTILIDADES NETAS | R5: TRAMO PROYECTADO | S5: ACTIVO
A6: 1 | B6: 46345862 | C6: CATAÑO OYANGUREN GIANCARLO | E6: 45658 | F6: 46022 | G6: =VLOOKUP(B6,DIAS!$B$57:$L$71,11,) -> 237 | H6: =VLOOKUP(B6,REM!$B$4:$U$18,20,) -> 39060 | J6: =+G6*$H$27 -> 1752.8438 | K6: =+H6*$H$28 -> 1035.1095 | L6: =+ROUND(J6+K6,2) -> 2787.95 | M6: =+ROUND(L6*R6,2) -> 223.04 | P6: =+ROUND(L6-M6-N6-O6,2) -> 2564.91 | R6: =HLOOKUP(B6,'5TA'!$B$2:$O$23,22,FALSE) -> 0.08 | S6: ACTIVO
A7: 2 | B7: 72196931 | C7: CONDORI LOPEZ ANDREA DEL PILAR | E7: 45658 | F7: 46022 | G7: =VLOOKUP(B7,DIAS!$B$57:$L$71,11,) -> 230 | H7: =VLOOKUP(B7,REM!$B$4:$U$18,20,) -> 45440 | J7: =+G7*$H$27 -> 1701.072 | K7: =+H7*$H$28 -> 1204.1827 | L7: =+ROUND(J7+K7,2) -> 2905.25 | M7: =+ROUND(L7*R7,2) -> 232.42 | P7: =+ROUND(L7-M7-N7-O7,2) -> 2672.83 | R7: =HLOOKUP(B7,'5TA'!$B$2:$O$23,22,FALSE) -> 0.08 | S7: ACTIVO
A8: 3 | B8: 41194847 | C8: DURAND GARCIA ERICKA RAQUEL | E8: 45658 | F8: 46022 | G8: =VLOOKUP(B8,DIAS!$B$57:$L$71,11,) -> 229 | H8: =VLOOKUP(B8,REM!$B$4:$U$18,20,) -> 55700 | J8: =+G8*$H$27 -> 1693.676 | K8: =+H8*$H$28 -> 1476.0778 | L8: =+ROUND(J8+K8,2) -> 3169.75 | M8: =+ROUND(L8*R8,2) -> 253.58 | P8: =+ROUND(L8-M8-N8-O8,2) -> 2916.17 | R8: =HLOOKUP(B8,'5TA'!$B$2:$O$23,22,FALSE) -> 0.08 | S8: ACTIVO
A9: 4 | B9: 41202202 | C9: GARCIA ZAVALETA GIOVANNA HERMELINDA | E9: 45658 | F9: 46022 | G9: =VLOOKUP(B9,DIAS!$B$57:$L$71,11,) -> 234 | H9: =VLOOKUP(B9,REM!$B$4:$U$18,20,) -> 57782 | J9: =+G9*$H$27 -> 1730.6559 | K9: =+H9*$H$28 -> 1531.2518 | L9: =+ROUND(J9+K9,2) -> 3261.91 | M9: =+ROUND(L9*R9,2) -> 260.95 | P9: =+ROUND(L9-M9-N9-O9,2) -> 3000.96 | R9: =HLOOKUP(B9,'5TA'!$B$2:$O$23,22,FALSE) -> 0.08 | S9: ACTIVO
A10: 5 | B10: 42263949 | C10: HERRERA ANDAMAYO NAHALA DOROTHY | E10: 45658 | F10: 46022 | G10: =VLOOKUP(B10,DIAS!$B$57:$L$71,11,) -> 223 | H10: =VLOOKUP(B10,REM!$B$4:$U$18,20,) -> 56582 | J10: =+G10*$H$27 -> 1649.3003 | K10: =+H10*$H$28 -> 1499.4512 | L10: =+ROUND(J10+K10,2) -> 3148.75 | M10: =+ROUND(L10*R10,2) -> 251.9 | P10: =+ROUND(L10-M10-N10-O10,2) -> 2896.85 | R10: =HLOOKUP(B10,'5TA'!$B$2:$O$23,22,FALSE) -> 0.08 | S10: ACTIVO
A11: 6 | B11: 46098021 | C11: HERRERA GERONIMO MARYELIZA SANTA | E11: 45658 | F11: 46022 | G11: =VLOOKUP(B11,DIAS!$B$57:$L$71,11,) -> 231 | H11: =VLOOKUP(B11,REM!$B$4:$U$18,20,) -> 36500 | J11: =+G11*$H$27 -> 1708.468 | K11: =+H11*$H$28 -> 967.26822 | L11: =+ROUND(J11+K11,2) -> 2675.74 | M11: =+ROUND(L11*R11,2) -> 0 | P11: =+ROUND(L11-M11-N11-O11,2) -> 2675.74 | R11: =HLOOKUP(B11,'5TA'!$B$2:$O$23,22,FALSE) -> 0 | S11: ACTIVO
A12: 7 | B12: 40243954 | C12: KUANG CHUSING HECTOR ENRIQUE | E12: 45658 | F12: 46022 | G12: =VLOOKUP(B12,DIAS!$B$57:$L$71,11,) -> 229 | H12: =VLOOKUP(B12,REM!$B$4:$U$18,20,) -> 210000 | J12: =+G12*$H$27 -> 1693.676 | K12: =+H12*$H$28 -> 5565.1048 | L12: =+ROUND(J12+K12,2) -> 7258.78 | M12: =+ROUND(L12*R12,2) -> 1233.99 | P12: =+ROUND(L12-M12-N12-O12,2) -> 6024.79 | R12: =HLOOKUP(B12,'5TA'!$B$2:$O$23,22,FALSE) -> 0.17 | S12: ACTIVO
A13: 8 | B13: 10798282 | C13: KUANG CHUSING NANCY AIDA | E13: 45658 | F13: 46022 | G13: =VLOOKUP(B13,DIAS!$B$57:$L$71,11,) -> 229 | H13: =VLOOKUP(B13,REM!$B$4:$U$18,20,) -> 141582 | J13: =+G13*$H$27 -> 1693.676 | K13: =+H13*$H$28 -> 3751.9937 | L13: =+ROUND(J13+K13,2) -> 5445.67 | M13: =+ROUND(L13*R13,2) -> 762.39 | P13: =+ROUND(L13-M13-N13-O13,2) -> 4683.28 | R13: =HLOOKUP(B13,'5TA'!$B$2:$O$23,22,FALSE) -> 0.14 | S13: ACTIVO
A14: 9 | B14: 09859427 | C14: KUANG LINARES MARIA ROSARIO | E14: 45658 | F14: 46022 | G14: =VLOOKUP(B14,DIAS!$B$57:$L$71,11,) -> 229 | H14: =VLOOKUP(B14,REM!$B$4:$U$18,20,) -> 53200 | J14: =+G14*$H$27 -> 1693.676 | K14: =+H14*$H$28 -> 1409.8266 | L14: =+ROUND(J14+K14,2) -> 3103.5 | M14: =+ROUND(L14*R14,2) -> 248.28 | P14: =+ROUND(L14-M14-N14-O14,2) -> 2855.22 | R14: =HLOOKUP(B14,'5TA'!$B$2:$O$23,22,FALSE) -> 0.08 | S14: ACTIVO
A15: 10 | B15: 41320534 | C15: LEZAMA ULLOA CESAR ENRIQUE | E15: 45658 | F15: 46022 | G15: =VLOOKUP(B15,DIAS!$B$57:$L$71,11,) -> 225 | H15: =VLOOKUP(B15,REM!$B$4:$U$18,20,) -> 40882 | J15: =+G15*$H$27 -> 1664.0922 | K15: =+H15*$H$28 -> 1083.3934 | L15: =+ROUND(J15+K15,2) -> 2747.49 | M15: =+ROUND(L15*R15,2) -> 219.8 | P15: =+ROUND(L15-M15-N15-O15,2) -> 2527.69 | R15: =HLOOKUP(B15,'5TA'!$B$2:$O$23,22,FALSE) -> 0.08 | S15: ACTIVO
A16: 11 | B16: 44262618 | C16: NIQUEN PUMA MARIELLA ISABEL | E16: 45658 | F16: 46022 | G16: =VLOOKUP(B16,DIAS!$B$57:$L$71,11,) -> 227 | H16: =VLOOKUP(B16,REM!$B$4:$U$18,20,) -> 40782 | J16: =+G16*$H$27 -> 1678.8841 | K16: =+H16*$H$28 -> 1080.7434 | L16: =+ROUND(J16+K16,2) -> 2759.63 | M16: =+ROUND(L16*R16,2) -> 220.77 | P16: =+ROUND(L16-M16-N16-O16,2) -> 2538.86 | R16: =HLOOKUP(B16,'5TA'!$B$2:$O$23,22,FALSE) -> 0.08 | S16: ACTIVO
A17: 12 | B17: 40640169 | C17: OLIVARES HERRERA LILY | E17: 45658 | F17: 46022 | G17: =VLOOKUP(B17,DIAS!$B$57:$L$71,11,) -> 231 | H17: =VLOOKUP(B17,REM!$B$4:$U$18,20,) -> 49000 | J17: =+G17*$H$27 -> 1708.468 | K17: =+H17*$H$28 -> 1298.5245 | L17: =+ROUND(J17+K17,2) -> 3006.99 | M17: =+ROUND(L17*R17,2) -> 240.56 | P17: =+ROUND(L17-M17-N17-O17,2) -> 2766.43 | R17: =HLOOKUP(B17,'5TA'!$B$2:$O$23,22,FALSE) -> 0.08 | S17: ACTIVO
... A19: 14 | B19: 43658082 | C19: TENORIO FERNANDEZ JOSE VICTOR | E19: 45658 | F19: 46022 | G19: =VLOOKUP(B19,DIAS!$B$57:$L$71,11,) -> 215 | H19: =VLOOKUP(B19,REM!$B$4:$U$18,20,) -> 45800 | J19: =+G19*$H$27 -> 1590.1325 | K19: =+H19*$H$28 -> 1213.7229 | L19: =+ROUND(J19+K19,2) -> 2803.86 | M19: =+ROUND(L19*R19,2) -> 224.31 | P19: =+ROUND(L19-M19-N19-O19,2) -> 2579.55 | R19: =HLOOKUP(B19,'5TA'!$B$2:$O$23,22,FALSE) -> 0.08 | S19: ACTIVO
A20: 15 | B20: 73093059 | C20: VEGA FARRO JOSE RICARDO | E20: 45658 | F20: 45996 | G20: =VLOOKUP(B20,DIAS!$B$57:$L$71,11,) -> 217 | H20: =VLOOKUP(B20,REM!$B$4:$U$18,20,) -> 33576.39 | J20: =+G20*$H$27 -> 1604.9245 | K20: =+H20*$H$28 -> 889.79109 | L20: =+ROUND(J20+K20,2) -> 2494.72 | P20: =+ROUND(L20-M20-N20-O20,2) -> 2494.72
G21: =SUM(G6:G20) -> 3411 | H21: =SUM(H6:H20) -> 951968.39 | J21: =SUM(J6:J20) -> 25227.638 | K21: =SUM(K6:K20) -> 25227.638 | L21: =SUM(L6:L20) -> 50455.28 | M21: =SUM(M6:M20) -> 4602.81 | P21: =+ROUND(L21-M21-N21-O21,2) -> 45852.47
E23: Renta anual de la empresa antes de impuestos : | H23: 1009105.5
E24: Porcentaje a distribuir : | H24: 0.05
E25: Monto a distribuir : | H25: =H23*H24 -> 50455.275
E27: Factor Dias trabajados : | G27: 0.5 | H27: =H25/2/G21 -> 7.3959653
E28: Factor Total Remuneraciones : | G28: 0.5 | H28: =+H25/2/H21 -> 0.026500499

Sheet BOLETA
L3: 5
M5: 1 | N5: KUANG LINARES MARIA ROSARIO
M6: 2 | N6: KUANG CHUSING HECTOR ENRIQUE
M7: 3 | N7: OLIVARES HERRERA LILY
M8: 4 | N8: HERRERA ANDAMAYO NAHALA DOROTHY
M9: 5 | N9: DURAND GARCIA ERICKA RAQUEL
M10: 6 | N10: GARCIA ZAVALETA GIOVANNA HERMELINDA
B11: PARTICIPACION EN LAS UTILIDADES VOLUNTARIAS POR EL EJERCICIO GRAVABLE 2025 | M11: 7 | N11: NIQUEN PUMA MARIELLA ISABEL
M12: 8 | N12: LEZAMA ULLOA CESAR ENRIQUE
M13: 9 | N13: ORELLANA CORI CESAR ENRIQUE
B14: GERENCIA DE RIESGOS ASESORES Y CORREDORES DE SEGUROS S.R.L., con RUC Nº 20258342241 domiciliado en Calle La Casuarina Nro. 291 Urb. Los Sauces, Distrito de Surquillo, Provincia y Departamento de Lima, debidamente representada por HECTOR ENRIQUE KUANG CHUSING con DNI 40243954, en su calidad de empleador y en cumplimiento, deja constancia de la determinación, distribución y pago de la participación en las utilidades voluntarias al : | M14: 10 | N14: TENORIO FERNANDEZ JOSE VICTOR
M15: 11 | N15: CATAÑO OYANGUREN GIANCARLO
M16: 12 | N16: KUANG CHUSING NANCY AIDA
M17: 13 | N17: CONDORI LOPEZ ANDREA DEL PILAR
M18: 14 | N18: HERRERA GERONIMO MARYELIZA SANTA
B19: Sr.(a) | C19: =VLOOKUP(L3,UTILIDADES!A6:C20,3,0) -> HERRERA ANDAMAYO NAHALA DOROTHY | G19: identificado(a) con DNI / C.E. | J19: =VLOOKUP(L3,UTILIDADES!A6:C20,2,0) -> 42263949 | K19: , | M19: 15 | N19: MENDOZA DEL AGUILA CAROLINA DEL ROSARIO
B20: correspondiente al ejercicio gravable 2025, calculado en base al siguiente detalle: | M20: 16 | N20: VEGA FARRO JOSE RICARDO
M21: 17 | N21: BRAVO VASQUEZ ROSALÍA
B23: 1. UTILIDAD POR DISTRIBUIR
B25: - Renta anual de la empresa antes de impuestos : | J25: =+UTILIDADES!H23 -> 1009105.5
B27: - Porcentaje a distribuir : | J27: 0.05
B29: - Monto a distribuir : | J29: =J25*J27 -> 50455.275
B31: 2. CALCULO DE LA PARTICIPACION
B33: 2.1. SEGÚN LOS DÍAS LABORADOS
B35: - Número total de días laborados durante el ejercicio 2025 por todos los trabajadores
B36: de la empresa con derecho a percibir utilidades : | J36: =+UTILIDADES!G21 -> 3411
B38: - Número de días laborados durante el ejercicio 2025 por el trabajador : | J38: =VLOOKUP(BOLETA!J19,UTILIDADES!B6:P20,6,0) -> 223
B40: - Participación del trabajador según los días laborados : | J40: =VLOOKUP(BOLETA!J19,UTILIDADES!B6:P20,9,0) -> 1649.3003
B42: 2.2. SEGÚN LAS REMUNERACION PERCIBIDAS
B44: - Remuneración computable total pagada durante el ejercicio 2025 a todos los
B45: trabajadores de la empresa : | J45: =+UTILIDADES!H21 -> 951968.39
B47: - Remuneración computable percibida durante el ejercicio 2025 por el trabajador : | J47: =VLOOKUP(BOLETA!J19,UTILIDADES!B6:P20,7,0) -> 56582
B49: - Participación del trabajador según las remuneraciones percibidas : | J49: =VLOOKUP(BOLETA!J19,UTILIDADES!B6:P20,10,0) -> 1499.4512
B51: 3. MONTO DE LA PARTICIPACIÓN A PERCIBIR POR EL TRABAJADOR
B53: - Participación según los días laborados : | J53: =+J40 -> 1649.3003
B55: - Participación según las remuneraciones percibidas : | J55: =+J49 -> 1499.4512
B57: - Total de la participación del trabajador en las utilidades : | J57: =ROUND(J53+J55,2) -> 3148.75
B59: - Descuento de Renta de Quinta Categoria : | J59: =VLOOKUP(BOLETA!J19,UTILIDADES!B6:P20,12,0) -> 251.9
B61: TOTAL DE LA PARTICIPACION NETA DEL TRABAJADOR EN LAS UTILIDADES | J61: =J57-J59 -> 2896.85
B66: Lima, | C66: 46101
...

Sheet DIAS
A2: R07: Trabajadores - Motivos de suspensión de labores | J2: 11/03/2026
A3: RUC : 20258342241
A4: Empleador : GERENCIA DE RIESGOS ASESORES Y CORREDORES DE SEGUROS S.R.L.
A5: Periodo : 01/2025 a 12/2025
A6: PDT Planilla Electrónica - PLAME Número de Orden :
A8: Datos del Trabajador | F8: Motivos de Suspensión de Labores
A9: Documento de Identidad | C9: Apellido Paterno | D9: Apellido Materno | E9: Nombres | F9: Código | G9: Descripción | J9: Num. Días
A10: Tipo | B10: Número
A11: ENERO | B11: 09859427 | C11: KUANG | D11: LINARES | E11: MARIA ROSARIO | F11: 23 | G11: S.I. DESCANSO VACACIONAL | J11: 28 | L11: =NETWORKDAYS.INTL(M11,N11,1,$F$51:$J$54) -> 20 | M11: 45659 | N11: 45686 | O11: =+N11-M11+1-J11 -> 0
A12: ENERO | B12: 40243954 | C12: KUANG | D12: CHUSING | E12: HECTOR ENRIQUE | F12: 23 | G12: S.I. DESCANSO VACACIONAL | J12: 28 | L12: =NETWORKDAYS.INTL(M12,N12,1,$F$51:$J$54) -> 20 | M12: 45659 | N12: 45686 | O12: =+N12-M12+1-J12 -> 0
A13: ENERO | B13: 42263949 | C13: HERRERA | D13: ANDAMAYO | E13: NAHALA DOROTHY | F13: 20 | G13: S.I. ENFERM/ACCIDENTE (20 PRIMEROS DÍAS) | J13: 2 | L13: =NETWORKDAYS.INTL(M13,N13,1,$F$51:$J$54) -> 2 | M13: 45665 | N13: 45666 | O13: =+N13-M13+1-J13 -> 0
A14: FEBRERO | B14: 10798282 | C14: KUANG | D14: CHUSING | E14: NANCY AIDA | F14: 23 | G14: S.I. DESCANSO VACACIONAL | J14: 28 | L14: =NETWORKDAYS.INTL(M14,N14,1,$F$51:$J$54) -> 20 | M14: 45689 | N14: 45716 | O14: =+N14-M14+1-J14 -> 0
A15: FEBRERO | B15: 41320534 | C15: LEZAMA | D15: ULLOA | E15: CESAR ENRIQUE | F15: 23 | G15: S.I. DESCANSO VACACIONAL | J15: 1 | L15: =NETWORKDAYS.INTL(M15,N15,1,$F$51:$J$54) -> 1 | M15: 45702 | N15: 45702 | O15: =+N15-M15+1-J15 -> 0
A16: FEBRERO | B16: 43658082 | C16: TENORIO | D16: FERNANDEZ | E16: JOSE VICTOR | F16: 23 | G16: S.I. DESCANSO VACACIONAL | J16: 7 | L16: =NETWORKDAYS.INTL(M16,N16,1,$F$51:$J$54) -> 5 | M16: 45705 | N16: 45711 | O16: =+N16-M16+1-J16 -> 0
A17: FEBRERO | B17: 44262618 | C17: NIQUEN | D17: PUMA | E17: MARIELLA ISABEL | F17: 23 | G17: S.I. DESCANSO VACACIONAL | J17: 28 | L17: =NETWORKDAYS.INTL(M17,N17,1,$F$51:$J$54) -> 20 | M17: 45689 | N17: 45716 | O17: =+N17-M17+1-J17 -> 0
A18: MARZO | B18: 41194847 | C18: DURAND | D18: GARCIA | E18: ERICKA RAQUEL | F18: 23 | G18: S.I. DESCANSO VACACIONAL | J18: 28 | L18: =NETWORKDAYS.INTL(M18,N18,1,$F$51:$J$54) -> 20 | M18: 45717 | N18: 45744 | O18: =+N18-M18+1-J18 -> 0
A19: MARZO | B19: 42263949 | C19: HERRERA | D19: ANDAMAYO | E19: NAHALA DOROTHY | F19: 20 | G19: S.I. ENFERM/ACCIDENTE (20 PRIMEROS DÍAS) | J19: 1 | L19: =NETWORKDAYS.INTL(M19,N19,1,$F$51:$J$54) -> 0 | M19: 45738 | N19: 45738 | O19: =+N19-M19+1-J19 -> 0
A20: MARZO | B20: 46345862 | C20: CATAÑO | D20: OYANGUREN | E20: GIANCARLO | F20: 23 | G20: S.I. DESCANSO VACACIONAL | J20: 7 | L20: =NETWORKDAYS.INTL(M20,N20,1,$F$51:$J$54) -> 5 | M20: 45903 | N20: 45909 | O20: =+N20-M20+1-J20 -> 0
A21: ABRIL | B21: 40640169 | C21: OLIVARES | D21: HERRERA | E21: LILY | F21: 23 | G21: S.I. DESCANSO VACACIONAL | J21: 28 | L21: =NETWORKDAYS.INTL(M21,N21,1,$F$51:$J$54) -> 18 | M21: 45748 | N21: 45775 | O21: =+N21-M21+1-J21 -> 0
A22: ABRIL | B22: 41202202 | C22: GARCIA | D22: ZAVALETA | E22: GIOVANNA HERMELINDA | F22: 20 | G22: S.I. ENFERM/ACCIDENTE (20 PRIMEROS DÍAS) | J22: 2 | L22: =NETWORKDAYS.INTL(M22,N22,1,$F$51:$J$54) -> 2 | M22: 45757 | N22: 45758 | O22: =+N22-M22+1-J22 -> 0
... A47: DICIEMBRE | B47: 46419969 | C47: ORELLANA | D47: CORI | E47: CESAR ENRIQUE | F47: 23 | G47: S.I. DESCANSO VACACIONAL | J47: 2 | L47: =NETWORKDAYS.INTL(M47,N47,1,$F$51:$J$54) -> 2 | M47: 45992 | N47: 45993 | O47: =+N47-M47+1-J47 -> 0
J48: =SUM(J11:J47) -> 435 | L48: =SUM(L11:L47) -> 309
A50: FERIADOS
F51: 45658 | G51: 45764 | H51: 45765 | I51: 45778 | J51: 45815
F52: 45837 | G52: 45861 | H52: 45866 | I52: 45867 | J52: 45875
F53: 45899 | G53: 45938 | H53: 45962 | I53: 45999 | J53: 46000
F54: 46016
L55: DIAS AFECTOS
B56: DNI | C56: NOMBRE | D56: INICIO | E56: INICIO | F56: CESE | G56: DIAS ENE-DIC | J56: DIAS NO LAB. | L56: A UTILIDADES 2025
B57: 46345862 | C57: CATAÑO OYANGUREN GIANCARLO | D57: 42278 | E57: 45658 | F57: 46022 | G57: =NETWORKDAYS.INTL(E57,F57,1,$F$51:$J$54) -> 249 | J57: =SUMIF($B$11:$B$47,B57,$L$11:$L$47) -> 12 | L57: =+G57-J57 -> 237 | N57: =VLOOKUP(B57,DIC_2025!$C$6:$C$20,1,) -> 46345862 | O57: =+B57-N57 -> 0
B58: 72196931 | C58: CONDORI LOPEZ ANDREA DEL PILAR | D58: 42297 | E58: 45658 | F58: 46022 | G58: =NETWORKDAYS.INTL(E58,F58,1,$F$51:$J$54) -> 249 | J58: =SUMIF($B$11:$B$47,B58,$L$11:$L$47) -> 19 | L58: =+G58-J58 -> 230 | N58: =VLOOKUP(B58,DIC_2025!$C$6:$C$20,1,) -> 72196931 | O58: =+B58-N58 -> 0
B59: 41194847 | C59: DURAND GARCIA ERICKA RAQUEL | D59: 40634 | E59: 45658 | F59: 46022 | G59: =NETWORKDAYS.INTL(E59,F59,1,$F$51:$J$54) -> 249 | J59: =SUMIF($B$11:$B$47,B59,$L$11:$L$47) -> 20 | L59: =+G59-J59 -> 229 | N59: =VLOOKUP(B59,DIC_2025!$C$6:$C$20,1,) -> 41194847 | O59: =+B59-N59 -> 0
B60: 41202202 | C60: GARCIA ZAVALETA GIOVANNA HERMELINDA | D60: 40817 | E60: 45658 | F60: 46022 | G60: =NETWORKDAYS.INTL(E60,F60,1,$F$51:$J$54) -> 249 | J60: =SUMIF($B$11:$B$47,B60,$L$11:$L$47) -> 15 | L60: =+G60-J60 -> 234 | N60: =VLOOKUP(B60,DIC_2025!$C$6:$C$20,1,) -> 41202202 | O60: =+B60-N60 -> 0
B61: 42263949 | C61: HERRERA ANDAMAYO NAHALA DOROTHY | D61: 40180 | E61: 45658 | F61: 46022 | G61: =NETWORKDAYS.INTL(E61,F61,1,$F$51:$J$54) -> 249 | J61: =SUMIF($B$11:$B$47,B61,$L$11:$L$47) -> 26 | L61: =+G61-J61 -> 223 | N61: =VLOOKUP(B61,DIC_2025!$C$6:$C$20,1,) -> 42263949 | O61: =+B61-N61 -> 0
B62: 46098021 | C62: HERRERA GERONIMO MARYELIZA SANTA | D62: 42767 | E62: 45658 | F62: 46022 | G62: =NETWORKDAYS.INTL(E62,F62,1,$F$51:$J$54) -> 249 | J62: =SUMIF($B$11:$B$47,B62,$L$11:$L$47) -> 18 | L62: =+G62-J62 -> 231 | N62: =VLOOKUP(B62,DIC_2025!$C$6:$C$20,1,) -> 46098021 | O62: =+B62-N62 -> 0
B63: 40243954 | C63: KUANG CHUSING HECTOR ENRIQUE | D63: 37803 | E63: 45658 | F63: 46022 | G63: =NETWORKDAYS.INTL(E63,F63,1,$F$51:$J$54) -> 249 | J63: =SUMIF($B$11:$B$47,B63,$L$11:$L$47) -> 20 | L63: =+G63-J63 -> 229 | N63: =VLOOKUP(B63,DIC_2025!$C$6:$C$20,1,) -> 40243954 | O63: =+B63-N63 -> 0
B64: 10798282 | C64: KUANG CHUSING NANCY AIDA | D64: 42296 | E64: 45658 | F64: 46022 | G64: =NETWORKDAYS.INTL(E64,F64,1,$F$51:$J$54) -> 249 | J64: =SUMIF($B$11:$B$47,B64,$L$11:$L$47) -> 20 | L64: =+G64-J64 -> 229 | N64: =VLOOKUP(B64,DIC_2025!$C$6:$C$20,1,) -> 10798282 | O64: =+B64-N64 -> 0
B65: 09859427 | C65: KUANG LINARES MARIA ROSARIO | D65: 35933 | E65: 45658 | F65: 46022 | G65: =NETWORKDAYS.INTL(E65,F65,1,$F$51:$J$54) -> 249 | J65: =SUMIF($B$11:$B$47,B65,$L$11:$L$47) -> 20 | L65: =+G65-J65 -> 229 | N65: =VLOOKUP(B65,DIC_2025!$C$6:$C$20,1,) -> 09859427 | O65: =+B65-N65 -> 0
B66: 41320534 | C66: LEZAMA ULLOA CESAR ENRIQUE | D66: 41518 | E66: 45658 | F66: 46022 | G66: =NETWORKDAYS.INTL(E66,F66,1,$F$51:$J$54) -> 249 | J66: =SUMIF($B$11:$B$47,B66,$L$11:$L$47) -> 24 | L66: =+G66-J66 -> 225 | N66: =VLOOKUP(B66,DIC_2025!$C$6:$C$20,1,) -> 41320534 | O66: =+B66-N66 -> 0
B67: 44262618 | C67: NIQUEN PUMA MARIELLA ISABEL | D67: 41334 | E67: 45658 | F67: 46022 | G67: =NETWORKDAYS.INTL(E67,F67,1,$F$51:$J$54) -> 249 | J67: =SUMIF($B$11:$B$47,B67,$L$11:$L$47) -> 22 | L67: =+G67-J67 -> 227 | N67: =VLOOKUP(B67,DIC_2025!$C$6:$C$20,1,) -> 44262618 | O67: =+B67-N67 -> 0
...

Sheet REM
A1: Datos del Trabajador
A2: Documento de Identidad | C2: Apellido Paterno | D2: Apellido Materno | E2: Nombres | F2: FECHA DE INICIO | G2: FECHA DE CESE
A3: Tipo | B3: Número | I3: ENERO | J3: FEBRERO | K3: MARZO | L3: ABRIL | M3: MAYO | N3: JUNIO | O3: JULIO | P3: AGOSTO | Q3: SETIEMBRE | R3: OCTUBRE | S3: NOVIEMBRE | T3: DICIEMBRE | U3: total
A4: 01 | B4: 09859427 | C4: KUANG | D4: LINARES | E4: MARIA ROSARIO | F4: 45658 | G4: 46022 | I4: 3800 | J4: 3800 | K4: 3800 | L4: 3800 | M4: 3800 | N4: 3800 | O4: 7600 | P4: 3800 | Q4: 3800 | R4: 3800 | S4: 3800 | T4: 7600 | U4: =SUM(I4:T4) -> 53200
A5: 01 | B5: 10798282 | C5: KUANG | D5: CHUSING | E5: NANCY AIDA | F5: 45658 | G5: 46022 | I5: 10113 | J5: 10113 | K5: 10113 | L5: 10113 | M5: 10113 | N5: 10113 | O5: 20226 | P5: 10113 | Q5: 10113 | R5: 10113 | S5: 10113 | T5: 20226 | U5: =SUM(I5:T5) -> 141582
A6: 01 | B6: 40243954 | C6: KUANG | D6: CHUSING | E6: HECTOR ENRIQUE | F6: 45658 | G6: 46022 | I6: 15000 | J6: 15000 | K6: 15000 | L6: 15000 | M6: 15000 | N6: 15000 | O6: 30000 | P6: 15000 | Q6: 15000 | R6: 15000 | S6: 15000 | T6: 30000 | U6: =SUM(I6:T6) -> 210000
A7: 01 | B7: 40640169 | C7: OLIVARES | D7: HERRERA | E7: LILY | F7: 45658 | G7: 46022 | I7: 3500 | J7: 3500 | K7: 3500 | L7: 3500 | M7: 3500 | N7: 3500 | O7: 7000 | P7: 3500 | Q7: 3500 | R7: 3500 | S7: 3500 | T7: 7000 | U7: =SUM(I7:T7) -> 49000
A8: 01 | B8: 41194847 | C8: DURAND | D8: GARCIA | E8: ERICKA RAQUEL | F8: 45658 | G8: 46022 | I8: 3800 | J8: 3800 | K8: 3800 | L8: 3800 | M8: 3800 | N8: 3800 | O8: 7600 | P8: 3800 | Q8: 3800 | R8: 3800 | S8: 3800 | T8: 10100 | U8: =SUM(I8:T8) -> 55700
A9: 01 | B9: 41202202 | C9: GARCIA | D9: ZAVALETA | E9: GIOVANNA HERMELINDA | F9: 45658 | G9: 46022 | I9: 3913 | J9: 3913 | K9: 3913 | L9: 3913 | M9: 3913 | N9: 3913 | O9: 7826 | P9: 3913 | Q9: 3913 | R9: 3913 | S9: 3913 | T9: 10826 | U9: =SUM(I9:T9) -> 57782
A10: 01 | B10: 41320534 | C10: LEZAMA | D10: ULLOA | E10: CESAR ENRIQUE | F10: 45658 | G10: 46022 | I10: 2813 | J10: 2813 | K10: 2813 | L10: 2813 | M10: 2813 | N10: 2813 | O10: 5626 | P10: 2813 | Q10: 2813 | R10: 2813 | S10: 2813 | T10: 7126 | U10: =SUM(I10:T10) -> 40882
A11: 01 | B11: 42263949 | C11: HERRERA | D11: ANDAMAYO | E11: NAHALA DOROTHY | F11: 45658 | G11: 46022 | I11: 3913 | J11: 3913 | K11: 3913 | L11: 3913 | M11: 3913 | N11: 3913 | O11: 7826 | P11: 3913 | Q11: 3913 | R11: 3913 | S11: 3913 | T11: 9626 | U11: =SUM(I11:T11) -> 56582
A12: 01 | B12: 43658082 | C12: TENORIO | D12: FERNANDEZ | E12: JOSE VICTOR | F12: 45658 | G12: 46022 | I12: 3200 | J12: 3200 | K12: 3200 | L12: 3200 | M12: 3200 | N12: 3200 | O12: 6400 | P12: 3200 | Q12: 3200 | R12: 3200 | S12: 3200 | T12: 7400 | U12: =SUM(I12:T12) -> 45800
A13: 01 | B13: 44262618 | C13: NIQUEN | D13: PUMA | E13: MARIELLA ISABEL | F13: 45658 | G13: 46022 | I13: 2913 | J13: 2913 | K13: 2913 | L13: 2913 | M13: 2913 | N13: 2913 | O13: 5826 | P13: 2913 | Q13: 2913 | R13: 2913 | S13: 2913 | T13: 5826 | U13: =SUM(I13:T13) -> 40782
A14: 01 | B14: 46098021 | C14: HERRERA | D14: GERONIMO | E14: MARYELIZA SANTA | F14: 45658 | G14: 46022 | I14: 2500 | J14: 2500 | K14: 2500 | L14: 2500 | M14: 2500 | N14: 2500 | O14: 5000 | P14: 2500 | Q14: 2500 | R14: 2500 | S14: 2500 | T14: 6500 | U14: =SUM(I14:T14) -> 36500
A15: 01 | B15: 46345862 | C15: CATAÑO | D15: OYANGUREN | E15: GIANCARLO | F15: 45658 | G15: 46022 | I15: 2700 | J15: 2700 | K15: 2700 | L15: 2700 | M15: 2700 | N15: 2700 | O15: 5400 | P15: 2700 | Q15: 3960 | R15: 2700 | S15: 2700 | T15: 5400 | U15: =SUM(I15:T15) -> 39060
... A18: 01 | B18: 73093059 | C18: VEGA | D18: FARRO | E18: JOSE RICARDO | F18: 45658 | G18: 46022 | I18: 2500 | J18: 2500 | K18: 2500 | L18: 2500 | M18: 2500 | N18: 2500 | O18: 5000 | P18: 2500 | Q18: 2500 | R18: 2500 | S18: 2500 | T18: 3576.39 | U18: =SUM(I18:T18) -> 33576.39
I19: =SUM(I4:I18) -> 66978 | J19: =SUM(J4:J18) -> 66978 | K19: =SUM(K4:K18) -> 66978 | L19: =SUM(L4:L18) -> 66978 | M19: =SUM(M4:M18) -> 66978 | N19: =SUM(N4:N18) -> 66978 | O19: =SUM(O4:O18) -> 134596 | P19: =SUM(P4:P18) -> 66978 | ... T19: =SUM(T4:T18) -> 146332.39 | U19: =SUM(I19:T19) -> 951968.39

Sheet DIC_2025
A2: RUC | B2: 20258342241
A3: PLANILLA 2Q GERENCIA DE RIESGOS 12.2025
A5: Codigo de Personal | B5: Nombre del Trabajador | C5: DNI | D5: F. Ingreso | E5: F. Cese | F5: Cod. C. Costo | G5: Des. C. Costo | H5: Area | I5: Banco Cargo Empresa | J5: Banco Trabajador | K5: Nro. Cuenta Bancaria | L5: Tipo de Quinta | M5: Categoría | N5: Cargo | O5: Tipo Pension | P5: Com. Mixta | Q5: Sueldo | R5: Dias | S5: DIAS:1023 - D.MEDICO | T5: DIAS:5013 - VAC.NORMAL | U5: Horas | V5: 1001 - S. BASICO | W5: 1003 - R. VACACI | X5: 1012 - ASIG. FAMI | Y5: 1023 - D.MEDICO | Z5: GRATIFICACION | AA5: BONIF EXTRA | AB5: ASIGNACION POR FESTIVIDAD | AC5: BONO ANUAL | AD5: DEVOLUCION 5TA | AE5: TOTAL INGRESOS | AF5: 2001 - AFP FONDO | AG5: 2002 - AFP COMIS | AH5: 2003 - AFP SEGUR | AI5: 2004 - ONP | AJ5: 2005 - 5TA.CATEGO | AK5: 2009 - EPS TRABA. | AL5: 2021 - ADEL.QUINC | AM5: 2022 - ADEL.VACAC | AN5: ADELANTO | AO5: ADELANTO DE GRATIFICACIÓN | AP5: ADELANTO DE ASIGNACION | AQ5: ADELANTO DE BONO | AR5: TOTAL DESCUENTOS | AS5: NETO A PAGAR | AV5: 3001 - ESSALUD | AW5: 3006 - CRED. EPS | AX5: TOTAL APORTES
A6: 000011 | B6: CATAÑO OYANGUREN GIANCARLO | C6: 46345862 | D6: 42278 | F6: 0000001 | G6: GENERAL | H6: GENERAL | I6: BBVA BANCO CONTINENTAL | J6: BBVA BANCO CONTINENTAL | K6: 001100570220702643 | L6: DOMICILIADO | M6: EMPLEADOS | N6: EJECUTIVO DE NEGOCIOS | O6: PROFUTURO | P6: NO | Q6: 2700 | R6: 30 | U6: =8*R6 -> 240 | V6: =+Q6 -> 2700 | Z6: 2700 | AA6: 182.25 | AB6: 250 | AE6: =+SUM(V6:AD6) -> 5832.25 | AF6: 270 | AG6: 45.63 | AH6: 36.99 | AJ6: 24.76 | AK6: 69.14 | AL6: 1350 | AO6: =+Z6+AA6 -> 2882.25 | AP6: =+AB6 -> 250 | AQ6: =+AC6 -> 0 | AR6: =+SUM(AF6:AQ6) -> 4928.77 | AS6: =+AE6-AR6 -> 903.48 | AV6: 182.25 | AW6: 60.75 | AX6: 243
A7: 000013 | B7: CONDORI LOPEZ ANDREA DEL PILAR | C7: 72196931 | D7: 42297 | F7: 0000001 | G7: GENERAL | H7: GENERAL | I7: BBVA BANCO CONTINENTAL | J7: BBVA BANCO CONTINENTAL | K7: 001100570220871860 | L7: DOMICILIADO | M7: EMPLEADOS | N7: EJECUTIVO DE NEGOCIOS SENIOR | O7: PRIMA | P7: NO | Q7: 3200 | R7: 30 | U7: =8*R7 -> 240 | V7: =+Q7 -> 3200 | Z7: 3200 | AA7: 216 | AB7: 250 | AE7: =+SUM(V7:AD7) -> 6866 | AF7: 320 | AG7: 51.2 | AH7: 43.84 | AJ7: 71.87 | AK7: 69.14 | AL7: 1600 | AO7: =+Z7+AA7 -> 3416 | AP7: =+AB7 -> 250 | AQ7: =+AC7 -> 0 | AR7: =+SUM(AF7:AQ7) -> 5822.05 | AS7: =+AE7-AR7 -> 1043.95 | AV7: 216 | AW7: 72 | AX7: 288
A8: 000005 | B8: DURAND GARCIA ERICKA RAQUEL | C8: 41194847 | D8: 40634 | F8: 0000001 | G8: GENERAL | H8: GENERAL | I8: BBVA BANCO CONTINENTAL | J8: BBVA BANCO CONTINENTAL | K8: 001101820200286368 | L8: DOMICILIADO | M8: EMPLEADOS | N8: JEFE DE RENOVACIONES | O8: INTEGRA | P8: NO | Q8: 3800 | R8: 30 | U8: =8*R8 -> 240 | V8: =+Q8 -> 3800 | Z8: 3800 | AA8: 256.5 | AB8: 250 | AC8: 2500 | AE8: =+SUM(V8:AD8) -> 10606.5 | AF8: 630 | AG8: 97.65 | AH8: 86.31 | AJ8: 328.42 | AK8: 69.14 | AL8: 1900 | AO8: =+Z8+AA8 -> 4056.5 | AP8: =+AB8 -> 250 | AQ8: =+AC8 -> 2500 | AR8: =+SUM(AF8:AQ8) -> 9918.02 | AS8: =+AE8-AR8 -> 688.48 | AV8: 425.25 | AW8: 141.75 | AX8: 567
A9: 000006 | B9: GARCIA ZAVALETA GIOVANNA HERMELINDA | C9: 41202202 | D9: 40817 | F9: 0000001 | G9: GENERAL | H9: GENERAL | I9: BANCO INTERNACIONAL DEL PERU-INTERBANK | J9: BANCO INTERNACIONAL DEL PERU-INTERBANK | K9: 00304101310937054912 | L9: DOMICILIADO | M9: EMPLEADOS | N9: JEFE DE OPERACIONES | O9: INTEGRA | P9: NO | Q9: 3800 | R9: 30 | U9: =8*R9 -> 240 | V9: =+Q9 -> 3800 | X9: 113 | Z9: 3913 | AA9: 352.17 | AB9: 250 | AC9: 3000 | AE9: =+SUM(V9:AD9) -> 11428.17 | AF9: 691.3 | AG9: 107.15 | AH9: 94.71 | AJ9: 380.24 | AL9: 1956.5 | AO9: =+Z9+AA9 -> 4265.17 | AP9: =+AB9 -> 250 | AQ9: =+AC9 -> 3000 | AR9: =+SUM(AF9:AQ9) -> 10745.07 | AS9: =+AE9-AR9 -> 683.1 | AV9: 622.17 | AX9: 622.17
A10: 000004 | B10: HERRERA ANDAMAYO NAHALA DOROTHY | C10: 42263949 | D10: 40180 | F10: 0000001 | G10: GENERAL | H10: GENERAL | I10: BBVA BANCO CONTINENTAL | J10: BBVA BANCO CONTINENTAL | K10: 001101820200243774 | L10: DOMICILIADO | M10: EMPLEADOS | N10: JEFE DE VENTAS | O10: PRIMA | P10: NO | Q10: 3800 | R10: 28 | S10: 2 | U10: =8*R10 -> 224 | V10: 3546.6667 | X10: 113 | Y10: =+Q10/30*2 -> 253.33333 | Z10: 3913 | AA10: 352.17 | AB10: 250 | AC10: 1800 | AE10: =+SUM(V10:AD10) -> 10228.17 | AF10: =+(V10+X10+Y10+AC10)*0.1 -> 571.3 | AG10: =+(V10+X10+Y10+AC10)*1.6% -> 91.408 | AH10: =+(V10+X10+Y10+AC10)*1.37% -> 78.2681 | AJ10: 284.24 | AL10: 1956.5 | AO10: =+Z10+AA10 -> 4265.17 | AP10: =+AB10 -> 250 | AQ10: =+AC10 -> 1800 | AR10: =+SUM(AF10:AQ10) -> 9296.8861 | AS10: =+AE10-AR10 -> 931.2839 | AV10: 514.17 | AX10: 514.17
A11: 000014 | B11: HERRERA GERONIMO MARYELIZA SANTA | C11: 46098021 | D11: 42767 | F11: 0000001 | G11: GENERAL | H11: GENERAL | I11: BBVA BANCO CONTINENTAL | J11: BBVA BANCO CONTINENTAL | K11: 00110057750228218627 | L11: DOMICILIADO | M11: EMPLEADOS | N11: EJECUTIVO DE NEGOCIOS | O11: HABITAT | P11: SI | Q11: 2500 | R11: 30 | U11: =8*R11 -> 240 | V11: =+Q11 -> 2500 | Z11: 2500 | AA11: 168.75 | AB11: 250 | AC11: 1500 | AD11: 29 | AE11: =+SUM(V11:AD11) -> 6947.75 | AF11: 400 | AH11: 54.8 | AK11: 69.14 | AL11: 1250 | AO11: =+Z11+AA11 -> 2668.75 | AP11: =+AB11 -> 250 | AQ11: =+AC11 -> 1500 | AR11: =+SUM(AF11:AQ11) -> 6192.69 | AS11: =+AE11-AR11 -> 755.06 | AV11: 270 | AW11: 90 | AX11: 360
A12: 000002 | B12: KUANG CHUSING HECTOR ENRIQUE | C12: 40243954 | D12: 37803 | F12: 0000001 | G12: GENERAL | H12: GENERAL | I12: BBVA BANCO CONTINENTAL | J12: BBVA BANCO CONTINENTAL | K12: 001101820200153627 | L12: DOMICILIADO | M12: EMPLEADOS | N12: DIRECTOR DE NEGOCIOS Y MARKETING | O12: INTEGRA | P12: NO | Q12: 15000 | R12: 30 | U12: =8*R12 -> 240 | V12: =+Q12 -> 15000 | Z12: 15000 | AA12: 1012.5 | AB12: 250 | AE12: =+SUM(V12:AD12) -> 31262.5 | AF12: 1500 | AG12: 232.5 | AH12: 166.85 | AJ12: 2114.52 | AK12: 227.93 | AL12: 7500 | AO12: =+Z12+AA12 -> 16012.5 | AP12: =+AB12 -> 250 | AQ12: =+AC12 -> 0 | AR12: =+SUM(AF12:AQ12) -> 28004.3 | AS12: =+AE12-AR12 -> 3258.2 | AV12: 1012.5 | AW12: 337.5 | AX12: 1350
A13: 000012 | B13: KUANG CHUSING NANCY AIDA | C13: 10798282 | D13: 42296 | F13: 0000001 | G13: GENERAL | H13: GENERAL | I13: BBVA BANCO CONTINENTAL | J13: BBVA BANCO CONTINENTAL | K13: 001100570220854001 | L13: DOMICILIADO | M13: EMPLEADOS | N13: GERENTE DE MARKETING | O13: HABITAT | P13: NO | Q13: 10000 | R13: 30 | U13: =8*R13 -> 240 | V13: =+Q13 -> 10000 | X13: 113 | Z13: 10113 | AA13: 910.17 | AB13: 250 | AE13: =+SUM(V13:AD13) -> 21386.17 | AF13: 1011.3 | AG13: 148.66 | AH13: 138.55 | AJ13: 1141.36 | AL13: 5056.5 | AO13: =+Z13+AA13 -> 11023.17 | AP13: =+AB13 -> 250 | AQ13: =+AC13 -> 0 | AR13: =+SUM(AF13:AQ13) -> 18769.54 | AS13: =+AE13-AR13 -> 2616.63 | AV13: 910.17 | AX13: 910.17
A14: 000001 | B14: KUANG LINARES MARIA ROSARIO | C14: 09859427 | D14: 35933 | F14: 0000001 | G14: GENERAL | H14: GENERAL | I14: BBVA BANCO CONTINENTAL | J14: BBVA BANCO CONTINENTAL | K14: 001100570212532526 | L14: DOMICILIADO | M14: EMPLEADOS | N14: ADMINISTRADOR GENERAL CONTABLE | O14: INTEGRA | P14: NO | Q14: 3800 | R14: 30 | U14: =8*R14 -> 240 | V14: =+Q14 -> 3800 | Z14: 3800 | AA14: 256.5 | AB14: 250 | AE14: =+SUM(V14:AD14) -> 8106.5 | AF14: 380 | AG14: 58.9 | AJ14: 128.42 | AK14: 227.93 | AL14: 1900 | AO14: =+Z14+AA14 -> 4056.5 | AP14: =+AB14 -> 250 | AQ14: =+AC14 -> 0 | AR14: =+SUM(AF14:AQ14) -> 7001.75 | AS14: =+AE14-AR14 -> 1104.75 | AV14: 256.5 | AW14: 85.5 | AX14: 342
A15: 000008 | B15: LEZAMA ULLOA CESAR ENRIQUE | C15: 41320534 | D15: 41518 | F15: 0000001 | G15: GENERAL | H15: GENERAL | I15: BBVA BANCO CONTINENTAL | J15: BBVA BANCO CONTINENTAL | K15: 001101820200162561 | L15: DOMICILIADO | M15: EMPLEADOS | N15: EJECUTIVO DE NEGOCIOS | O15: INTEGRA | P15: NO | Q15: 2700 | R15: 23 | T15: 7 | U15: =8*R15 -> 184 | V15: =+Q15/30*R15 -> 2070 | W15: =+(Q15+113)/30*T15 -> 656.36667 | X15: =3.76666666666667*R15 -> 86.633333 | Z15: 2813 | AA15: 253.17 | AB15: 250 | AC15: 1500 | AE15: =+SUM(V15:AD15) -> 7629.17 | AF15: 374.52 | AG15: 58.05 | AH15: 51.31 | AJ15: 156.25 | AL15: 843.9 | AM15: 567.77 | AO15: =+Z15+AA15 -> 3066.17 | AP15: =+AB15 -> 250 | AQ15: =+AC15 -> 1500 | AR15: =+SUM(AF15:AQ15) -> 6867.97 | AS15: =+AE15-AR15 -> 761.2 | AV15: 337.07 | AX15: 337.07
